Workbook

Sheet 00_README
A1: Audit Manual Dashboard PHK (empdash)
A5: TUJUAN
A6: 1 | B6: Hitung ulang secara manual dan bandingkan dengan dashboard
A7: 2 | B7: Periksa perhitungan SHOCK-nya, bukan hanya hasil ke tenaga kerja
A8: 3 | B8: Periksa apakah kode mengambil data terkini
A9: 4 | B9: Kerjakan langsung seluruh matriks 52x34, bukan per sektor
A11: VINTAGE DATA YANG DIBANDINGKAN
A12: Theme 1 (harga komoditas) | B12: 2026M05
A13: Theme 2 (mitra dagang) | B13: WEO April 2026 - WEO April 2025
A14: Theme 3 (permintaan domestik) | B14: 2026-05
A15: Elastisitas | B15: PLACEHOLDER (sintetis) - bukan hasil IndoTERM
A17: RANTAI PERHITUNGAN
A18: Langkah 1-2 | B18: Data mentah -> shock x_j (38 angka, satuan percentage point)
A19: Langkah 3 | B19: E[s,p] = share[s,p] x JUMLAH_j ( x_j x intensity_j[s] )
A20: Langkah 4 | B20: dL[s,p] = E[s,p] / 100 x L0[s,p]
A22: PENYEDERHANAAN PENTING
B23: Semua 38 matriks elastisitas berbentuk eta_j[s,p] = intensity_j[s] x share[s,p].
B24: Terverifikasi persis untuk seluruh 38 x 52 pasangan, sehingga matriks 52x34
B25: cukup dihitung dari SATU tabel intensitas 38x52 - tidak perlu 38 matriks.
A27: DAFTAR SHEET
A28: 01_shock_T1 | B28: Harga komoditas -> YoY -> tren 48 -> x_j (7 shock)
A29: 02_shock_T2 | B29: Revisi WEO x bobot ekspor -> x_k (23 shock)
A30: 03_shock_T3 | B30: Indeks ritel BI -> YoY -> tren 48 -> x_i (8 shock)
A31: 04_L0 | B31: Tenaga kerja awal 52x34
A32: 05_shares | B32: Pangsa provinsi per sektor 52x34 (rumus dari 04)
A33: 06_intensity | B33: Tabel intensitas 38x52 + vektor w[s]
A34: 07_E_manual | B34: Hasil hitung manual E (%) 52x34 (rumus)
A35: 08_dL_manual | B35: Hasil hitung manual dL (orang) 52x34 (rumus)
A36: 09_dash_E | B36: E dari dashboard - pembanding
A37: 10_dash_dL | B37: dL dari dashboard - pembanding
A38: 11_selisih | B38: Perbandingan sel per sel + ringkasan
A39: 12_catatan | B39: Temuan
A41: CATATAN | B41: Semua sel matriks berupa RUMUS, bukan angka tempelan.
B42: Klik sel manapun untuk menelusuri asal perhitungannya.

Sheet 01_shock_T1
A1: Theme 1 — Shock Harga Komoditas
A2: x_j = YoY%(t) − rata-rata 48 periode YoY% (lag 1). Sumber: World Bank Pink Sheet + FRED IY3344
A4: period | B4: cpo: harga | C4: cpo: YoY% | D4: cpo: tren48 | E4: cpo: x_j | F4: coal: harga | G4: coal: YoY% | H4: coal: tren48 | I4: coal: x_j | J4: nickel: harga | K4: nickel: YoY% | L4: nickel: tren48 | M4: nickel: x_j | N4: copper: harga | O4: copper: YoY% | P4: copper: tren48 | Q4: copper: x_j | R4: rubber: harga | S4: rubber: YoY% | T4: rubber: tren48 | U4: rubber: x_j | V4: oilgas: harga | W4: oilgas: YoY% | X4: oilgas: tren48 | Y4: oilgas: x_j | Z4: electronics: harga | AA4: electronics: YoY% | AB4: electronics: tren48 | AC4: electronics: x_j
A5: 1960M01 | B5: 233 | J5: 1631 | N5: 715.4 | V5: 1.63
A6: 1960M02 | B6: 229 | J6: 1631 | N6: 728.19 | V6: 1.63
A7: 1960M03 | B7: 225 | J7: 1631 | N7: 684.94 | V7: 1.63
A8: 1960M04 | B8: 225 | J8: 1631 | N8: 723.11 | V8: 1.63
A9: 1960M05 | B9: 225 | J9: 1631 | N9: 684.75 | V9: 1.63
A10: 1960M06 | B10: 219 | J10: 1631 | N10: 691.59 | V10: 1.63
A11: 1960M07 | B11: 221 | J11: 1631 | N11: 702.39 | V11: 1.63
A12: 1960M08 | B12: 225 | J12: 1631 | N12: 675.94 | V12: 1.63
A13: 1960M09 | B13: 224 | J13: 1631 | N13: 647.06 | V13: 1.63
A14: 1960M10 | B14: 222 | J14: 1631 | N14: 612.66 | V14: 1.63
A15: 1960M11 | B15: 222 | J15: 1631 | N15: 642.13 | V15: 1.63
A16: 1960M12 | B16: 223 | J16: 1631 | N16: 636.91 | V16: 1.63
A17: 1961M01 | B17: 223 | C17: =IF(OR(B17="",B5=""),"",(B17/B5-1)*100) -> -4.2918455 | G17: =IF(OR(F17="",F5=""),"",(F17/F5-1)*100) | J17: 1711 | K17: =IF(OR(J17="",J5=""),"",(J17/J5-1)*100) -> 4.9049663 | N17: 606.71 | O17: =IF(OR(N17="",N5=""),"",(N17/N5-1)*100) -> -15.192899 | S17: =IF(OR(R17="",R5=""),"",(R17/R5-1)*100) | V17: 1.57 | W17: =IF(OR(V17="",V5=""),"",(V17/V5-1)*100) -> -3.6809816 | AA17: =IF(OR(Z17="",Z5=""),"",(Z17/Z5-1)*100)
A18: 1961M02 | B18: 228 | C18: =IF(OR(B18="",B6=""),"",(B18/B6-1)*100) -> -0.43668122 | G18: =IF(OR(F18="",F6=""),"",(F18/F6-1)*100) | J18: 1711 | K18: =IF(OR(J18="",J6=""),"",(J18/J6-1)*100) -> 4.9049663 | N18: 616.63 | O18: =IF(OR(N18="",N6=""),"",(N18/N6-1)*100) -> -15.320177 | S18: =IF(OR(R18="",R6=""),"",(R18/R6-1)*100) | V18: 1.57 | W18: =IF(OR(V18="",V6=""),"",(V18/V6-1)*100) -> -3.6809816 | AA18: =IF(OR(Z18="",Z6=""),"",(Z18/Z6-1)*100)
A19: 1961M03 | B19: 231 | C19: =IF(OR(B19="",B7=""),"",(B19/B7-1)*100) -> 2.6666667 | G19: =IF(OR(F19="",F7=""),"",(F19/F7-1)*100) | J19: 1711 | K19: =IF(OR(J19="",J7=""),"",(J19/J7-1)*100) -> 4.9049663 | N19: 621.26 | O19: =IF(OR(N19="",N7=""),"",(N19/N7-1)*100) -> -9.2971647 | S19: =IF(OR(R19="",R7=""),"",(R19/R7-1)*100) | V19: 1.57 | W19: =IF(OR(V19="",V7=""),"",(V19/V7-1)*100) -> -3.6809816 | AA19: =IF(OR(Z19="",Z7=""),"",(Z19/Z7-1)*100)
A20: 1961M04 | B20: 233 | C20: =IF(OR(B20="",B8=""),"",(B20/B8-1)*100) -> 3.5555556 | G20: =IF(OR(F20="",F8=""),"",(F20/F8-1)*100) | J20: 1711 | K20: =IF(OR(J20="",J8=""),"",(J20/J8-1)*100) -> 4.9049663 | N20: 631.84 | O20: =IF(OR(N20="",N8=""),"",(N20/N8-1)*100) -> -12.621869 | S20: =IF(OR(R20="",R8=""),"",(R20/R8-1)*100) | V20: 1.57 | W20: =IF(OR(V20="",V8=""),"",(V20/V8-1)*100) -> -3.6809816 | AA20: =IF(OR(Z20="",Z8=""),"",(Z20/Z8-1)*100)
A21: 1961M05 | B21: 234 | C21: =IF(OR(B21="",B9=""),"",(B21/B9-1)*100) -> 4 | G21: =IF(OR(F21="",F9=""),"",(F21/F9-1)*100) | J21: 1711 | K21: =IF(OR(J21="",J9=""),"",(J21/J9-1)*100) -> 4.9049663 | N21: 668.44 | O21: =IF(OR(N21="",N9=""),"",(N21/N9-1)*100) -> -2.3818912 | S21: =IF(OR(R21="",R9=""),"",(R21/R9-1)*100) | V21: 1.57 | W21: =IF(OR(V21="",V9=""),"",(V21/V9-1)*100) -> -3.6809816 | AA21: =IF(OR(Z21="",Z9=""),"",(Z21/Z9-1)*100)
A22: 1961M06 | B22: 233 | C22: =IF(OR(B22="",B10=""),"",(B22/B10-1)*100) -> 6.3926941 | G22: =IF(OR(F22="",F10=""),"",(F22/F10-1)*100) | J22: 1711 | K22: =IF(OR(J22="",J10=""),"",(J22/J10-1)*100) -> 4.9049663 | N22: 652.12 | O22: =IF(OR(N22="",N10=""),"",(N22/N10-1)*100) -> -5.7071386 | S22: =IF(OR(R22="",R10=""),"",(R22/R10-1)*100) | V22: 1.57 | W22: =IF(OR(V22="",V10=""),"",(V22/V10-1)*100) -> -3.6809816 | AA22: =IF(OR(Z22="",Z10=""),"",(Z22/Z10-1)*100)
A23: 1961M07 | B23: 229 | C23: =IF(OR(B23="",B11=""),"",(B23/B11-1)*100) -> 3.6199095 | G23: =IF(OR(F23="",F11=""),"",(F23/F11-1)*100) | J23: 1711 | K23: =IF(OR(J23="",J11=""),"",(J23/J11-1)*100) -> 4.9049663 | N23: 633.39 | O23: =IF(OR(N23="",N11=""),"",(N23/N11-1)*100) -> -9.8236023 | S23: =IF(OR(R23="",R11=""),"",(R23/R11-1)*100) | V23: 1.57 | W23: =IF(OR(V23="",V11=""),"",(V23/V11-1)*100) -> -3.6809816 | AA23: =IF(OR(Z23="",Z11=""),"",(Z23/Z11-1)*100)
A24: 1961M08 | B24: 226 | C24: =IF(OR(B24="",B12=""),"",(B24/B12-1)*100) -> 0.44444444 | G24: =IF(OR(F24="",F12=""),"",(F24/F12-1)*100) | J24: 1711 | K24: =IF(OR(J24="",J12=""),"",(J24/J12-1)*100) -> 4.9049663 | N24: 636.47 | O24: =IF(OR(N24="",N12=""),"",(N24/N12-1)*100) -> -5.8392757 | S24: =IF(OR(R24="",R12=""),"",(R24/R12-1)*100) | V24: 1.57 | W24: =IF(OR(V24="",V12=""),"",(V24/V12-1)*100) -> -3.6809816 | AA24: =IF(OR(Z24="",Z12=""),"",(Z24/Z12-1)*100)
A25: 1961M09 | B25: 226 | C25: =IF(OR(B25="",B13=""),"",(B25/B13-1)*100) -> 0.89285714 | G25: =IF(OR(F25="",F13=""),"",(F25/F13-1)*100) | J25: 1711 | K25: =IF(OR(J25="",J13=""),"",(J25/J13-1)*100) -> 4.9049663 | N25: 632.72 | O25: =IF(OR(N25="",N13=""),"",(N25/N13-1)*100) -> -2.2161778 | S25: =IF(OR(R25="",R13=""),"",(R25/R13-1)*100) | V25: 1.57 | W25: =IF(OR(V25="",V13=""),"",(V25/V13-1)*100) -> -3.6809816 | AA25: =IF(OR(Z25="",Z13=""),"",(Z25/Z13-1)*100)
A26: 1961M10 | B26: 226 | C26: =IF(OR(B26="",B14=""),"",(B26/B14-1)*100) -> 1.8018018 | G26: =IF(OR(F26="",F14=""),"",(F26/F14-1)*100) | J26: 1711 | K26: =IF(OR(J26="",J14=""),"",(J26/J14-1)*100) -> 4.9049663 | N26: 630.3 | O26: =IF(OR(N26="",N14=""),"",(N26/N14-1)*100) -> 2.8792479 | S26: =IF(OR(R26="",R14=""),"",(R26/R14-1)*100) | V26: 1.57 | W26: =IF(OR(V26="",V14=""),"",(V26/V14-1)*100) -> -3.6809816 | AA26: =IF(OR(Z26="",Z14=""),"",(Z26/Z14-1)*100)
A27: 1961M11 | B27: 226 | C27: =IF(OR(B27="",B15=""),"",(B27/B15-1)*100) -> 1.8018018 | G27: =IF(OR(F27="",F15=""),"",(F27/F15-1)*100) | J27: 1711 | K27: =IF(OR(J27="",J15=""),"",(J27/J15-1)*100) -> 4.9049663 | N27: 632.28 | O27: =IF(OR(N27="",N15=""),"",(N27/N15-1)*100) -> -1.5339573 | S27: =IF(OR(R27="",R15=""),"",(R27/R15-1)*100) | V27: 1.57 | W27: =IF(OR(V27="",V15=""),"",(V27/V15-1)*100) -> -3.6809816 | AA27: =IF(OR(Z27="",Z15=""),"",(Z27/Z15-1)*100)
A28: 1961M12 | B28: 226 | C28: =IF(OR(B28="",B16=""),"",(B28/B16-1)*100) -> 1.3452915 | G28: =IF(OR(F28="",F16=""),"",(F28/F16-1)*100) | J28: 1711 | K28: =IF(OR(J28="",J16=""),"",(J28/J16-1)*100) -> 4.9049663 | N28: 634.85 | O28: =IF(OR(N28="",N16=""),"",(N28/N16-1)*100) -> -0.32343659 | S28: =IF(OR(R28="",R16=""),"",(R28/R16-1)*100) | V28: 1.57 | W28: =IF(OR(V28="",V16=""),"",(V28/V16-1)*100) -> -3.6809816 | AA28: =IF(OR(Z28="",Z16=""),"",(Z28/Z16-1)*100)
... A64: 1964M12 | B64: 261.25 | C64: =IF(OR(B64="",B52=""),"",(B64/B52-1)*100) -> 12.72437 | G64: =IF(OR(F64="",F52=""),"",(F64/F52-1)*100) | J64: 1742 | K64: =IF(OR(J64="",J52=""),"",(J64/J52-1)*100) -> 0 | N64: 1269.2 | O64: =IF(OR(N64="",N52=""),"",(N64/N52-1)*100) -> 95.219491 | S64: =IF(OR(R64="",R52=""),"",(R64/R52-1)*100) | V64: 1.45 | W64: =IF(OR(V64="",V52=""),"",(V64/V52-1)*100) -> -3.3333333 | AA64: =IF(OR(Z64="",Z52=""),"",(Z64/Z52-1)*100)
A65: 1965M01 | B65: 266.21 | C65: =IF(OR(B65="",B53=""),"",(B65/B53-1)*100) -> 14.32191 | D65: =IF(COUNT(C17:C64)<48,"",AVERAGE(C17:C64)) -> 1.8366703 | E65: =IF(OR(C65="",D65=""),"",C65-D65) -> 12.48524 | G65: =IF(OR(F65="",F53=""),"",(F65/F53-1)*100) | H65: =IF(COUNT(G17:G64)<48,"",AVERAGE(G17:G64)) | I65: =IF(OR(G65="",H65=""),"",G65-H65) | J65: 1735 | K65: =IF(OR(J65="",J53=""),"",(J65/J53-1)*100) -> -0.34462952 | L65: =IF(COUNT(K17:K64)<48,"",AVERAGE(K17:K64)) -> 1.6823432 | M65: =IF(OR(K65="",L65=""),"",K65-L65) -> -2.0269727 | N65: 1000.68 | O65: =IF(OR(N65="",N53=""),"",(N65/N53-1)*100) -> 52.624113 | P65: =IF(COUNT(O17:O64)<48,"",AVERAGE(O17:O64)) -> 11.434296 | Q65: =IF(OR(O65="",P65=""),"",O65-P65) -> 41.189817 | S65: =IF(OR(R65="",R53=""),"",(R65/R53-1)*100) | T65: =IF(COUNT(S17:S64)<48,"",AVERAGE(S17:S64)) | U65: =IF(OR(S65="",T65=""),"",S65-T65) | V65: 1.42 | W65: =IF(OR(V65="",V53=""),"",(V65/V53-1)*100) -> -2.0689655 | X65: =IF(COUNT(W17:W64)<48,"",AVERAGE(W17:W64)) -> -2.8787044 | Y65: =IF(OR(W65="",X65=""),"",W65-X65) -> 0.80973893 | AA65: =IF(OR(Z65="",Z53=""),"",(Z65/Z53-1)*100) | AB65: =IF(COUNT(AA17:AA64)<48,"",AVERAGE(AA17:AA64)) | AC65: =IF(OR(AA65="",AB65=""),"",AA65-AB65)
A66: 1965M02 | B66: 283.02 | C66: =IF(OR(B66="",B54=""),"",(B66/B54-1)*100) -> 21.68193 | D66: =IF(COUNT(C18:C65)<48,"",AVERAGE(C18:C65)) -> 2.2244569 | E66: =IF(OR(C66="",D66=""),"",C66-D66) -> 19.457473 | G66: =IF(OR(F66="",F54=""),"",(F66/F54-1)*100) | H66: =IF(COUNT(G18:G65)<48,"",AVERAGE(G18:G65)) | I66: =IF(OR(G66="",H66=""),"",G66-H66) | J66: 1735 | K66: =IF(OR(J66="",J54=""),"",(J66/J54-1)*100) -> -0.40183697 | L66: =IF(COUNT(K18:K65)<48,"",AVERAGE(K18:K65)) -> 1.5729766 | M66: =IF(OR(K66="",L66=""),"",K66-L66) -> -1.9748136 | N66: 1179.91 | O66: =IF(OR(N66="",N54=""),"",(N66/N54-1)*100) -> 70.067311 | P66: =IF(COUNT(O18:O65)<48,"",AVERAGE(O18:O65)) -> 12.847151 | Q66: =IF(OR(O66="",P66=""),"",O66-P66) -> 57.220161 | S66: =IF(OR(R66="",R54=""),"",(R66/R54-1)*100) | T66: =IF(COUNT(S18:S65)<48,"",AVERAGE(S18:S65)) | U66: =IF(OR(S66="",T66=""),"",S66-T66) | V66: 1.42 | W66: =IF(OR(V66="",V54=""),"",(V66/V54-1)*100) -> -2.0689655 | X66: =IF(COUNT(W18:W65)<48,"",AVERAGE(W18:W65)) -> -2.8451208 | Y66: =IF(OR(W66="",X66=""),"",W66-X66) -> 0.77615526 | AA66: =IF(OR(Z66="",Z54=""),"",(Z66/Z54-1)*100) | AB66: =IF(COUNT(AA18:AA65)<48,"",AVERAGE(AA18:AA65)) | AC66: =IF(OR(AA66="",AB66=""),"",AA66-AB66)
A67: 1965M03 | B67: 292.11 | C67: =IF(OR(B67="",B55=""),"",(B67/B55-1)*100) -> 25.444473 | D67: =IF(COUNT(C19:C66)<48,"",AVERAGE(C19:C66)) -> 2.6852613 | E67: =IF(OR(C67="",D67=""),"",C67-D67) -> 22.759212 | G67: =IF(OR(F67="",F55=""),"",(F67/F55-1)*100) | H67: =IF(COUNT(G19:G66)<48,"",AVERAGE(G19:G66)) | I67: =IF(OR(G67="",H67=""),"",G67-H67) | J67: 1735 | K67: =IF(OR(J67="",J55=""),"",(J67/J55-1)*100) -> -0.40183697 | L67: =IF(COUNT(K19:K66)<48,"",AVERAGE(K19:K66)) -> 1.4624182 | M67: =IF(OR(K67="",L67=""),"",K67-L67) -> -1.8642552 | N67: 1237.23 | O67: =IF(OR(N67="",N55=""),"",(N67/N55-1)*100) -> 66.035482 | P67: =IF(COUNT(O19:O66)<48,"",AVERAGE(O19:O66)) -> 14.626057 | Q67: =IF(OR(O67="",P67=""),"",O67-P67) -> 51.409426 | S67: =IF(OR(R67="",R55=""),"",(R67/R55-1)*100) | T67: =IF(COUNT(S19:S66)<48,"",AVERAGE(S19:S66)) | U67: =IF(OR(S67="",T67=""),"",S67-T67) | V67: 1.42 | W67: =IF(OR(V67="",V55=""),"",(V67/V55-1)*100) -> -2.0689655 | X67: =IF(COUNT(W19:W66)<48,"",AVERAGE(W19:W66)) -> -2.8115371 | Y67: =IF(OR(W67="",X67=""),"",W67-X67) -> 0.74257159 | AA67: =IF(OR(Z67="",Z55=""),"",(Z67/Z55-1)*100) | AB67: =IF(COUNT(AA19:AA66)<48,"",AVERAGE(AA19:AA66)) | AC67: =IF(OR(AA67="",AB67=""),"",AA67-AB67)
A68: 1965M04 | B68: 297.62 | C68: =IF(OR(B68="",B56=""),"",(B68/B56-1)*100) -> 27.810702 | D68: =IF(COUNT(C20:C67)<48,"",AVERAGE(C20:C67)) -> 3.1597989 | E68: =IF(OR(C68="",D68=""),"",C68-D68) -> 24.650903 | G68: =IF(OR(F68="",F56=""),"",(F68/F56-1)*100) | H68: =IF(COUNT(G20:G67)<48,"",AVERAGE(G20:G67)) | I68: =IF(OR(G68="",H68=""),"",G68-H68) | J68: 1735 | K68: =IF(OR(J68="",J56=""),"",(J68/J56-1)*100) -> -0.34462952 | L68: =IF(COUNT(K20:K67)<48,"",AVERAGE(K20:K67)) -> 1.3518598 | M68: =IF(OR(K68="",L68=""),"",K68-L68) -> -1.6964894 | N68: 1348.34 | O68: =IF(OR(N68="",N56=""),"",(N68/N56-1)*100) -> 56.499838 | P68: =IF(COUNT(O20:O67)<48,"",AVERAGE(O20:O67)) -> 16.195487 | Q68: =IF(OR(O68="",P68=""),"",O68-P68) -> 40.304351 | S68: =IF(OR(R68="",R56=""),"",(R68/R56-1)*100) | T68: =IF(COUNT(S20:S67)<48,"",AVERAGE(S20:S67)) | U68: =IF(OR(S68="",T68=""),"",S68-T68) | V68: 1.42 | W68: =IF(OR(V68="",V56=""),"",(V68/V56-1)*100) -> -2.0689655 | X68: =IF(COUNT(W20:W67)<48,"",AVERAGE(W20:W67)) -> -2.7779534 | Y68: =IF(OR(W68="",X68=""),"",W68-X68) -> 0.70898792 | AA68: =IF(OR(Z68="",Z56=""),"",(Z68/Z56-1)*100) | AB68: =IF(COUNT(AA20:AA67)<48,"",AVERAGE(AA20:AA67)) | AC68: =IF(OR(AA68="",AB68=""),"",AA68-AB68)
A69: 1965M05 | B69: 303.13 | C69: =IF(OR(B69="",B57=""),"",(B69/B57-1)*100) -> 30.17693 | D69: =IF(COUNT(C21:C68)<48,"",AVERAGE(C21:C68)) -> 3.6651144 | E69: =IF(OR(C69="",D69=""),"",C69-D69) -> 26.511816 | G69: =IF(OR(F69="",F57=""),"",(F69/F57-1)*100) | H69: =IF(COUNT(G21:G68)<48,"",AVERAGE(G21:G68)) | I69: =IF(OR(G69="",H69=""),"",G69-H69) | J69: 1735 | K69: =IF(OR(J69="",J57=""),"",(J69/J57-1)*100) -> -0.40183697 | L69: =IF(COUNT(K21:K68)<48,"",AVERAGE(K21:K68)) -> 1.2424933 | M69: =IF(OR(K69="",L69=""),"",K69-L69) -> -1.6443302 | N69: 1378.55 | O69: =IF(OR(N69="",N57=""),"",(N69/N57-1)*100) -> 66.435263 | P69: =IF(COUNT(O21:O68)<48,"",AVERAGE(O21:O68)) -> 17.635522 | Q69: =IF(OR(O69="",P69=""),"",O69-P69) -> 48.799741 | S69: =IF(OR(R69="",R57=""),"",(R69/R57-1)*100) | T69: =IF(COUNT(S21:S68)<48,"",AVERAGE(S21:S68)) | U69: =IF(OR(S69="",T69=""),"",S69-T69) | V69: 1.42 | W69: =IF(OR(V69="",V57=""),"",(V69/V57-1)*100) -> -2.0689655 | X69: =IF(COUNT(W21:W68)<48,"",AVERAGE(W21:W68)) -> -2.7443698 | Y69: =IF(OR(W69="",X69=""),"",W69-X69) -> 0.67540425 | AA69: =IF(OR(Z69="",Z57=""),"",(Z69/Z57-1)*100) | AB69: =IF(COUNT(AA21:AA68)<48,"",AVERAGE(AA21:AA68)) | AC69: =IF(OR(AA69="",AB69=""),"",AA69-AB69)
A70: 1965M06 | B70: 294.87 | C70: =IF(OR(B70="",B58=""),"",(B70/B58-1)*100) -> 26.034365 | D70: =IF(COUNT(C22:C69)<48,"",AVERAGE(C22:C69)) -> 4.2104672 | E70: =IF(OR(C70="",D70=""),"",C70-D70) -> 21.823898 | G70: =IF(OR(F70="",F58=""),"",(F70/F58-1)*100) | H70: =IF(COUNT(G22:G69)<48,"",AVERAGE(G22:G69)) | I70: =IF(OR(G70="",H70=""),"",G70-H70) | J70: 1735 | K70: =IF(OR(J70="",J58=""),"",(J70/J58-1)*100) -> -0.40183697 | L70: =IF(COUNT(K22:K69)<48,"",AVERAGE(K22:K69)) -> 1.1319349 | M70: =IF(OR(K70="",L70=""),"",K70-L70) -> -1.5337718 | N70: 1308.88 | O70: =IF(OR(N70="",N58=""),"",(N70/N58-1)*100) -> 61.903937 | P70: =IF(COUNT(O22:O69)<48,"",AVERAGE(O22:O69)) -> 19.069213 | Q70: =IF(OR(O70="",P70=""),"",O70-P70) -> 42.834724 | S70: =IF(OR(R70="",R58=""),"",(R70/R58-1)*100) | T70: =IF(COUNT(S22:S69)<48,"",AVERAGE(S22:S69)) | U70: =IF(OR(S70="",T70=""),"",S70-T70) | V70: 1.42 | W70: =IF(OR(V70="",V58=""),"",(V70/V58-1)*100) -> -2.0689655 | X70: =IF(COUNT(W22:W69)<48,"",AVERAGE(W22:W69)) -> -2.7107861 | Y70: =IF(OR(W70="",X70=""),"",W70-X70) -> 0.64182059 | AA70: =IF(OR(Z70="",Z58=""),"",(Z70/Z58-1)*100) | AB70: =IF(COUNT(AA22:AA69)<48,"",AVERAGE(AA22:AA69)) | AC70: =IF(OR(AA70="",AB70=""),"",AA70-AB70)
A71: 1965M07 | B71: 279.99 | C71: =IF(OR(B71="",B59=""),"",(B71/B59-1)*100) -> 18.97255 | D71: =IF(COUNT(C23:C70)<48,"",AVERAGE(C23:C70)) -> 4.6196686 | E71: =IF(OR(C71="",D71=""),"",C71-D71) -> 14.352882 | G71: =IF(OR(F71="",F59=""),"",(F71/F59-1)*100) | H71: =IF(COUNT(G23:G70)<48,"",AVERAGE(G23:G70)) | I71: =IF(OR(G71="",H71=""),"",G71-H71) | J71: 1735 | K71: =IF(OR(J71="",J59=""),"",(J71/J59-1)*100) -> -0.34462952 | L71: =IF(COUNT(K23:K70)<48,"",AVERAGE(K23:K70)) -> 1.0213765 | M71: =IF(OR(K71="",L71=""),"",K71-L71) -> -1.366006 | N71: 1134.06 | O71: =IF(OR(N71="",N59=""),"",(N71/N59-1)*100) -> 32.646354 | P71: =IF(COUNT(O23:O70)<48,"",AVERAGE(O23:O70)) -> 20.477777 | Q71: =IF(OR(O71="",P71=""),"",O71-P71) -> 12.168576 | S71: =IF(OR(R71="",R59=""),"",(R71/R59-1)*100) | T71: =IF(COUNT(S23:S70)<48,"",AVERAGE(S23:S70)) | U71: =IF(OR(S71="",T71=""),"",S71-T71) | V71: 1.42 | W71: =IF(OR(V71="",V59=""),"",(V71/V59-1)*100) -> -2.0689655 | X71: =IF(COUNT(W23:W70)<48,"",AVERAGE(W23:W70)) -> -2.6772024 | Y71: =IF(OR(W71="",X71=""),"",W71-X71) -> 0.60823692 | AA71: =IF(OR(Z71="",Z59=""),"",(Z71/Z59-1)*100) | AB71: =IF(COUNT(AA23:AA70)<48,"",AVERAGE(AA23:AA70)) | AC71: =IF(OR(AA71="",AB71=""),"",AA71-AB71)
A72: 1965M08 | B72: 257.66 | C72: =IF(OR(B72="",B60=""),"",(B72/B60-1)*100) -> 9.3540446 | D72: =IF(COUNT(C24:C71)<48,"",AVERAGE(C24:C71)) -> 4.9395153 | E72: =IF(OR(C72="",D72=""),"",C72-D72) -> 4.4145293 | G72: =IF(OR(F72="",F60=""),"",(F72/F60-1)*100) | H72: =IF(COUNT(G24:G71)<48,"",AVERAGE(G24:G71)) | I72: =IF(OR(G72="",H72=""),"",G72-H72) | J72: 1735 | K72: =IF(OR(J72="",J60=""),"",(J72/J60-1)*100) -> -0.40183697 | L72: =IF(COUNT(K24:K71)<48,"",AVERAGE(K24:K71)) -> 0.91200988 | M72: =IF(OR(K72="",L72=""),"",K72-L72) -> -1.3138469 | N72: 1209.9 | O72: =IF(OR(N72="",N60=""),"",(N72/N60-1)*100) -> 21.071118 | P72: =IF(COUNT(O24:O71)<48,"",AVERAGE(O24:O71)) -> 21.362568 | Q72: =IF(OR(O72="",P72=""),"",O72-P72) -> -0.29145036 | S72: =IF(OR(R72="",R60=""),"",(R72/R60-1)*100) | T72: =IF(COUNT(S24:S71)<48,"",AVERAGE(S24:S71)) | U72: =IF(OR(S72="",T72=""),"",S72-T72) | V72: 1.42 | W72: =IF(OR(V72="",V60=""),"",(V72/V60-1)*100) -> -2.0689655 | X72: =IF(COUNT(W24:W71)<48,"",AVERAGE(W24:W71)) -> -2.6436188 | Y72: =IF(OR(W72="",X72=""),"",W72-X72) -> 0.57465325 | AA72: =IF(OR(Z72="",Z60=""),"",(Z72/Z60-1)*100) | AB72: =IF(COUNT(AA24:AA71)<48,"",AVERAGE(AA24:AA71)) | AC72: =IF(OR(AA72="",AB72=""),"",AA72-AB72)
A73: 1965M09 | B73: 246.64 | C73: =IF(OR(B73="",B61=""),"",(B73/B61-1)*100) -> 3.8265628 | D73: =IF(COUNT(C25:C72)<48,"",AVERAGE(C25:C72)) -> 5.125132 | E73: =IF(OR(C73="",D73=""),"",C73-D73) -> -1.2985692 | G73: =IF(OR(F73="",F61=""),"",(F73/F61-1)*100) | H73: =IF(COUNT(G25:G72)<48,"",AVERAGE(G25:G72)) | I73: =IF(OR(G73="",H73=""),"",G73-H73) | J73: 1735 | K73: =IF(OR(J73="",J61=""),"",(J73/J61-1)*100) -> -0.40183697 | L73: =IF(COUNT(K25:K72)<48,"",AVERAGE(K25:K72)) -> 0.80145148 | M73: =IF(OR(K73="",L73=""),"",K73-L73) -> -1.2032885 | N73: 1327.84 | O73: =IF(OR(N73="",N61=""),"",(N73/N61-1)*100) -> 14.267028 | P73: =IF(COUNT(O25:O72)<48,"",AVERAGE(O25:O72)) -> 21.923201 | Q73: =IF(OR(O73="",P73=""),"",O73-P73) -> -7.6561731 | S73: =IF(OR(R73="",R61=""),"",(R73/R61-1)*100) | T73: =IF(COUNT(S25:S72)<48,"",AVERAGE(S25:S72)) | U73: =IF(OR(S73="",T73=""),"",S73-T73) | V73: 1.42 | W73: =IF(OR(V73="",V61=""),"",(V73/V61-1)*100) -> -2.0689655 | X73: =IF(COUNT(W25:W72)<48,"",AVERAGE(W25:W72)) -> -2.6100351 | Y73: =IF(OR(W73="",X73=""),"",W73-X73) -> 0.54106958 | AA73: =IF(OR(Z73="",Z61=""),"",(Z73/Z61-1)*100) | AB73: =IF(COUNT(AA25:AA72)<48,"",AVERAGE(AA25:AA72)) | AC73: =IF(OR(AA73="",AB73=""),"",AA73-AB73)
A74: 1965M10 | B74: 250.22 | C74: =IF(OR(B74="",B62=""),"",(B74/B62-1)*100) -> -0.21932448 | D74: =IF(COUNT(C26:C73)<48,"",AVERAGE(C26:C73)) -> 5.1862509 | E74: =IF(OR(C74="",D74=""),"",C74-D74) -> -5.4055753 | G74: =IF(OR(F74="",F62=""),"",(F74/F62-1)*100) | H74: =IF(COUNT(G26:G73)<48,"",AVERAGE(G26:G73)) | I74: =IF(OR(G74="",H74=""),"",G74-H74) | J74: 1735 | K74: =IF(OR(J74="",J62=""),"",(J74/J62-1)*100) -> -0.34462952 | L74: =IF(COUNT(K26:K73)<48,"",AVERAGE(K26:K73)) -> 0.69089308 | M74: =IF(OR(K74="",L74=""),"",K74-L74) -> -1.0355226 | N74: 1401.92 | O74: =IF(OR(N74="",N62=""),"",(N74/N62-1)*100) -> 3.2136468 | P74: =IF(COUNT(O26:O73)<48,"",AVERAGE(O26:O73)) -> 22.266601 | Q74: =IF(OR(O74="",P74=""),"",O74-P74) -> -19.052955 | S74: =IF(OR(R74="",R62=""),"",(R74/R62-1)*100) | T74: =IF(COUNT(S26:S73)<48,"",AVERAGE(S26:S73)) | U74: =IF(OR(S74="",T74=""),"",S74-T74) | V74: 1.42 | W74: =IF(OR(V74="",V62=""),"",(V74/V62-1)*100) -> -2.0689655 | X74: =IF(COUNT(W26:W73)<48,"",AVERAGE(W26:W73)) -> -2.5764514 | Y74: =IF(OR(W74="",X74=""),"",W74-X74) -> 0.50748591 | AA74: =IF(OR(Z74="",Z62=""),"",(Z74/Z62-1)*100) | AB74: =IF(COUNT(AA26:AA73)<48,"",AVERAGE(AA26:AA73)) | AC74: =IF(OR(AA74="",AB74=""),"",AA74-AB74)
A75: 1965M11 | B75: 250.22 | C75: =IF(OR(B75="",B63=""),"",(B75/B63-1)*100) -> -1.8398651 | D75: =IF(COUNT(C27:C74)<48,"",AVERAGE(C27:C74)) -> 5.1441441 | E75: =IF(OR(C75="",D75=""),"",C75-D75) -> -6.9840091 | G75: =IF(OR(F75="",F63=""),"",(F75/F63-1)*100) | H75: =IF(COUNT(G27:G74)<48,"",AVERAGE(G27:G74)) | I75: =IF(OR(G75="",H75=""),"",G75-H75) | J75: 1735 | K75: =IF(OR(J75="",J63=""),"",(J75/J63-1)*100) -> -0.40183697 | L75: =IF(COUNT(K27:K74)<48,"",AVERAGE(K27:K74)) -> 0.5815265 | M75: =IF(OR(K75="",L75=""),"",K75-L75) -> -0.98336347 | N75: 1469.16 | O75: =IF(OR(N75="",N63=""),"",(N75/N63-1)*100) -> 4.9122732 | P75: =IF(COUNT(O27:O74)<48,"",AVERAGE(O27:O74)) -> 22.273568 | Q75: =IF(OR(O75="",P75=""),"",O75-P75) -> -17.361295 | S75: =IF(OR(R75="",R63=""),"",(R75/R63-1)*100) | T75: =IF(COUNT(S27:S74)<48,"",AVERAGE(S27:S74)) | U75: =IF(OR(S75="",T75=""),"",S75-T75) | V75: 1.42 | W75: =IF(OR(V75="",V63=""),"",(V75/V63-1)*100) -> -2.0689655 | X75: =IF(COUNT(W27:W74)<48,"",AVERAGE(W27:W74)) -> -2.5428678 | Y75: =IF(OR(W75="",X75=""),"",W75-X75) -> 0.47390224 | AA75: =IF(OR(Z75="",Z63=""),"",(Z75/Z63-1)*100) | AB75: =IF(COUNT(AA27:AA74)<48,"",AVERAGE(AA27:AA74)) | AC75: =IF(OR(AA75="",AB75=""),"",AA75-AB75)
A76: 1965M12 | B76: 248.57 | C76: =IF(OR(B76="",B64=""),"",(B76/B64-1)*100) -> -4.8535885 | D76: =IF(COUNT(C28:C75)<48,"",AVERAGE(C28:C75)) -> 5.068276 | E76: =IF(OR(C76="",D76=""),"",C76-D76) -> -9.9218645 | G76: =IF(OR(F76="",F64=""),"",(F76/F64-1)*100) | H76: =IF(COUNT(G28:G75)<48,"",AVERAGE(G28:G75)) | I76: =IF(OR(G76="",H76=""),"",G76-H76) | J76: 1735 | K76: =IF(OR(J76="",J64=""),"",(J76/J64-1)*100) -> -0.40183697 | L76: =IF(COUNT(K28:K75)<48,"",AVERAGE(K28:K75)) -> 0.4709681 | M76: =IF(OR(K76="",L76=""),"",K76-L76) -> -0.87280507 | N76: 1517.66 | O76: =IF(OR(N76="",N64=""),"",(N76/N64-1)*100) -> 19.576111 | P76: =IF(COUNT(O28:O75)<48,"",AVERAGE(O28:O75)) -> 22.407864 | Q76: =IF(OR(O76="",P76=""),"",O76-P76) -> -2.8317535 | S76: =IF(OR(R76="",R64=""),"",(R76/R64-1)*100) | T76: =IF(COUNT(S28:S75)<48,"",AVERAGE(S28:S75)) | U76: =IF(OR(S76="",T76=""),"",S76-T76) | V76: 1.42 | W76: =IF(OR(V76="",V64=""),"",(V76/V64-1)*100) -> -2.0689655 | X76: =IF(COUNT(W28:W75)<48,"",AVERAGE(W28:W75)) -> -2.5092841 | Y76: =IF(OR(W76="",X76=""),"",W76-X76) -> 0.44031858 | AA76: =IF(OR(Z76="",Z64=""),"",(Z76/Z64-1)*100) | AB76: =IF(COUNT(AA28:AA75)<48,"",AVERAGE(AA28:AA75)) | AC76: =IF(OR(AA76="",AB76=""),"",AA76-AB76)
...

Sheet 02_shock_T2
A1: Theme 2 — Shock Pertumbuhan Mitra Dagang
A2: d^g_c = WEO Apr2026 − Apr2025 (tahun 2026). x_k = JUMLAH_c ( w_kc × d^g_c )
A4: BLOK A — revisi ramalan per negara
A5: negara | B5: WEO Apr2026 | C5: WEO Apr2025 | D5: d^g_c (rumus)
A6: ABW | B6: 2.3 | C6: 2.58 | D6: =B6-C6 -> -0.28
A7: AGO | B7: 2.3 | C7: 2.076 | D7: =B7-C7 -> 0.224
A8: ALB | B8: 3.4 | C8: 3.468 | D8: =B8-C8 -> -0.068
A9: AND | B9: 2.1 | C9: 1.6 | D9: =B9-C9 -> 0.5
A10: ARE | B10: 3.1 | C10: 4.986 | D10: =B10-C10 -> -1.886
A11: ARG | B11: 3.5 | C11: 4.52 | D11: =B11-C11 -> -1.02
A12: ARM | B12: 5.3 | C12: 4.5 | D12: =B12-C12 -> 0.8
A13: ATG | B13: 2.6 | C13: 2.541 | D13: =B13-C13 -> 0.059
A14: AUS | B14: 2 | C14: 2.078 | D14: =B14-C14 -> -0.078
A15: AUT | B15: 0.7 | C15: 0.775 | D15: =B15-C15 -> -0.075
A16: AZE | B16: 2.2 | C16: 2.498 | D16: =B16-C16 -> -0.298
A17: BDI | B17: 3.8 | C17: 2.589 | D17: =B17-C17 -> 1.211
... A185: ZWE | B185: 5 | C185: 4.64 | D185: =B185-C185 -> 0.36
A188: BLOK B — bobot ekspor × revisi
A189: sector_52 | B189: sector_name | C189: country_iso | D189: w_kc | E189: d^g_c (VLOOKUP) | F189: w × d^g
A190: 2 | B190: HortiCrops | C190: AFG | D190: 0.00068825127 | E190: =IFERROR(VLOOKUP(C190,$A$6:$D$185,4,FALSE),0) -> 0 | F190: =D190*E190 -> 0
A191: 2 | B191: HortiCrops | C191: ARE | D191: 0.028168011 | E191: =IFERROR(VLOOKUP(C191,$A$6:$D$185,4,FALSE),0) -> -1.886 | F191: =D191*E191 -> -0.053124869
A192: 2 | B192: HortiCrops | C192: ARG | D192: 0.00014551452 | E192: =IFERROR(VLOOKUP(C192,$A$6:$D$185,4,FALSE),0) -> -1.02 | F192: =D192*E192 -> -0.00014842481
A193: 2 | B193: HortiCrops | C193: AUS | D193: 0.002029196 | E193: =IFERROR(VLOOKUP(C193,$A$6:$D$185,4,FALSE),0) -> -0.078 | F193: =D193*E193 -> -0.00015827729
A194: 2 | B194: HortiCrops | C194: AUT | D194: 2.9262384e-07 | E194: =IFERROR(VLOOKUP(C194,$A$6:$D$185,4,FALSE),0) -> -0.075 | F194: =D194*E194 -> -2.1946788e-08
A195: 2 | B195: HortiCrops | C195: BEL | D195: 3.636364e-05 | E195: =IFERROR(VLOOKUP(C195,$A$6:$D$185,4,FALSE),0) -> -0.269 | F195: =D195*E195 -> -9.7818192e-06
A196: 2 | B196: HortiCrops | C196: BEN | D196: 1.5187787e-05 | E196: =IFERROR(VLOOKUP(C196,$A$6:$D$185,4,FALSE),0) -> 0.814 | F196: =D196*E196 -> 1.2362859e-05
A197: 2 | B197: HortiCrops | C197: BFA | D197: 7.315596e-08 | E197: =IFERROR(VLOOKUP(C197,$A$6:$D$185,4,FALSE),0) -> 0.372 | F197: =D197*E197 -> 2.7214017e-08
A198: 2 | B198: HortiCrops | C198: BGD | D198: 0.066659751 | E198: =IFERROR(VLOOKUP(C198,$A$6:$D$185,4,FALSE),0) -> -1.83 | F198: =D198*E198 -> -0.12198735
A199: 2 | B199: HortiCrops | C199: BGR | D199: 9.380935e-05 | E199: =IFERROR(VLOOKUP(C199,$A$6:$D$185,4,FALSE),0) -> 0.147 | F199: =D199*E199 -> 1.3789974e-05
A200: 2 | B200: HortiCrops | C200: BHR | D200: 0.0001319975 | E200: =IFERROR(VLOOKUP(C200,$A$6:$D$185,4,FALSE),0) -> -3.494 | F200: =D200*E200 -> -0.00046119927
A201: 2 | B201: HortiCrops | C201: BRA | D201: 0.00040012113 | E201: =IFERROR(VLOOKUP(C201,$A$6:$D$185,4,FALSE),0) -> -0.084 | F201: =D201*E201 -> -3.3610175e-05
... A3296: 27 | B3296: OtherMan | C3296: ZAF | D3296: 0.0010329292 | E3296: =IFERROR(VLOOKUP(C3296,$A$6:$D$185,4,FALSE),0) -> -0.289 | F3296: =D3296*E3296 -> -0.00029851654
A3299: BLOK C — x_k per sektor (SUMIF atas Blok B)
A3300: sector_52 | B3300: sector_name | C3300: x_k (manual) | D3300: dashboard | E3300: selisih
A3301: 2 | B3301: HortiCrops | C3301: =SUMIF($A$190:$A$3296,A3301,$F$190:$F$3296) -> -0.87800091 | D3301: -0.87800091 | E3301: =C3301-D3301 -> 0
A3302: 3 | B3302: Estates | C3302: =SUMIF($A$190:$A$3296,A3302,$F$190:$F$3296) -> 0.22714337 | D3302: 0.22714337 | E3302: =C3302-D3302 -> 0
A3303: 6 | B3303: Forestry | C3303: =SUMIF($A$190:$A$3296,A3303,$F$190:$F$3296) -> 0.16702107 | D3303: 0.16702107 | E3303: =C3303-D3303 -> 0
A3304: 7 | B3304: Fishery | C3304: =SUMIF($A$190:$A$3296,A3304,$F$190:$F$3296) -> 0.44210939 | D3304: 0.44210939 | E3304: =C3304-D3304 -> 0
A3305: 8 | B3305: Coal | C3305: =SUMIF($A$190:$A$3296,A3305,$F$190:$F$3296) -> 0.23018091 | D3305: 0.23018091 | E3305: =C3305-D3305 -> 0
A3306: 9 | B3306: OilGasGeo | C3306: =SUMIF($A$190:$A$3296,A3306,$F$190:$F$3296) -> 0.9329143 | D3306: 0.9329143 | E3306: =C3306-D3306 -> 0
...

Sheet 03_shock_T3
A1: Theme 3 — Shock Permintaan Domestik
A2: x_i = g_yoy(t) − rata-rata 48 periode g_yoy (lag 1). Sumber: BI Survei Penjualan Eceran
A4: Panel sudah dideduplikasi (ambil baris terakhir per kategori+bulan) — lihat 12_catatan G3
A5: kategori | B5: tanggal | C5: g_yoy | D5: tren48 (rumus) | E5: x_i (rumus)
A6: cultural_rec | B6: 2012-01 | C6: 4.2
A7: cultural_rec | B7: 2012-02 | C7: 19
A8: cultural_rec | B8: 2012-03 | C8: 8.9
A9: cultural_rec | B9: 2012-04 | C9: 3.1
A10: cultural_rec | B10: 2012-05 | C10: 1.1
A11: cultural_rec | B11: 2012-06 | C11: 4
A12: cultural_rec | B12: 2012-07 | C12: -3.4
A13: cultural_rec | B13: 2012-08 | C13: 10.7
A14: cultural_rec | B14: 2012-09 | C14: 4.4
A15: cultural_rec | B15: 2012-10 | C15: 5.8
A16: cultural_rec | B16: 2012-11 | C16: -3.6
A17: cultural_rec | B17: 2012-12 | C17: -18.2
... A53: cultural_rec | B53: 2016-01 | C53: -2.2
A54: cultural_rec | B54: 2016-02 | C54: -0.7 | D54: =AVERAGE(C6:C53) -> 0.80208333 | E54: =C54-D54 -> -1.5020833
A55: cultural_rec | B55: 2016-03 | C55: -5.1 | D55: =AVERAGE(C7:C54) -> 0.7 | E55: =C55-D55 -> -5.8
A56: cultural_rec | B56: 2016-04 | C56: 5 | D56: =AVERAGE(C8:C55) -> 0.19791667 | E56: =C56-D56 -> 4.8020833
A57: cultural_rec | B57: 2016-05 | C57: -1.7 | D57: =AVERAGE(C9:C56) -> 0.11666667 | E57: =C57-D57 -> -1.8166667
A58: cultural_rec | B58: 2016-06 | C58: 7.6 | D58: =AVERAGE(C10:C57) -> 0.016666667 | E58: =C58-D58 -> 7.5833333
A59: cultural_rec | B59: 2016-07 | C59: 2 | D59: =AVERAGE(C11:C58) -> 0.15208333 | E59: =C59-D59 -> 1.8479167
A60: cultural_rec | B60: 2016-08 | C60: 7.6 | D60: =AVERAGE(C12:C59) -> 0.11041667 | E60: =C60-D60 -> 7.4895833
A61: cultural_rec | B61: 2016-09 | C61: 15.4 | D61: =AVERAGE(C13:C60) -> 0.33958333 | E61: =C61-D61 -> 15.060417
A62: cultural_rec | B62: 2016-10 | C62: 12.1 | D62: =AVERAGE(C14:C61) -> 0.4375 | E62: =C62-D62 -> 11.6625
A63: cultural_rec | B63: 2016-11 | C63: 10.7 | D63: =AVERAGE(C15:C62) -> 0.59791667 | E63: =C63-D63 -> 10.102083
A64: cultural_rec | B64: 2016-12 | C64: 12 | D64: =AVERAGE(C16:C63) -> 0.7 | E64: =C64-D64 -> 11.3
A65: cultural_rec | B65: 2017-01 | C65: 7.8 | D65: =AVERAGE(C17:C64) -> 1.025 | E65: =C65-D65 -> 6.775
... A161: cultural_rec | B161: 2026-05 | C161: -0.1 | D161: =AVERAGE(C113:C160) -> -3.8541667 | E161: =C161-D161 -> 3.7541667
A162: food_bev_tobacco | B162: 2012-01 | C162: 15.1
A163: food_bev_tobacco | B163: 2012-02 | C163: 11.4
A164: food_bev_tobacco | B164: 2012-03 | C164: 13.4
A165: food_bev_tobacco | B165: 2012-04 | C165: 9.9
A166: food_bev_tobacco | B166: 2012-05 | C166: 5.1
A167: food_bev_tobacco | B167: 2012-06 | C167: 11.8
A168: food_bev_tobacco | B168: 2012-07 | C168: 19.9
A169: food_bev_tobacco | B169: 2012-08 | C169: 6.7
A170: food_bev_tobacco | B170: 2012-09 | C170: 19.9
A171: food_bev_tobacco | B171: 2012-10 | C171: 16.5
...

Sheet 04_L0
A1: Tenaga Kerja Awal L0
A2: Sumber: rawdata/lo.csv (4 provinsi pemekaran Papua 2022 dikeluarkan)
A4: sektor | B4: 1100_ACEH | C4: 1200_SUMATERA UTARA | D4: 1300_SUMATERA BARAT | E4: 1400_RIAU | F4: 1500_JAMBI | G4: 1600_SUMATERA SELATAN | H4: 1700_BENGKULU | I4: 1800_LAMPUNG | J4: 1900_KEPULAUAN BANGKA BELITUNG | K4: 2100_KEPULAUAN RIAU | L4: 3100_DKI JAKARTA | M4: 3200_JAWA BARAT | N4: 3300_JAWA TENGAH | O4: 3400_DI YOGYAKARTA | P4: 3500_JAWA TIMUR | Q4: 3600_BANTEN | R4: 5100_BALI | S4: 5200_NUSA TENGGARA BARAT | T4: 5300_NUSA TENGGARA TIMUR | U4: 6100_KALIMANTAN BARAT | V4: 6200_KALIMANTAN TENGAH | W4: 6300_KALIMANTAN SELATAN | X4: 6400_KALIMANTAN TIMUR | Y4: 6500_KALIMANTAN UTARA | Z4: 7100_SULAWESI UTARA | AA4: 7200_SULAWESI TENGAH | AB4: 7300_SULAWESI SELATAN | AC4: 7400_SULAWESI TENGGARA | AD4: 7500_GORONTALO | AE4: 7600_SULAWESI BARAT | AF4: 8100_MALUKU | AG4: 8200_MALUKU UTARA | AH4: 9100_PAPUA BARAT | AI4: 9400_PAPUA
A5: 01_FoodCrops | B5: 385372 | C5: 947858 | D5: 464112 | E5: 53193 | F5: 97754 | G5: 414195 | H5: 80738 | I5: 805007 | J5: 18439 | K5: 9627 | L5: 1202 | M5: 2537240 | N5: 2897863 | O5: 174812 | P5: 3283899 | Q5: 561944 | R5: 142477 | S5: 480467 | T5: 759711 | U5: 369314 | V5: 92917 | W5: 266241 | X5: 98178 | Y5: 42637 | Z5: 93055 | AA5: 220593 | AB5: 875856 | AC5: 155487 | AD5: 126806 | AE5: 102597 | AF5: 146055 | AG5: 48510 | AH5: 90148 | AI5: 63576
A6: 02_HortiCrops | B6: 116948 | C6: 567920 | D6: 231201 | E6: 158510 | F6: 295748 | G6: 896935 | H6: 112711 | I6: 381173 | J6: 48898 | K6: 14483 | L6: 25 | M6: 339616 | N6: 519985 | O6: 57171 | P6: 498743 | Q6: 61661 | R6: 103427 | S6: 58887 | T6: 285284 | U6: 364028 | V6: 102967 | W6: 196023 | X6: 45780 | Y6: 3262 | Z6: 140577 | AA6: 162644 | AB6: 265811 | AC6: 152495 | AD6: 19106 | AE6: 21164 | AF6: 69497 | AG6: 78099 | AH6: 7654 | AI6: 17792
A7: 03_Estates | B7: 315856 | C7: 733236 | D7: 170720 | E7: 813721 | F7: 370156 | G7: 622962 | H7: 272238 | I7: 373757 | J7: 87811 | K7: 5668 | L7: 3407 | M7: 142494 | N7: 515521 | O7: 7661 | P7: 1243147 | Q7: 27207 | R7: 40989 | S7: 226340 | T7: 168354 | U7: 506422 | V7: 231876 | W7: 75752 | X7: 148250 | Y7: 26507 | Z7: 68108 | AA7: 193202 | AB7: 131569 | AC7: 65319 | AD7: 18850 | AE7: 166389 | AF7: 40531 | AG7: 127835 | AH7: 5597 | AI7: 6146
A8: 04_Livestock | B8: 25115 | C8: 131976 | D8: 48000 | E8: 22978 | F8: 8206 | G8: 31104 | H8: 10377 | I8: 271209 | J8: 3417 | K8: 2690 | L8: 4757 | M8: 471677 | N8: 1091681 | O8: 169295 | P8: 1957838 | Q8: 49725 | R8: 174456 | S8: 280884 | T8: 211110 | U8: 20650 | V8: 13657 | W8: 28653 | X8: 8561 | Y8: 5016 | Z8: 6425 | AA8: 15273 | AB8: 167986 | AC8: 19688 | AD8: 8014 | AE8: 33477 | AF8: 5087 | AG8: 943 | AH8: 3345 | AI8: 7496
A9: 05_AgricService | B9: 74074 | C9: 153141 | D9: 52464 | E9: 57369 | F9: 21480 | G9: 63694 | H9: 18297 | I9: 102594 | J9: 9908 | K9: 24997 | L9: 89708 | M9: 500041 | N9: 369838 | O9: 15383 | P9: 428660 | Q9: 139422 | R9: 36305 | S9: 55066 | T9: 20231 | U9: 39579 | V9: 25308 | W9: 50861 | X9: 25758 | Y9: 5175 | Z9: 20458 | AA9: 25033 | AB9: 68872 | AC9: 15241 | AD9: 10987 | AE9: 8142 | AF9: 9199 | AG9: 7608 | AH9: 2754 | AI9: 6224
A10: 06_Forestry | B10: 9929 | C10: 26247 | D10: 13602 | E10: 23210 | F10: 9809 | G10: 17225 | H10: 2369 | I10: 14671 | J10: 2978 | K10: 2101 | L10: 0 | M10: 67539 | N10: 116662 | O10: 9111 | P10: 116866 | Q10: 29270 | R10: 6138 | S10: 11510 | T10: 20311 | U10: 21866 | V10: 20432 | W10: 16756 | X10: 11001 | Y10: 5318 | Z10: 3962 | AA10: 9936 | AB10: 7784 | AC10: 10667 | AD10: 3156 | AE10: 2065 | AF10: 3705 | AG10: 5168 | AH10: 2781 | AI10: 4917
A11: 07_Fishery | B11: 66429 | C11: 129511 | D11: 32716 | E11: 50137 | F11: 20072 | G11: 41219 | H11: 8332 | I11: 73889 | J11: 27126 | K11: 38050 | L11: 15409 | M11: 110773 | N11: 200564 | O11: 7407 | P11: 250007 | Q11: 39848 | R11: 15140 | S11: 62213 | T11: 72855 | U11: 41059 | V11: 33268 | W11: 39829 | X11: 42012 | Y11: 37619 | Z11: 39613 | AA11: 63640 | AB11: 188688 | AC11: 88906 | AD11: 19451 | AE11: 26073 | AF11: 49332 | AG11: 23532 | AH11: 13531 | AI11: 36084
A12: 08_Coal | B12: 1860 | C12: 148 | D12: 4210 | E12: 3575 | F12: 9381 | G12: 39037 | H12: 4375 | I12: 703 | J12: 0 | K12: 65 | L12: 1117 | M12: 3770 | N12: 2344 | O12: 0 | P12: 5690 | Q12: 5490 | R12: 0 | S12: 0 | T12: 0 | U12: 219 | V12: 20842 | W12: 68642 | X12: 134526 | Y12: 9056 | Z12: 1723 | AA12: 151 | AB12: 1191 | AC12: 0 | AD12: 128 | AE12: 139 | AF12: 0 | AG12: 0 | AH12: 0 | AI12: 0
A13: 09_OilGasGeo | B13: 4640 | C13: 5175 | D13: 1221 | E13: 28022 | F13: 9526 | G13: 24777 | H13: 166 | I13: 3912 | J13: 0 | K13: 6460 | L13: 1846 | M13: 50023 | N13: 8820 | O13: 893 | P13: 14959 | Q13: 6790 | R13: 231 | S13: 296 | T13: 0 | U13: 116 | V13: 531 | W13: 465 | X13: 12981 | Y13: 1887 | Z13: 694 | AA13: 4144 | AB13: 1085 | AC13: 88 | AD13: 0 | AE13: 0 | AF13: 563 | AG13: 199 | AH13: 868 | AI13: 238
A14: 10_IronOre | B14: 29847 | C14: 70154 | D14: 56336 | E14: 19106 | F14: 53641 | G14: 38761 | H14: 10196 | I14: 83835 | J14: 117658 | K14: 6103 | L14: 6159 | M14: 161128 | N14: 162725 | O14: 11934 | P14: 169282 | Q14: 56286 | R14: 11321 | S14: 73160 | T14: 19898 | U14: 77439 | V14: 115865 | W14: 25588 | X14: 17496 | Y14: 1208 | Z14: 40090 | AA14: 29896 | AB14: 51051 | AC14: 41597 | AD14: 19892 | AE14: 6574 | AF14: 17645 | AG14: 15922 | AH14: 1841 | AI14: 2565
A15: 11_OtherMine | B15: 384 | C15: 824 | D15: 0 | E15: 7903 | F15: 0 | G15: 1199 | H15: 0 | I15: 137 | J15: 83 | K15: 1011 | L15: 3926 | M15: 4745 | N15: 21770 | O15: 0 | P15: 20065 | Q15: 1372 | R15: 745 | S15: 2807 | T15: 2672 | U15: 270 | V15: 1148 | W15: 2162 | X15: 8039 | Y15: 276 | Z15: 604 | AA15: 316 | AB15: 6371 | AC15: 61 | AD15: 107 | AE15: 0 | AF15: 125 | AG15: 369 | AH15: 0 | AI15: 250
A16: 12_FoodMan | B16: 76692 | C16: 301778 | D16: 126078 | E16: 143552 | F16: 41678 | G16: 119592 | H16: 32173 | I16: 213407 | J16: 43721 | K16: 43944 | L16: 141910 | M16: 1184237 | N16: 1084016 | O16: 119500 | P16: 1040643 | Q16: 256055 | R16: 86834 | S16: 96867 | T16: 80491 | U16: 82300 | V16: 42082 | W16: 68335 | X16: 63413 | Y16: 12439 | Z16: 65278 | AA16: 55342 | AB16: 187234 | AC16: 56637 | AD16: 27767 | AE16: 35124 | AF16: 58483 | AG16: 37145 | AH16: 7582 | AI16: 11121
... A56: 52_OtherSvc | B56: 219 | C56: 93 | D56: 199 | E56: 152 | F56: 147 | G56: 0 | H56: 0 | I56: 524 | J56: 262 | K56: 0 | L56: 0 | M56: 192 | N56: 2433 | O56: 1339 | P56: 2553 | Q56: 0 | R56: 489 | S56: 317 | T56: 0 | U56: 0 | V56: 0 | W56: 456 | X56: 159 | Y56: 48 | Z56: 0 | AA56: 177 | AB56: 445 | AC56: 153 | AD56: 82 | AE56: 0 | AF56: 0 | AG56: 31 | AH56: 0 | AI56: 0

Sheet 05_shares
A1: Pangsa Provinsi per Sektor
A2: share[s,p] = L0[s,p] / total baris — setiap baris berjumlah 1
A4: sektor | B4: 1100_ACEH | C4: 1200_SUMATERA UTARA | D4: 1300_SUMATERA BARAT | E4: 1400_RIAU | F4: 1500_JAMBI | G4: 1600_SUMATERA SELATAN | H4: 1700_BENGKULU | I4: 1800_LAMPUNG | J4: 1900_KEPULAUAN BANGKA BELITUNG | K4: 2100_KEPULAUAN RIAU | L4: 3100_DKI JAKARTA | M4: 3200_JAWA BARAT | N4: 3300_JAWA TENGAH | O4: 3400_DI YOGYAKARTA | P4: 3500_JAWA TIMUR | Q4: 3600_BANTEN | R4: 5100_BALI | S4: 5200_NUSA TENGGARA BARAT | T4: 5300_NUSA TENGGARA TIMUR | U4: 6100_KALIMANTAN BARAT | V4: 6200_KALIMANTAN TENGAH | W4: 6300_KALIMANTAN SELATAN | X4: 6400_KALIMANTAN TIMUR | Y4: 6500_KALIMANTAN UTARA | Z4: 7100_SULAWESI UTARA | AA4: 7200_SULAWESI TENGAH | AB4: 7300_SULAWESI SELATAN | AC4: 7400_SULAWESI TENGGARA | AD4: 7500_GORONTALO | AE4: 7600_SULAWESI BARAT | AF4: 8100_MALUKU | AG4: 8200_MALUKU UTARA | AH4: 9100_PAPUA BARAT | AI4: 9400_PAPUA
A5: 01_FoodCrops | B5: =IF(SUM('04_L0'!$B5:$AI5)=0,0,'04_L0'!B5/SUM('04_L0'!$B5:$AI5)) -> 0.022792449 | C5: =IF(SUM('04_L0'!$B5:$AI5)=0,0,'04_L0'!C5/SUM('04_L0'!$B5:$AI5)) -> 0.056060133 | D5: =IF(SUM('04_L0'!$B5:$AI5)=0,0,'04_L0'!D5/SUM('04_L0'!$B5:$AI5)) -> 0.02744945 | E5: =IF(SUM('04_L0'!$B5:$AI5)=0,0,'04_L0'!E5/SUM('04_L0'!$B5:$AI5)) -> 0.0031460479 | F5: =IF(SUM('04_L0'!$B5:$AI5)=0,0,'04_L0'!F5/SUM('04_L0'!$B5:$AI5)) -> 0.0057815646 | G5: =IF(SUM('04_L0'!$B5:$AI5)=0,0,'04_L0'!G5/SUM('04_L0'!$B5:$AI5)) -> 0.024497158 | H5: =IF(SUM('04_L0'!$B5:$AI5)=0,0,'04_L0'!H5/SUM('04_L0'!$B5:$AI5)) -> 0.0047751699 | I5: =IF(SUM('04_L0'!$B5:$AI5)=0,0,'04_L0'!I5/SUM('04_L0'!$B5:$AI5)) -> 0.04761135 | ... AI5: =IF(SUM('04_L0'!$B5:$AI5)=0,0,'04_L0'!AI5/SUM('04_L0'!$B5:$AI5)) -> 0.0037601402
A6: 02_HortiCrops | B6: =IF(SUM('04_L0'!$B6:$AI6)=0,0,'04_L0'!B6/SUM('04_L0'!$B6:$AI6)) -> 0.01828391 | C6: =IF(SUM('04_L0'!$B6:$AI6)=0,0,'04_L0'!C6/SUM('04_L0'!$B6:$AI6)) -> 0.088789872 | D6: =IF(SUM('04_L0'!$B6:$AI6)=0,0,'04_L0'!D6/SUM('04_L0'!$B6:$AI6)) -> 0.036146477 | E6: =IF(SUM('04_L0'!$B6:$AI6)=0,0,'04_L0'!E6/SUM('04_L0'!$B6:$AI6)) -> 0.024781805 | F6: =IF(SUM('04_L0'!$B6:$AI6)=0,0,'04_L0'!F6/SUM('04_L0'!$B6:$AI6)) -> 0.046237898 | G6: =IF(SUM('04_L0'!$B6:$AI6)=0,0,'04_L0'!G6/SUM('04_L0'!$B6:$AI6)) -> 0.14022881 | H6: =IF(SUM('04_L0'!$B6:$AI6)=0,0,'04_L0'!H6/SUM('04_L0'!$B6:$AI6)) -> 0.017621488 | I6: =IF(SUM('04_L0'!$B6:$AI6)=0,0,'04_L0'!I6/SUM('04_L0'!$B6:$AI6)) -> 0.059593432 | ... AI6: =IF(SUM('04_L0'!$B6:$AI6)=0,0,'04_L0'!AI6/SUM('04_L0'!$B6:$AI6)) -> 0.0027816407
A7: 03_Estates | B7: =IF(SUM('04_L0'!$B7:$AI7)=0,0,'04_L0'!B7/SUM('04_L0'!$B7:$AI7)) -> 0.039712342 | C7: =IF(SUM('04_L0'!$B7:$AI7)=0,0,'04_L0'!C7/SUM('04_L0'!$B7:$AI7)) -> 0.092189221 | D7: =IF(SUM('04_L0'!$B7:$AI7)=0,0,'04_L0'!D7/SUM('04_L0'!$B7:$AI7)) -> 0.021464499 | E7: =IF(SUM('04_L0'!$B7:$AI7)=0,0,'04_L0'!E7/SUM('04_L0'!$B7:$AI7)) -> 0.10230854 | F7: =IF(SUM('04_L0'!$B7:$AI7)=0,0,'04_L0'!F7/SUM('04_L0'!$B7:$AI7)) -> 0.04653944 | G7: =IF(SUM('04_L0'!$B7:$AI7)=0,0,'04_L0'!G7/SUM('04_L0'!$B7:$AI7)) -> 0.078324552 | H7: =IF(SUM('04_L0'!$B7:$AI7)=0,0,'04_L0'!H7/SUM('04_L0'!$B7:$AI7)) -> 0.034228283 | I7: =IF(SUM('04_L0'!$B7:$AI7)=0,0,'04_L0'!I7/SUM('04_L0'!$B7:$AI7)) -> 0.046992191 | ... AI7: =IF(SUM('04_L0'!$B7:$AI7)=0,0,'04_L0'!AI7/SUM('04_L0'!$B7:$AI7)) -> 0.00077273204
A8: 04_Livestock | B8: =IF(SUM('04_L0'!$B8:$AI8)=0,0,'04_L0'!B8/SUM('04_L0'!$B8:$AI8)) -> 0.004729073 | C8: =IF(SUM('04_L0'!$B8:$AI8)=0,0,'04_L0'!C8/SUM('04_L0'!$B8:$AI8)) -> 0.024850652 | D8: =IF(SUM('04_L0'!$B8:$AI8)=0,0,'04_L0'!D8/SUM('04_L0'!$B8:$AI8)) -> 0.0090382442 | E8: =IF(SUM('04_L0'!$B8:$AI8)=0,0,'04_L0'!E8/SUM('04_L0'!$B8:$AI8)) -> 0.0043266828 | F8: =IF(SUM('04_L0'!$B8:$AI8)=0,0,'04_L0'!F8/SUM('04_L0'!$B8:$AI8)) -> 0.0015451632 | G8: =IF(SUM('04_L0'!$B8:$AI8)=0,0,'04_L0'!G8/SUM('04_L0'!$B8:$AI8)) -> 0.0058567822 | H8: =IF(SUM('04_L0'!$B8:$AI8)=0,0,'04_L0'!H8/SUM('04_L0'!$B8:$AI8)) -> 0.0019539554 | I8: =IF(SUM('04_L0'!$B8:$AI8)=0,0,'04_L0'!I8/SUM('04_L0'!$B8:$AI8)) -> 0.051067774 | ... AI8: =IF(SUM('04_L0'!$B8:$AI8)=0,0,'04_L0'!AI8/SUM('04_L0'!$B8:$AI8)) -> 0.0014114725
A9: 05_AgricService | B9: =IF(SUM('04_L0'!$B9:$AI9)=0,0,'04_L0'!B9/SUM('04_L0'!$B9:$AI9)) -> 0.029004597 | C9: =IF(SUM('04_L0'!$B9:$AI9)=0,0,'04_L0'!C9/SUM('04_L0'!$B9:$AI9)) -> 0.059964266 | D9: =IF(SUM('04_L0'!$B9:$AI9)=0,0,'04_L0'!D9/SUM('04_L0'!$B9:$AI9)) -> 0.020542933 | E9: =IF(SUM('04_L0'!$B9:$AI9)=0,0,'04_L0'!E9/SUM('04_L0'!$B9:$AI9)) -> 0.022463547 | F9: =IF(SUM('04_L0'!$B9:$AI9)=0,0,'04_L0'!F9/SUM('04_L0'!$B9:$AI9)) -> 0.0084107615 | G9: =IF(SUM('04_L0'!$B9:$AI9)=0,0,'04_L0'!G9/SUM('04_L0'!$B9:$AI9)) -> 0.024940179 | H9: =IF(SUM('04_L0'!$B9:$AI9)=0,0,'04_L0'!H9/SUM('04_L0'!$B9:$AI9)) -> 0.0071644182 | I9: =IF(SUM('04_L0'!$B9:$AI9)=0,0,'04_L0'!I9/SUM('04_L0'!$B9:$AI9)) -> 0.040171959 | ... AI9: =IF(SUM('04_L0'!$B9:$AI9)=0,0,'04_L0'!AI9/SUM('04_L0'!$B9:$AI9)) -> 0.0024370847
A10: 06_Forestry | B10: =IF(SUM('04_L0'!$B10:$AI10)=0,0,'04_L0'!B10/SUM('04_L0'!$B10:$AI10)) -> 0.015783818 | C10: =IF(SUM('04_L0'!$B10:$AI10)=0,0,'04_L0'!C10/SUM('04_L0'!$B10:$AI10)) -> 0.041724027 | D10: =IF(SUM('04_L0'!$B10:$AI10)=0,0,'04_L0'!D10/SUM('04_L0'!$B10:$AI10)) -> 0.02162267 | E10: =IF(SUM('04_L0'!$B10:$AI10)=0,0,'04_L0'!E10/SUM('04_L0'!$B10:$AI10)) -> 0.036896204 | F10: =IF(SUM('04_L0'!$B10:$AI10)=0,0,'04_L0'!F10/SUM('04_L0'!$B10:$AI10)) -> 0.015593058 | G10: =IF(SUM('04_L0'!$B10:$AI10)=0,0,'04_L0'!G10/SUM('04_L0'!$B10:$AI10)) -> 0.027382039 | H10: =IF(SUM('04_L0'!$B10:$AI10)=0,0,'04_L0'!H10/SUM('04_L0'!$B10:$AI10)) -> 0.0037659245 | I10: =IF(SUM('04_L0'!$B10:$AI10)=0,0,'04_L0'!I10/SUM('04_L0'!$B10:$AI10)) -> 0.023322025 | ... AI10: =IF(SUM('04_L0'!$B10:$AI10)=0,0,'04_L0'!AI10/SUM('04_L0'!$B10:$AI10)) -> 0.0078163997
A11: 07_Fishery | B11: =IF(SUM('04_L0'!$B11:$AI11)=0,0,'04_L0'!B11/SUM('04_L0'!$B11:$AI11)) -> 0.03314268 | C11: =IF(SUM('04_L0'!$B11:$AI11)=0,0,'04_L0'!C11/SUM('04_L0'!$B11:$AI11)) -> 0.064615478 | D11: =IF(SUM('04_L0'!$B11:$AI11)=0,0,'04_L0'!D11/SUM('04_L0'!$B11:$AI11)) -> 0.016322629 | E11: =IF(SUM('04_L0'!$B11:$AI11)=0,0,'04_L0'!E11/SUM('04_L0'!$B11:$AI11)) -> 0.025014294 | F11: =IF(SUM('04_L0'!$B11:$AI11)=0,0,'04_L0'!F11/SUM('04_L0'!$B11:$AI11)) -> 0.010014299 | G11: =IF(SUM('04_L0'!$B11:$AI11)=0,0,'04_L0'!G11/SUM('04_L0'!$B11:$AI11)) -> 0.020564936 | H11: =IF(SUM('04_L0'!$B11:$AI11)=0,0,'04_L0'!H11/SUM('04_L0'!$B11:$AI11)) -> 0.0041569918 | I11: =IF(SUM('04_L0'!$B11:$AI11)=0,0,'04_L0'!I11/SUM('04_L0'!$B11:$AI11)) -> 0.036864614 | ... AI11: =IF(SUM('04_L0'!$B11:$AI11)=0,0,'04_L0'!AI11/SUM('04_L0'!$B11:$AI11)) -> 0.018002988
A12: 08_Coal | B12: =IF(SUM('04_L0'!$B12:$AI12)=0,0,'04_L0'!B12/SUM('04_L0'!$B12:$AI12)) -> 0.0058420388 | C12: =IF(SUM('04_L0'!$B12:$AI12)=0,0,'04_L0'!C12/SUM('04_L0'!$B12:$AI12)) -> 0.0004648504 | D12: =IF(SUM('04_L0'!$B12:$AI12)=0,0,'04_L0'!D12/SUM('04_L0'!$B12:$AI12)) -> 0.013223109 | E12: =IF(SUM('04_L0'!$B12:$AI12)=0,0,'04_L0'!E12/SUM('04_L0'!$B12:$AI12)) -> 0.01122865 | F12: =IF(SUM('04_L0'!$B12:$AI12)=0,0,'04_L0'!F12/SUM('04_L0'!$B12:$AI12)) -> 0.029464605 | G12: =IF(SUM('04_L0'!$B12:$AI12)=0,0,'04_L0'!G12/SUM('04_L0'!$B12:$AI12)) -> 0.12261057 | H12: =IF(SUM('04_L0'!$B12:$AI12)=0,0,'04_L0'!H12/SUM('04_L0'!$B12:$AI12)) -> 0.013741355 | I12: =IF(SUM('04_L0'!$B12:$AI12)=0,0,'04_L0'!I12/SUM('04_L0'!$B12:$AI12)) -> 0.0022080394 | ... AI12: =IF(SUM('04_L0'!$B12:$AI12)=0,0,'04_L0'!AI12/SUM('04_L0'!$B12:$AI12)) -> 0
A13: 09_OilGasGeo | B13: =IF(SUM('04_L0'!$B13:$AI13)=0,0,'04_L0'!B13/SUM('04_L0'!$B13:$AI13)) -> 0.024215097 | C13: =IF(SUM('04_L0'!$B13:$AI13)=0,0,'04_L0'!C13/SUM('04_L0'!$B13:$AI13)) -> 0.027007139 | D13: =IF(SUM('04_L0'!$B13:$AI13)=0,0,'04_L0'!D13/SUM('04_L0'!$B13:$AI13)) -> 0.0063721192 | E13: =IF(SUM('04_L0'!$B13:$AI13)=0,0,'04_L0'!E13/SUM('04_L0'!$B13:$AI13)) -> 0.1462404 | F13: =IF(SUM('04_L0'!$B13:$AI13)=0,0,'04_L0'!F13/SUM('04_L0'!$B13:$AI13)) -> 0.049714011 | G13: =IF(SUM('04_L0'!$B13:$AI13)=0,0,'04_L0'!G13/SUM('04_L0'!$B13:$AI13)) -> 0.12930549 | H13: =IF(SUM('04_L0'!$B13:$AI13)=0,0,'04_L0'!H13/SUM('04_L0'!$B13:$AI13)) -> 0.00086631597 | I13: =IF(SUM('04_L0'!$B13:$AI13)=0,0,'04_L0'!I13/SUM('04_L0'!$B13:$AI13)) -> 0.020415832 | ... AI13: =IF(SUM('04_L0'!$B13:$AI13)=0,0,'04_L0'!AI13/SUM('04_L0'!$B13:$AI13)) -> 0.0012420675
A14: 10_IronOre | B14: =IF(SUM('04_L0'!$B14:$AI14)=0,0,'04_L0'!B14/SUM('04_L0'!$B14:$AI14)) -> 0.018399099 | C14: =IF(SUM('04_L0'!$B14:$AI14)=0,0,'04_L0'!C14/SUM('04_L0'!$B14:$AI14)) -> 0.043246236 | D14: =IF(SUM('04_L0'!$B14:$AI14)=0,0,'04_L0'!D14/SUM('04_L0'!$B14:$AI14)) -> 0.034728168 | E14: =IF(SUM('04_L0'!$B14:$AI14)=0,0,'04_L0'!E14/SUM('04_L0'!$B14:$AI14)) -> 0.01177784 | F14: =IF(SUM('04_L0'!$B14:$AI14)=0,0,'04_L0'!F14/SUM('04_L0'!$B14:$AI14)) -> 0.033066843 | G14: =IF(SUM('04_L0'!$B14:$AI14)=0,0,'04_L0'!G14/SUM('04_L0'!$B14:$AI14)) -> 0.023894109 | H14: =IF(SUM('04_L0'!$B14:$AI14)=0,0,'04_L0'!H14/SUM('04_L0'!$B14:$AI14)) -> 0.0062852955 | I14: =IF(SUM('04_L0'!$B14:$AI14)=0,0,'04_L0'!I14/SUM('04_L0'!$B14:$AI14)) -> 0.051679849 | ... AI14: =IF(SUM('04_L0'!$B14:$AI14)=0,0,'04_L0'!AI14/SUM('04_L0'!$B14:$AI14)) -> 0.001581187
A15: 11_OtherMine | B15: =IF(SUM('04_L0'!$B15:$AI15)=0,0,'04_L0'!B15/SUM('04_L0'!$B15:$AI15)) -> 0.0042789806 | C15: =IF(SUM('04_L0'!$B15:$AI15)=0,0,'04_L0'!C15/SUM('04_L0'!$B15:$AI15)) -> 0.0091819793 | D15: =IF(SUM('04_L0'!$B15:$AI15)=0,0,'04_L0'!D15/SUM('04_L0'!$B15:$AI15)) -> 0 | E15: =IF(SUM('04_L0'!$B15:$AI15)=0,0,'04_L0'!E15/SUM('04_L0'!$B15:$AI15)) -> 0.088064541 | F15: =IF(SUM('04_L0'!$B15:$AI15)=0,0,'04_L0'!F15/SUM('04_L0'!$B15:$AI15)) -> 0 | G15: =IF(SUM('04_L0'!$B15:$AI15)=0,0,'04_L0'!G15/SUM('04_L0'!$B15:$AI15)) -> 0.013360671 | H15: =IF(SUM('04_L0'!$B15:$AI15)=0,0,'04_L0'!H15/SUM('04_L0'!$B15:$AI15)) -> 0 | I15: =IF(SUM('04_L0'!$B15:$AI15)=0,0,'04_L0'!I15/SUM('04_L0'!$B15:$AI15)) -> 0.0015266155 | ... AI15: =IF(SUM('04_L0'!$B15:$AI15)=0,0,'04_L0'!AI15/SUM('04_L0'!$B15:$AI15)) -> 0.0027857947
A16: 12_FoodMan | B16: =IF(SUM('04_L0'!$B16:$AI16)=0,0,'04_L0'!B16/SUM('04_L0'!$B16:$AI16)) -> 0.012690103 | C16: =IF(SUM('04_L0'!$B16:$AI16)=0,0,'04_L0'!C16/SUM('04_L0'!$B16:$AI16)) -> 0.049934723 | D16: =IF(SUM('04_L0'!$B16:$AI16)=0,0,'04_L0'!D16/SUM('04_L0'!$B16:$AI16)) -> 0.020861925 | E16: =IF(SUM('04_L0'!$B16:$AI16)=0,0,'04_L0'!E16/SUM('04_L0'!$B16:$AI16)) -> 0.02375332 | F16: =IF(SUM('04_L0'!$B16:$AI16)=0,0,'04_L0'!F16/SUM('04_L0'!$B16:$AI16)) -> 0.006896392 | G16: =IF(SUM('04_L0'!$B16:$AI16)=0,0,'04_L0'!G16/SUM('04_L0'!$B16:$AI16)) -> 0.019788697 | H16: =IF(SUM('04_L0'!$B16:$AI16)=0,0,'04_L0'!H16/SUM('04_L0'!$B16:$AI16)) -> 0.0053236148 | I16: =IF(SUM('04_L0'!$B16:$AI16)=0,0,'04_L0'!I16/SUM('04_L0'!$B16:$AI16)) -> 0.035312115 | ... AI16: =IF(SUM('04_L0'!$B16:$AI16)=0,0,'04_L0'!AI16/SUM('04_L0'!$B16:$AI16)) -> 0.0018401741
... A56: 52_OtherSvc | B56: =IF(SUM('04_L0'!$B56:$AI56)=0,0,'04_L0'!B56/SUM('04_L0'!$B56:$AI56)) -> 0.020916905 | C56: =IF(SUM('04_L0'!$B56:$AI56)=0,0,'04_L0'!C56/SUM('04_L0'!$B56:$AI56)) -> 0.0088825215 | D56: =IF(SUM('04_L0'!$B56:$AI56)=0,0,'04_L0'!D56/SUM('04_L0'!$B56:$AI56)) -> 0.019006686 | E56: =IF(SUM('04_L0'!$B56:$AI56)=0,0,'04_L0'!E56/SUM('04_L0'!$B56:$AI56)) -> 0.01451767 | F56: =IF(SUM('04_L0'!$B56:$AI56)=0,0,'04_L0'!F56/SUM('04_L0'!$B56:$AI56)) -> 0.014040115 | G56: =IF(SUM('04_L0'!$B56:$AI56)=0,0,'04_L0'!G56/SUM('04_L0'!$B56:$AI56)) -> 0 | H56: =IF(SUM('04_L0'!$B56:$AI56)=0,0,'04_L0'!H56/SUM('04_L0'!$B56:$AI56)) -> 0 | I56: =IF(SUM('04_L0'!$B56:$AI56)=0,0,'04_L0'!I56/SUM('04_L0'!$B56:$AI56)) -> 0.050047755 | ... AI56: =IF(SUM('04_L0'!$B56:$AI56)=0,0,'04_L0'!AI56/SUM('04_L0'!$B56:$AI56)) -> 0

Sheet 06_intensity
A1: Tabel Intensitas 38 × 52
A2: eta_j[s,p] = intensity_j[s] × share[s,p]. w[s] = JUMLAH_j ( x_j × intensity_j[s] )
A4: shock | B4: x_j (pp) | C4: 01_FoodCrops | D4: 02_HortiCrops | E4: 03_Estates | F4: 04_Livestock | G4: 05_AgricService | H4: 06_Forestry | I4: 07_Fishery | J4: 08_Coal | K4: 09_OilGasGeo | L4: 10_IronOre | M4: 11_OtherMine | N4: 12_FoodMan | O4: 13_Tobacco | P4: 14_Textiles | Q4: 15_Leather | R4: 16_WoodProd | S4: 17_PaperProd | T4: 18_NonMetalProd | U4: 19_CoalOilMan | V4: 20_Chemical | W4: 21_Rubber | X4: 22_BasicMetal | Y4: 23_MetalProd | Z4: 24_Machinery | AA4: 25_TranspEquip | AB4: 26_Furniture | AC4: 27_OtherMan | AD4: 28_Electricity | AE4: 29_CityGas | AF4: 30_WasteMan | AG4: 31_Construction | AH4: 32_VehicTrade | AI4: 33_OthTrade | AJ4: 34_RailTransp | AK4: 35_LandTransp | AL4: 36_SeaTransp | AM4: 37_WaterTransp | AN4: 38_AirTransp | AO4: 39_TranspSvc | AP4: 40_Hotels | AQ4: 41_Restaurant | AR4: 42_Telecom | AS4: 43_Finance | AT4: 44_Insurance | AU4: 45_OthFinance | AV4: 46_FinanSvc | AW4: 47_RealEstate | AX4: 48_BusSvc | AY4: 49_GovAdmin | AZ4: 50_Education | BA4: 51_HealthSvc | BB4: 52_OtherSvc
A5: t1_cpo | B5: 28.565884 | C5: 0.06 | D5: 0.01 | E5: 0.2 | F5: 0.01 | G5: 0.01 | H5: 0.01 | I5: 0.01 | J5: 0.01 | K5: 0.01 | L5: 0.01 | M5: 0.01 | N5: 0.12 | O5: 0.01 | P5: 0.01 | Q5: 0.01 | R5: 0.01 | S5: 0.01 | T5: 0.01 | U5: 0.01 | V5: 0.06 | W5: 0.06 | X5: 0.01 | Y5: 0.01 | Z5: 0.01 | AA5: 0.01 | AB5: 0.01 | AC5: 0.01 | AD5: 0.01 | AE5: 0.01 | AF5: 0.01 | AG5: 0.01 | AH5: 0.01 | AI5: 0.01 | AJ5: 0.01 | AK5: 0.01 | AL5: 0.01 | AM5: 0.01 | AN5: 0.01 | AO5: 0.01 | AP5: 0.01 | AQ5: 0.01 | AR5: 0.01 | AS5: 0.01 | AT5: 0.01 | AU5: 0.01 | AV5: 0.01 | AW5: 0.01 | AX5: 0.01 | AY5: 0.01 | AZ5: 0.01 | BA5: 0.01 | BB5: 0.01
A6: t1_coal | B6: 24.757917 | C6: 0.01 | D6: 0.01 | E6: 0.01 | F6: 0.01 | G6: 0.01 | H6: 0.01 | I6: 0.01 | J6: 0.2 | K6: 0.01 | L6: 0.01 | M6: 0.01 | N6: 0.01 | O6: 0.01 | P6: 0.01 | Q6: 0.01 | R6: 0.01 | S6: 0.01 | T6: 0.01 | U6: 0.1 | V6: 0.01 | W6: 0.01 | X6: 0.06 | Y6: 0.01 | Z6: 0.01 | AA6: 0.01 | AB6: 0.01 | AC6: 0.01 | AD6: 0.01 | AE6: 0.01 | AF6: 0.01 | AG6: 0.06 | AH6: 0.01 | AI6: 0.01 | AJ6: 0.01 | AK6: 0.06 | AL6: 0.01 | AM6: 0.01 | AN6: 0.01 | AO6: 0.01 | AP6: 0.01 | AQ6: 0.01 | AR6: 0.01 | AS6: 0.01 | AT6: 0.01 | AU6: 0.01 | AV6: 0.01 | AW6: 0.01 | AX6: 0.01 | AY6: 0.01 | AZ6: 0.01 | BA6: 0.01 | BB6: 0.01
A7: t1_nickel | B7: 27.646386 | C7: 0.01 | D7: 0.01 | E7: 0.01 | F7: 0.01 | G7: 0.01 | H7: 0.01 | I7: 0.01 | J7: 0.01 | K7: 0.01 | L7: 0.06 | M7: 0.2 | N7: 0.01 | O7: 0.01 | P7: 0.01 | Q7: 0.01 | R7: 0.01 | S7: 0.01 | T7: 0.01 | U7: 0.01 | V7: 0.01 | W7: 0.01 | X7: 0.12 | Y7: 0.06 | Z7: 0.06 | AA7: 0.01 | AB7: 0.01 | AC7: 0.01 | AD7: 0.01 | AE7: 0.01 | AF7: 0.01 | AG7: 0.01 | AH7: 0.01 | AI7: 0.01 | AJ7: 0.01 | AK7: 0.01 | AL7: 0.01 | AM7: 0.01 | AN7: 0.01 | AO7: 0.01 | AP7: 0.01 | AQ7: 0.01 | AR7: 0.01 | AS7: 0.01 | AT7: 0.01 | AU7: 0.01 | AV7: 0.01 | AW7: 0.01 | AX7: 0.01 | AY7: 0.01 | AZ7: 0.01 | BA7: 0.01 | BB7: 0.01
A8: t1_copper | B8: 37.766699 | C8: 0.01 | D8: 0.01 | E8: 0.01 | F8: 0.01 | G8: 0.01 | H8: 0.01 | I8: 0.01 | J8: 0.01 | K8: 0.01 | L8: 0.2 | M8: 0.12 | N8: 0.01 | O8: 0.01 | P8: 0.01 | Q8: 0.01 | R8: 0.01 | S8: 0.01 | T8: 0.01 | U8: 0.01 | V8: 0.01 | W8: 0.01 | X8: 0.06 | Y8: 0.06 | Z8: 0.01 | AA8: 0.01 | AB8: 0.01 | AC8: 0.01 | AD8: 0.01 | AE8: 0.01 | AF8: 0.01 | AG8: 0.01 | AH8: 0.01 | AI8: 0.01 | AJ8: 0.01 | AK8: 0.01 | AL8: 0.01 | AM8: 0.01 | AN8: 0.01 | AO8: 0.01 | AP8: 0.01 | AQ8: 0.01 | AR8: 0.01 | AS8: 0.01 | AT8: 0.01 | AU8: 0.01 | AV8: 0.01 | AW8: 0.01 | AX8: 0.01 | AY8: 0.01 | AZ8: 0.01 | BA8: 0.01 | BB8: 0.01
A9: t1_rubber | B9: 27.189479 | C9: 0.01 | D9: 0.01 | E9: 0.14 | F9: 0.01 | G9: 0.01 | H9: 0.01 | I9: 0.01 | J9: 0.01 | K9: 0.01 | L9: 0.01 | M9: 0.01 | N9: 0.01 | O9: 0.01 | P9: 0.06 | Q9: 0.06 | R9: 0.01 | S9: 0.01 | T9: 0.01 | U9: 0.01 | V9: 0.06 | W9: 0.2 | X9: 0.01 | Y9: 0.01 | Z9: 0.01 | AA9: 0.01 | AB9: 0.01 | AC9: 0.01 | AD9: 0.01 | AE9: 0.01 | AF9: 0.01 | AG9: 0.01 | AH9: 0.01 | AI9: 0.01 | AJ9: 0.01 | AK9: 0.01 | AL9: 0.01 | AM9: 0.01 | AN9: 0.01 | AO9: 0.01 | AP9: 0.01 | AQ9: 0.01 | AR9: 0.01 | AS9: 0.01 | AT9: 0.01 | AU9: 0.01 | AV9: 0.01 | AW9: 0.01 | AX9: 0.01 | AY9: 0.01 | AZ9: 0.01 | BA9: 0.01 | BB9: 0.01
A10: t1_oilgas | B10: 61.117867 | C10: 0.01 | D10: 0.01 | E10: 0.01 | F10: 0.01 | G10: 0.01 | H10: 0.01 | I10: 0.01 | J10: 0.01 | K10: 0.2 | L10: 0.01 | M10: 0.01 | N10: 0.01 | O10: 0.01 | P10: 0.01 | Q10: 0.01 | R10: 0.01 | S10: 0.01 | T10: 0.01 | U10: 0.14 | V10: 0.06 | W10: 0.01 | X10: 0.01 | Y10: 0.01 | Z10: 0.01 | AA10: 0.01 | AB10: 0.01 | AC10: 0.01 | AD10: 0.06 | AE10: 0.06 | AF10: 0.01 | AG10: 0.01 | AH10: 0.01 | AI10: 0.01 | AJ10: 0.01 | AK10: 0.01 | AL10: 0.01 | AM10: 0.01 | AN10: 0.01 | AO10: 0.01 | AP10: 0.01 | AQ10: 0.01 | AR10: 0.01 | AS10: 0.01 | AT10: 0.01 | AU10: 0.01 | AV10: 0.01 | AW10: 0.01 | AX10: 0.01 | AY10: 0.01 | AZ10: 0.01 | BA10: 0.01 | BB10: 0.01
A11: t1_electronics | B11: 1.0168076 | C11: 0.01 | D11: 0.01 | E11: 0.01 | F11: 0.01 | G11: 0.01 | H11: 0.01 | I11: 0.01 | J11: 0.01 | K11: 0.01 | L11: 0.01 | M11: 0.01 | N11: 0.01 | O11: 0.01 | P11: 0.06 | Q11: 0.01 | R11: 0.01 | S11: 0.01 | T11: 0.01 | U11: 0.01 | V11: 0.01 | W11: 0.01 | X11: 0.01 | Y11: 0.06 | Z11: 0.12 | AA11: 0.06 | AB11: 0.01 | AC11: 0.2 | AD11: 0.01 | AE11: 0.01 | AF11: 0.01 | AG11: 0.01 | AH11: 0.01 | AI11: 0.01 | AJ11: 0.01 | AK11: 0.01 | AL11: 0.01 | AM11: 0.01 | AN11: 0.01 | AO11: 0.01 | AP11: 0.01 | AQ11: 0.01 | AR11: 0.06 | AS11: 0.01 | AT11: 0.01 | AU11: 0.01 | AV11: 0.01 | AW11: 0.01 | AX11: 0.01 | AY11: 0.01 | AZ11: 0.01 | BA11: 0.01 | BB11: 0.01
A12: t2_HortiCrops | B12: -0.87800091 | C12: 0.045 | D12: 0.15 | E12: 0.045 | F12: 0.0075 | G12: 0.0075 | H12: 0.0075 | I12: 0.0075 | J12: 0.0075 | K12: 0.0075 | L12: 0.0075 | M12: 0.0075 | N12: 0.045 | O12: 0.0075 | P12: 0.0075 | Q12: 0.0075 | R12: 0.0075 | S12: 0.0075 | T12: 0.0075 | U12: 0.0075 | V12: 0.0075 | W12: 0.0075 | X12: 0.0075 | Y12: 0.0075 | Z12: 0.0075 | AA12: 0.0075 | AB12: 0.0075 | AC12: 0.0075 | AD12: 0.0075 | AE12: 0.0075 | AF12: 0.0075 | AG12: 0.0075 | AH12: 0.0075 | AI12: 0.0075 | AJ12: 0.0075 | AK12: 0.0075 | AL12: 0.0075 | AM12: 0.0075 | AN12: 0.0075 | AO12: 0.0075 | AP12: 0.0075 | AQ12: 0.0075 | AR12: 0.0075 | AS12: 0.0075 | AT12: 0.0075 | AU12: 0.0075 | AV12: 0.0075 | AW12: 0.0075 | AX12: 0.0075 | AY12: 0.0075 | AZ12: 0.0075 | BA12: 0.0075 | BB12: 0.0075
A13: t2_Estates | B13: 0.22714337 | C13: 0.045 | D13: 0.0075 | E13: 0.15 | F13: 0.0075 | G13: 0.0075 | H13: 0.0075 | I13: 0.0075 | J13: 0.0075 | K13: 0.0075 | L13: 0.0075 | M13: 0.0075 | N13: 0.045 | O13: 0.0075 | P13: 0.0075 | Q13: 0.0075 | R13: 0.0075 | S13: 0.0075 | T13: 0.0075 | U13: 0.0075 | V13: 0.0075 | W13: 0.045 | X13: 0.0075 | Y13: 0.0075 | Z13: 0.0075 | AA13: 0.0075 | AB13: 0.0075 | AC13: 0.0075 | AD13: 0.0075 | AE13: 0.0075 | AF13: 0.0075 | AG13: 0.0075 | AH13: 0.0075 | AI13: 0.0075 | AJ13: 0.0075 | AK13: 0.0075 | AL13: 0.0075 | AM13: 0.0075 | AN13: 0.0075 | AO13: 0.0075 | AP13: 0.0075 | AQ13: 0.0075 | AR13: 0.0075 | AS13: 0.0075 | AT13: 0.0075 | AU13: 0.0075 | AV13: 0.0075 | AW13: 0.0075 | AX13: 0.0075 | AY13: 0.0075 | AZ13: 0.0075 | BA13: 0.0075 | BB13: 0.0075
A14: t2_Forestry | B14: 0.16702107 | C14: 0.0075 | D14: 0.0075 | E14: 0.0075 | F14: 0.0075 | G14: 0.0075 | H14: 0.15 | I14: 0.0075 | J14: 0.0075 | K14: 0.0075 | L14: 0.0075 | M14: 0.0075 | N14: 0.0075 | O14: 0.0075 | P14: 0.0075 | Q14: 0.0075 | R14: 0.045 | S14: 0.045 | T14: 0.0075 | U14: 0.0075 | V14: 0.0075 | W14: 0.0075 | X14: 0.0075 | Y14: 0.0075 | Z14: 0.0075 | AA14: 0.0075 | AB14: 0.0075 | AC14: 0.0075 | AD14: 0.0075 | AE14: 0.0075 | AF14: 0.0075 | AG14: 0.0075 | AH14: 0.0075 | AI14: 0.0075 | AJ14: 0.0075 | AK14: 0.0075 | AL14: 0.0075 | AM14: 0.0075 | AN14: 0.0075 | AO14: 0.0075 | AP14: 0.0075 | AQ14: 0.0075 | AR14: 0.0075 | AS14: 0.0075 | AT14: 0.0075 | AU14: 0.0075 | AV14: 0.0075 | AW14: 0.0075 | AX14: 0.0075 | AY14: 0.0075 | AZ14: 0.0075 | BA14: 0.0075 | BB14: 0.0075
A15: t2_Fishery | B15: 0.44210939 | C15: 0.0075 | D15: 0.0075 | E15: 0.0075 | F15: 0.0075 | G15: 0.0075 | H15: 0.0075 | I15: 0.15 | J15: 0.0075 | K15: 0.0075 | L15: 0.0075 | M15: 0.0075 | N15: 0.045 | O15: 0.0075 | P15: 0.0075 | Q15: 0.0075 | R15: 0.0075 | S15: 0.0075 | T15: 0.0075 | U15: 0.0075 | V15: 0.0075 | W15: 0.0075 | X15: 0.0075 | Y15: 0.0075 | Z15: 0.0075 | AA15: 0.0075 | AB15: 0.0075 | AC15: 0.0075 | AD15: 0.0075 | AE15: 0.0075 | AF15: 0.0075 | AG15: 0.0075 | AH15: 0.0075 | AI15: 0.0075 | AJ15: 0.0075 | AK15: 0.0075 | AL15: 0.0075 | AM15: 0.0075 | AN15: 0.0075 | AO15: 0.0075 | AP15: 0.045 | AQ15: 0.045 | AR15: 0.0075 | AS15: 0.0075 | AT15: 0.0075 | AU15: 0.0075 | AV15: 0.0075 | AW15: 0.0075 | AX15: 0.0075 | AY15: 0.0075 | AZ15: 0.0075 | BA15: 0.0075 | BB15: 0.0075
A16: t2_Coal | B16: 0.23018091 | C16: 0.0075 | D16: 0.0075 | E16: 0.0075 | F16: 0.0075 | G16: 0.0075 | H16: 0.0075 | I16: 0.0075 | J16: 0.15 | K16: 0.0075 | L16: 0.0075 | M16: 0.0075 | N16: 0.0075 | O16: 0.0075 | P16: 0.0075 | Q16: 0.0075 | R16: 0.0075 | S16: 0.0075 | T16: 0.0075 | U16: 0.045 | V16: 0.0075 | W16: 0.0075 | X16: 0.045 | Y16: 0.0075 | Z16: 0.0075 | AA16: 0.0075 | AB16: 0.0075 | AC16: 0.0075 | AD16: 0.0075 | AE16: 0.0075 | AF16: 0.0075 | AG16: 0.045 | AH16: 0.0075 | AI16: 0.0075 | AJ16: 0.0075 | AK16: 0.0075 | AL16: 0.0075 | AM16: 0.0075 | AN16: 0.0075 | AO16: 0.0075 | AP16: 0.0075 | AQ16: 0.0075 | AR16: 0.0075 | AS16: 0.0075 | AT16: 0.0075 | AU16: 0.0075 | AV16: 0.0075 | AW16: 0.0075 | AX16: 0.0075 | AY16: 0.0075 | AZ16: 0.0075 | BA16: 0.0075 | BB16: 0.0075
... A42: t3_spare_parts | B42: -1.2270833 | C42: 0.005 | D42: 0.005 | E42: 0.005 | F42: 0.005 | G42: 0.005 | H42: 0.005 | I42: 0.005 | J42: 0.005 | K42: 0.005 | L42: 0.005 | M42: 0.005 | N42: 0.005 | O42: 0.005 | P42: 0.005 | Q42: 0.005 | R42: 0.005 | S42: 0.005 | T42: 0.005 | U42: 0.005 | V42: 0.005 | W42: 0.005 | X42: 0.03 | Y42: 0.07 | Z42: 0.05 | AA42: 0.03 | AB42: 0.005 | AC42: 0.005 | AD42: 0.005 | AE42: 0.005 | AF42: 0.005 | AG42: 0.005 | AH42: 0.1 | AI42: 0.005 | AJ42: 0.005 | AK42: 0.03 | AL42: 0.005 | AM42: 0.005 | AN42: 0.005 | AO42: 0.005 | AP42: 0.005 | AQ42: 0.005 | AR42: 0.005 | AS42: 0.005 | AT42: 0.005 | AU42: 0.005 | AV42: 0.005 | AW42: 0.005 | AX42: 0.005 | AY42: 0.005 | AZ42: 0.005 | BA42: 0.005 | BB42: 0.005
