Workbook

Sheet Dashboard_Risiko Sektoral
B1: Heat Map | C1: 33rd percentile | D1: =_xlfn.PERCENTILE.INC(D$6:D$29,1/3) -> 29.543333 | E1: =_xlfn.PERCENTILE.INC(E$6:E$29,1/3) -> 21.850774 | F1: =_xlfn.PERCENTILE.INC(F$6:F$29,1/3) -> 3.2541852 | G1: =_xlfn.PERCENTILE.INC(G$6:G$29,1/3) -> 11.459149 | R1: =(3-1)/3 + 1 -> 1.6666667 | S1: Membagi rata rentang 1-3 menjadi 3 kelompok
C2: 67th percentile | D2: =_xlfn.PERCENTILE.INC(D$6:D$29,2/3) -> 45.1 | E2: =_xlfn.PERCENTILE.INC(E$6:E$29,2/3) -> 40.101812 | F2: =_xlfn.PERCENTILE.INC(F$6:F$29,2/3) -> 5.1293747 | G2: =_xlfn.PERCENTILE.INC(G$6:G$29,2/3) -> 20.793743 | R2: =3 -((3-1)/3) -> 2.3333333
B4: Kode KBLI (2020) | C4: Sektor Industri Pengolahan | D4: Eksposur Ekspor | E4: Eksposur Impor | F4: Eksposur Energi | G4: Intensitas Tenaga Kerja | I4: Eksposur Ekspor | J4: Eksposur Impor | K4: Eksposur Energi | L4: Intensitas Tenaga Kerja | N4: Eksposur Ekspor | O4: Eksposur Impor | P4: Eksposur Energi | Q4: Intensitas Tenaga Kerja | R4: Rata-Rata Skor | S4: Risiko PHK | U4: Provinsi Utama (Top 5 Jumlah Perusahaan Terbanyak)
U5: 1 | V5: 2 | W5: 3 | X5: 4 | Y5: 5
B6: 10 | C6: Makanan | D6: 57.76 | E6: 8.022286 | F6: 1.7244097 | G6: 3.7494466 | I6: =IF(D6<=$D$1,"Rendah",IF(D6<=$D$2,"Sedang","Tinggi")) -> Tinggi | J6: =IF(E6<=$E$1,"Rendah",IF(E6<=$E$2,"Sedang","Tinggi")) -> Rendah | K6: =IF(F6<=$F$1,"Rendah",IF(F6<=$F$2,"Sedang","Tinggi")) -> Rendah | L6: =IF(G6<=$G$1,"Rendah",IF(G6<=$G$2,"Sedang","Tinggi")) -> Rendah | N6: =IF(I6="Tinggi",3,IF(I6="Sedang",2,IF(I6="Rendah",1,""))) -> 3 | O6: =IF(J6="Tinggi",3,IF(J6="Sedang",2,IF(J6="Rendah",1,""))) -> 1 | P6: =IF(K6="Tinggi",3,IF(K6="Sedang",2,IF(K6="Rendah",1,""))) -> 1 | Q6: =IF(L6="Tinggi",3,IF(L6="Sedang",2,IF(L6="Rendah",1,""))) -> 1 | R6: =AVERAGE(N6:Q6) -> 1.5 | S6: =IF(R6<$R$1,"Rendah",IF(R6<$R$2,"Sedang","Tinggi")) -> Rendah | U6: Jawa Timur | V6: Jawa Barat | W6: Jawa Tengah | X6: Sumatera Utara | Y6: Banten
B7: 11 | C7: Minuman | D7: 12.08 | E7: 14.659392 | F7: 9.6004284 | G7: 23.955096 | I7: =IF(D7<=$D$1,"Rendah",IF(D7<=$D$2,"Sedang","Tinggi")) -> Rendah | J7: =IF(E7<=$E$1,"Rendah",IF(E7<=$E$2,"Sedang","Tinggi")) -> Rendah | K7: =IF(F7<=$F$1,"Rendah",IF(F7<=$F$2,"Sedang","Tinggi")) -> Tinggi | L7: =IF(G7<=$G$1,"Rendah",IF(G7<=$G$2,"Sedang","Tinggi")) -> Tinggi | N7: =IF(I7="Tinggi",3,IF(I7="Sedang",2,IF(I7="Rendah",1,""))) -> 1 | O7: =IF(J7="Tinggi",3,IF(J7="Sedang",2,IF(J7="Rendah",1,""))) -> 1 | P7: =IF(K7="Tinggi",3,IF(K7="Sedang",2,IF(K7="Rendah",1,""))) -> 3 | Q7: =IF(L7="Tinggi",3,IF(L7="Sedang",2,IF(L7="Rendah",1,""))) -> 3 | R7: =AVERAGE(N7:Q7) -> 2 | S7: =IF(R7<$R$1,"Rendah",IF(R7<$R$2,"Sedang","Tinggi")) -> Sedang | U7: Jawa Barat | V7: Jawa Timur | W7: Jawa Tengah | X7: Bali | Y7: Banten
B8: 12 | C8: Pengolahan Tembakau | D8: 49.95 | E8: 6.8926004 | F8: 0.83883462 | G8: 11.533097 | I8: =IF(D8<=$D$1,"Rendah",IF(D8<=$D$2,"Sedang","Tinggi")) -> Tinggi | J8: =IF(E8<=$E$1,"Rendah",IF(E8<=$E$2,"Sedang","Tinggi")) -> Rendah | K8: =IF(F8<=$F$1,"Rendah",IF(F8<=$F$2,"Sedang","Tinggi")) -> Rendah | L8: =IF(G8<=$G$1,"Rendah",IF(G8<=$G$2,"Sedang","Tinggi")) -> Sedang | N8: =IF(I8="Tinggi",3,IF(I8="Sedang",2,IF(I8="Rendah",1,""))) -> 3 | O8: =IF(J8="Tinggi",3,IF(J8="Sedang",2,IF(J8="Rendah",1,""))) -> 1 | P8: =IF(K8="Tinggi",3,IF(K8="Sedang",2,IF(K8="Rendah",1,""))) -> 1 | Q8: =IF(L8="Tinggi",3,IF(L8="Sedang",2,IF(L8="Rendah",1,""))) -> 2 | R8: =AVERAGE(N8:Q8) -> 1.75 | S8: =IF(R8<$R$1,"Rendah",IF(R8<$R$2,"Sedang","Tinggi")) -> Sedang | U8: Jawa Timur | V8: Jawa Tengah | W8: Nusa Tenggara Barat | X8: Jawa Barat | Y8: Kepulauan Riau
B9: 13 | C9: Tekstil | D9: 40.83 | E9: 34.801635 | F9: 8.3422448 | G9: 13.701183 | I9: =IF(D9<=$D$1,"Rendah",IF(D9<=$D$2,"Sedang","Tinggi")) -> Sedang | J9: =IF(E9<=$E$1,"Rendah",IF(E9<=$E$2,"Sedang","Tinggi")) -> Sedang | K9: =IF(F9<=$F$1,"Rendah",IF(F9<=$F$2,"Sedang","Tinggi")) -> Tinggi | L9: =IF(G9<=$G$1,"Rendah",IF(G9<=$G$2,"Sedang","Tinggi")) -> Sedang | N9: =IF(I9="Tinggi",3,IF(I9="Sedang",2,IF(I9="Rendah",1,""))) -> 2 | O9: =IF(J9="Tinggi",3,IF(J9="Sedang",2,IF(J9="Rendah",1,""))) -> 2 | P9: =IF(K9="Tinggi",3,IF(K9="Sedang",2,IF(K9="Rendah",1,""))) -> 3 | Q9: =IF(L9="Tinggi",3,IF(L9="Sedang",2,IF(L9="Rendah",1,""))) -> 2 | R9: =AVERAGE(N9:Q9) -> 2.25 | S9: =IF(R9<$R$1,"Rendah",IF(R9<$R$2,"Sedang","Tinggi")) -> Sedang | U9: Jawa Barat | V9: Jawa Tengah | W9: Jawa Timur | X9: Banten | Y9: DKI Jakarta
B10: 14 | C10: Pakaian Jadi | D10: 62.03 | E10: 70.847882 | F10: 4.054556 | G10: 30.579504 | I10: =IF(D10<=$D$1,"Rendah",IF(D10<=$D$2,"Sedang","Tinggi")) -> Tinggi | J10: =IF(E10<=$E$1,"Rendah",IF(E10<=$E$2,"Sedang","Tinggi")) -> Tinggi | K10: =IF(F10<=$F$1,"Rendah",IF(F10<=$F$2,"Sedang","Tinggi")) -> Sedang | L10: =IF(G10<=$G$1,"Rendah",IF(G10<=$G$2,"Sedang","Tinggi")) -> Tinggi | N10: =IF(I10="Tinggi",3,IF(I10="Sedang",2,IF(I10="Rendah",1,""))) -> 3 | O10: =IF(J10="Tinggi",3,IF(J10="Sedang",2,IF(J10="Rendah",1,""))) -> 3 | P10: =IF(K10="Tinggi",3,IF(K10="Sedang",2,IF(K10="Rendah",1,""))) -> 2 | Q10: =IF(L10="Tinggi",3,IF(L10="Sedang",2,IF(L10="Rendah",1,""))) -> 3 | R10: =AVERAGE(N10:Q10) -> 2.75 | S10: =IF(R10<$R$1,"Rendah",IF(R10<$R$2,"Sedang","Tinggi")) -> Tinggi | U10: Jawa Barat | V10: Jawa Tengah | W10: Jawa Timur | X10: DKI Jakarta | Y10: Banten
B11: 15 | C11: Kulit, Barang dari Kulit dan Alas Kaki | D11: 43.65 | E11: 34.884554 | F11: 2.2432006 | G11: 34.188985 | I11: =IF(D11<=$D$1,"Rendah",IF(D11<=$D$2,"Sedang","Tinggi")) -> Sedang | J11: =IF(E11<=$E$1,"Rendah",IF(E11<=$E$2,"Sedang","Tinggi")) -> Sedang | K11: =IF(F11<=$F$1,"Rendah",IF(F11<=$F$2,"Sedang","Tinggi")) -> Rendah | L11: =IF(G11<=$G$1,"Rendah",IF(G11<=$G$2,"Sedang","Tinggi")) -> Tinggi | N11: =IF(I11="Tinggi",3,IF(I11="Sedang",2,IF(I11="Rendah",1,""))) -> 2 | O11: =IF(J11="Tinggi",3,IF(J11="Sedang",2,IF(J11="Rendah",1,""))) -> 2 | P11: =IF(K11="Tinggi",3,IF(K11="Sedang",2,IF(K11="Rendah",1,""))) -> 1 | Q11: =IF(L11="Tinggi",3,IF(L11="Sedang",2,IF(L11="Rendah",1,""))) -> 3 | R11: =AVERAGE(N11:Q11) -> 2 | S11: =IF(R11<$R$1,"Rendah",IF(R11<$R$2,"Sedang","Tinggi")) -> Sedang | U11: Jawa Timur | V11: Jawa Barat | W11: Banten | X11: Jawa Tengah | Y11: DI Yogyakarta
B12: 16 | C12: Kayu, Barang dari Kayu dan Gabus (Tidak Termasuk Furnitur) dan Barang Anyaman dari Bambu, Rotan dan Sejenisnya | D12: 69.82 | E12: 6.4480895 | F12: 7.1492164 | G12: 26.010911 | I12: =IF(D12<=$D$1,"Rendah",IF(D12<=$D$2,"Sedang","Tinggi")) -> Tinggi | J12: =IF(E12<=$E$1,"Rendah",IF(E12<=$E$2,"Sedang","Tinggi")) -> Rendah | K12: =IF(F12<=$F$1,"Rendah",IF(F12<=$F$2,"Sedang","Tinggi")) -> Tinggi | L12: =IF(G12<=$G$1,"Rendah",IF(G12<=$G$2,"Sedang","Tinggi")) -> Tinggi | N12: =IF(I12="Tinggi",3,IF(I12="Sedang",2,IF(I12="Rendah",1,""))) -> 3 | O12: =IF(J12="Tinggi",3,IF(J12="Sedang",2,IF(J12="Rendah",1,""))) -> 1 | P12: =IF(K12="Tinggi",3,IF(K12="Sedang",2,IF(K12="Rendah",1,""))) -> 3 | Q12: =IF(L12="Tinggi",3,IF(L12="Sedang",2,IF(L12="Rendah",1,""))) -> 3 | R12: =AVERAGE(N12:Q12) -> 2.5 | S12: =IF(R12<$R$1,"Rendah",IF(R12<$R$2,"Sedang","Tinggi")) -> Tinggi | U12: Jawa Timur | V12: Jawa Tengah | W12: Jawa Barat | X12: Banten | Y12: Sumatera Utara
B13: 17 | C13: Kertas dan Barang dari Kertas | D13: 26.22 | E13: 11.21393 | F13: 6.9845549 | G13: 9.4763915 | I13: =IF(D13<=$D$1,"Rendah",IF(D13<=$D$2,"Sedang","Tinggi")) -> Rendah | J13: =IF(E13<=$E$1,"Rendah",IF(E13<=$E$2,"Sedang","Tinggi")) -> Rendah | K13: =IF(F13<=$F$1,"Rendah",IF(F13<=$F$2,"Sedang","Tinggi")) -> Tinggi | L13: =IF(G13<=$G$1,"Rendah",IF(G13<=$G$2,"Sedang","Tinggi")) -> Rendah | N13: =IF(I13="Tinggi",3,IF(I13="Sedang",2,IF(I13="Rendah",1,""))) -> 1 | O13: =IF(J13="Tinggi",3,IF(J13="Sedang",2,IF(J13="Rendah",1,""))) -> 1 | P13: =IF(K13="Tinggi",3,IF(K13="Sedang",2,IF(K13="Rendah",1,""))) -> 3 | Q13: =IF(L13="Tinggi",3,IF(L13="Sedang",2,IF(L13="Rendah",1,""))) -> 1 | R13: =AVERAGE(N13:Q13) -> 1.5 | S13: =IF(R13<$R$1,"Rendah",IF(R13<$R$2,"Sedang","Tinggi")) -> Rendah | U13: Jawa Barat | V13: Jawa Timur | W13: Banten | X13: Jawa Tengah | Y13: DKI Jakarta
B14: 18 | C14: Pencetakan dan Reproduksi Media Rekaman | D14: 22.25 | E14: 10.305336 | F14: 3.0821703 | G14: 27.359873 | I14: =IF(D14<=$D$1,"Rendah",IF(D14<=$D$2,"Sedang","Tinggi")) -> Rendah | J14: =IF(E14<=$E$1,"Rendah",IF(E14<=$E$2,"Sedang","Tinggi")) -> Rendah | K14: =IF(F14<=$F$1,"Rendah",IF(F14<=$F$2,"Sedang","Tinggi")) -> Rendah | L14: =IF(G14<=$G$1,"Rendah",IF(G14<=$G$2,"Sedang","Tinggi")) -> Tinggi | N14: =IF(I14="Tinggi",3,IF(I14="Sedang",2,IF(I14="Rendah",1,""))) -> 1 | O14: =IF(J14="Tinggi",3,IF(J14="Sedang",2,IF(J14="Rendah",1,""))) -> 1 | P14: =IF(K14="Tinggi",3,IF(K14="Sedang",2,IF(K14="Rendah",1,""))) -> 1 | Q14: =IF(L14="Tinggi",3,IF(L14="Sedang",2,IF(L14="Rendah",1,""))) -> 3 | R14: =AVERAGE(N14:Q14) -> 1.5 | S14: =IF(R14<$R$1,"Rendah",IF(R14<$R$2,"Sedang","Tinggi")) -> Rendah | U14: DKI Jakarta | V14: Jawa Barat | W14: Jawa Timur | X14: Jawa Tengah | Y14: Banten
B15: 19 | C15: Produk dari Batu Bara dan Pengilangan Minyak Bumi | D15: 38.05 | E15: 39.809315 | F15: 1.4287098 | G15: 1.7170783 | I15: =IF(D15<=$D$1,"Rendah",IF(D15<=$D$2,"Sedang","Tinggi")) -> Sedang | J15: =IF(E15<=$E$1,"Rendah",IF(E15<=$E$2,"Sedang","Tinggi")) -> Sedang | K15: =IF(F15<=$F$1,"Rendah",IF(F15<=$F$2,"Sedang","Tinggi")) -> Rendah | L15: =IF(G15<=$G$1,"Rendah",IF(G15<=$G$2,"Sedang","Tinggi")) -> Rendah | N15: =IF(I15="Tinggi",3,IF(I15="Sedang",2,IF(I15="Rendah",1,""))) -> 2 | O15: =IF(J15="Tinggi",3,IF(J15="Sedang",2,IF(J15="Rendah",1,""))) -> 2 | P15: =IF(K15="Tinggi",3,IF(K15="Sedang",2,IF(K15="Rendah",1,""))) -> 1 | Q15: =IF(L15="Tinggi",3,IF(L15="Sedang",2,IF(L15="Rendah",1,""))) -> 1 | R15: =AVERAGE(N15:Q15) -> 1.5 | S15: =IF(R15<$R$1,"Rendah",IF(R15<$R$2,"Sedang","Tinggi")) -> Rendah | U15: Jawa Barat | V15: Jawa Timur | W15: Banten | X15: Jawa Tengah | Y15: DKI Jakarta
B16: 20 | C16: Bahan Kimia dan Barang dari Bahan Kimia | D16: 32.9 | E16: 28.450133 | F16: 3.9040525 | G16: 5.162486 | I16: =IF(D16<=$D$1,"Rendah",IF(D16<=$D$2,"Sedang","Tinggi")) -> Sedang | J16: =IF(E16<=$E$1,"Rendah",IF(E16<=$E$2,"Sedang","Tinggi")) -> Sedang | K16: =IF(F16<=$F$1,"Rendah",IF(F16<=$F$2,"Sedang","Tinggi")) -> Sedang | L16: =IF(G16<=$G$1,"Rendah",IF(G16<=$G$2,"Sedang","Tinggi")) -> Rendah | N16: =IF(I16="Tinggi",3,IF(I16="Sedang",2,IF(I16="Rendah",1,""))) -> 2 | O16: =IF(J16="Tinggi",3,IF(J16="Sedang",2,IF(J16="Rendah",1,""))) -> 2 | P16: =IF(K16="Tinggi",3,IF(K16="Sedang",2,IF(K16="Rendah",1,""))) -> 2 | Q16: =IF(L16="Tinggi",3,IF(L16="Sedang",2,IF(L16="Rendah",1,""))) -> 1 | R16: =AVERAGE(N16:Q16) -> 1.75 | S16: =IF(R16<$R$1,"Rendah",IF(R16<$R$2,"Sedang","Tinggi")) -> Sedang | U16: Jawa Barat | V16: Banten | W16: Jawa Timur | X16: Jawa Tengah | Y16: DKI Jakarta
B17: 21 | C17: Farmasi, Produk Obat Kimia dan Obat Tradisional | D17: 18.1 | E17: 51.70402 | F17: 2.5846722 | G17: 14.629665 | I17: =IF(D17<=$D$1,"Rendah",IF(D17<=$D$2,"Sedang","Tinggi")) -> Rendah | J17: =IF(E17<=$E$1,"Rendah",IF(E17<=$E$2,"Sedang","Tinggi")) -> Tinggi | K17: =IF(F17<=$F$1,"Rendah",IF(F17<=$F$2,"Sedang","Tinggi")) -> Rendah | L17: =IF(G17<=$G$1,"Rendah",IF(G17<=$G$2,"Sedang","Tinggi")) -> Sedang | N17: =IF(I17="Tinggi",3,IF(I17="Sedang",2,IF(I17="Rendah",1,""))) -> 1 | O17: =IF(J17="Tinggi",3,IF(J17="Sedang",2,IF(J17="Rendah",1,""))) -> 3 | P17: =IF(K17="Tinggi",3,IF(K17="Sedang",2,IF(K17="Rendah",1,""))) -> 1 | Q17: =IF(L17="Tinggi",3,IF(L17="Sedang",2,IF(L17="Rendah",1,""))) -> 2 | R17: =AVERAGE(N17:Q17) -> 1.75 | S17: =IF(R17<$R$1,"Rendah",IF(R17<$R$2,"Sedang","Tinggi")) -> Sedang | U17: Jawa Barat | V17: Jawa Timur | W17: Jawa Tengah | X17: Banten | Y17: DKI Jakarta
... B29: 33 | C29: Reparasi dan Pemasangan Mesin dan Peralatan | D29: 3.33 | E29: 36.606967 | F29: 18.278673 | G29: 47.627115 | I29: =IF(D29<=$D$1,"Rendah",IF(D29<=$D$2,"Sedang","Tinggi")) -> Rendah | J29: =IF(E29<=$E$1,"Rendah",IF(E29<=$E$2,"Sedang","Tinggi")) -> Sedang | K29: =IF(F29<=$F$1,"Rendah",IF(F29<=$F$2,"Sedang","Tinggi")) -> Tinggi | L29: =IF(G29<=$G$1,"Rendah",IF(G29<=$G$2,"Sedang","Tinggi")) -> Tinggi | N29: =IF(I29="Tinggi",3,IF(I29="Sedang",2,IF(I29="Rendah",1,""))) -> 1 | O29: =IF(J29="Tinggi",3,IF(J29="Sedang",2,IF(J29="Rendah",1,""))) -> 2 | P29: =IF(K29="Tinggi",3,IF(K29="Sedang",2,IF(K29="Rendah",1,""))) -> 3 | Q29: =IF(L29="Tinggi",3,IF(L29="Sedang",2,IF(L29="Rendah",1,""))) -> 3 | R29: =AVERAGE(N29:Q29) -> 2.25 | S29: =IF(R29<$R$1,"Rendah",IF(R29<$R$2,"Sedang","Tinggi")) -> Sedang | U29: Jawa Barat | V29: Kepulauan Riau | W29: Jawa Timur | X29: Banten | Y29: Kalimantan Timur

Sheet Dashboard_Eksposur Kurs
Y1: IBS 2022. dummy | AH1: IBS 2022. dummy
Y2: KBLI | Z2: Eksposur Impor | AA2: Eksposur Ekspor | AD2: Impor (X) | AE2: Ekspor (Y) | AH2: Provinsi | AI2: Eksposur Impor | AJ2: Eksposur Ekspor | AM2: Impor (X) | AN2: Ekspor (Y)
X3: 10 | Y3: Makanan | Z3: 2.8762541 | AA3: 7.304348 | AB3: =IF(AND(Z3>=$AD$3,AA3>=$AE$3),"K1",IF(AND(Z3<$AD$3,AA3>=$AE$3),"K2",IF(AND(Z3<$AD$3,AA3<$AE$3),"K3","K4"))) -> K3 | AD3: =AVERAGE(Z3:Z26) -> 8.9126524 | AE3: =AVERAGE(AA3:AA26) -> 11.345507 | AG3: 11 | AH3: Aceh | AI3: 1.1494253 | AJ3: 4.5977011 | AK3: =IF(AND(AI3>=$AM$3,AJ3>=$AN$3),"K1",IF(AND(AI3<$AM$3,AJ3>=$AN$3),"K2",IF(AND(AI3<$AM$3,AJ3<$AN$3),"K3","K4"))) -> K3 | AM3: =AVERAGE(AI3:AI36) -> 4.2970575 | AN3: =AVERAGE(AJ3:AJ36) -> 11.943857
X4: 11 | Y4: Minuman | Z4: 3.0997305 | AA4: 3.3692722 | AB4: =IF(AND(Z4>=$AD$3,AA4>=$AE$3),"K1",IF(AND(Z4<$AD$3,AA4>=$AE$3),"K2",IF(AND(Z4<$AD$3,AA4<$AE$3),"K3","K4"))) -> K3 | AG4: 12 | AH4: Sumatera Utara | AI4: 8.7816458 | AJ4: 11.70886 | AK4: =IF(AND(AI4>=$AM$3,AJ4>=$AN$3),"K1",IF(AND(AI4<$AM$3,AJ4>=$AN$3),"K2",IF(AND(AI4<$AM$3,AJ4<$AN$3),"K3","K4"))) -> K4
X5: 12 | Y5: Pengolahan Tembakau | Z5: 3.4013608 | AA5: 6.666667 | AB5: =IF(AND(Z5>=$AD$3,AA5>=$AE$3),"K1",IF(AND(Z5<$AD$3,AA5>=$AE$3),"K2",IF(AND(Z5<$AD$3,AA5<$AE$3),"K3","K4"))) -> K3 | AD5: Garis Vertikal | AG5: 13 | AH5: Sumatera Barat | AI5: 3.0612245 | AJ5: 9.1836739 | AK5: =IF(AND(AI5>=$AM$3,AJ5>=$AN$3),"K1",IF(AND(AI5<$AM$3,AJ5>=$AN$3),"K2",IF(AND(AI5<$AM$3,AJ5<$AN$3),"K3","K4"))) -> K3 | AM5: Garis Vertikal
X6: 13 | Y6: Tekstil | Z6: 8.0907745 | AA6: 9.02812 | AB6: =IF(AND(Z6>=$AD$3,AA6>=$AE$3),"K1",IF(AND(Z6<$AD$3,AA6>=$AE$3),"K2",IF(AND(Z6<$AD$3,AA6<$AE$3),"K3","K4"))) -> K3 | AD6: =$AD$3 -> 8.9126524 | AE6: 0 | AG6: 14 | AH6: Riau | AI6: 0.51813471 | AJ6: 5.1813474 | AK6: =IF(AND(AI6>=$AM$3,AJ6>=$AN$3),"K1",IF(AND(AI6<$AM$3,AJ6>=$AN$3),"K2",IF(AND(AI6<$AM$3,AJ6<$AN$3),"K3","K4"))) -> K3 | AM6: =$AM$3 -> 4.2970575 | AN6: 0
X7: 14 | Y7: Pakaian Jadi | Z7: 8.513854 | AA7: 14.105794 | AB7: =IF(AND(Z7>=$AD$3,AA7>=$AE$3),"K1",IF(AND(Z7<$AD$3,AA7>=$AE$3),"K2",IF(AND(Z7<$AD$3,AA7<$AE$3),"K3","K4"))) -> K2 | AD7: =$AD$3 -> 8.9126524 | AE7: =MAX(AA3:AA26)*1.1 -> 39.285715 | AG7: 17 | AH7: Jambi | AI7: 1.0362694 | AJ7: 10.362695 | AK7: =IF(AND(AI7>=$AM$3,AJ7>=$AN$3),"K1",IF(AND(AI7<$AM$3,AJ7>=$AN$3),"K2",IF(AND(AI7<$AM$3,AJ7<$AN$3),"K3","K4"))) -> K3 | AM7: =$AM$3 -> 4.2970575 | AN7: =MAX(AJ3:AJ36)*1.1 -> 35.159818
X8: 15 | Y8: Kulit, Barang dari Kulit dan Alas Kaki | Z8: 11.973684 | AA8: 15.000001 | AB8: =IF(AND(Z8>=$AD$3,AA8>=$AE$3),"K1",IF(AND(Z8<$AD$3,AA8>=$AE$3),"K2",IF(AND(Z8<$AD$3,AA8<$AE$3),"K3","K4"))) -> K1 | AG8: 16 | AH8: Sumatera Selatan | AI8: 4.5016074 | AJ8: 8.0385847 | AK8: =IF(AND(AI8>=$AM$3,AJ8>=$AN$3),"K1",IF(AND(AI8<$AM$3,AJ8>=$AN$3),"K2",IF(AND(AI8<$AM$3,AJ8<$AN$3),"K3","K4"))) -> K4
X9: 16 | Y9: Kayu, Barang dari Kayu dan Gabus (Tidak Termasuk Furnitur) dan Barang Anyaman dari Bambu, Rotan dan Sejenisnya | Z9: 3.7390611 | AA9: 35.640411 | AB9: =IF(AND(Z9>=$AD$3,AA9>=$AE$3),"K1",IF(AND(Z9<$AD$3,AA9>=$AE$3),"K2",IF(AND(Z9<$AD$3,AA9<$AE$3),"K3","K4"))) -> K2 | AD9: Garis Horizontal | AG9: 17 | AH9: Bengkulu | AI9: 0 | AJ9: 8.1081076 | AK9: =IF(AND(AI9>=$AM$3,AJ9>=$AN$3),"K1",IF(AND(AI9<$AM$3,AJ9>=$AN$3),"K2",IF(AND(AI9<$AM$3,AJ9<$AN$3),"K3","K4"))) -> K3 | AM9: Garis Horizontal
X10: 17 | Y10: Kertas dan Barang dari Kertas | Z10: 9.7271652 | AA10: 7.4733095 | AB10: =IF(AND(Z10>=$AD$3,AA10>=$AE$3),"K1",IF(AND(Z10<$AD$3,AA10>=$AE$3),"K2",IF(AND(Z10<$AD$3,AA10<$AE$3),"K3","K4"))) -> K4 | AD10: 0 | AE10: =$AE$3 -> 11.345507 | AG10: 18 | AH10: Lampung | AI10: 2.4038463 | AJ10: 7.9326921 | AK10: =IF(AND(AI10>=$AM$3,AJ10>=$AN$3),"K1",IF(AND(AI10<$AM$3,AJ10>=$AN$3),"K2",IF(AND(AI10<$AM$3,AJ10<$AN$3),"K3","K4"))) -> K3 | AM10: 0 | AN10: =$AN$3 -> 11.943857
X11: 18 | Y11: Pencetakan dan Reproduksi Media Rekaman | Z11: 2.8538811 | AA11: 1.7123288 | AB11: =IF(AND(Z11>=$AD$3,AA11>=$AE$3),"K1",IF(AND(Z11<$AD$3,AA11>=$AE$3),"K2",IF(AND(Z11<$AD$3,AA11<$AE$3),"K3","K4"))) -> K3 | AD11: =MAX(Z3:Z26)*1.1 -> 20 | AE11: =$AE$3 -> 11.345507 | AG11: 19 | AH11: Bangka Belitung | AI11: 3.6363635 | AJ11: 23.636364 | AK11: =IF(AND(AI11>=$AM$3,AJ11>=$AN$3),"K1",IF(AND(AI11<$AM$3,AJ11>=$AN$3),"K2",IF(AND(AI11<$AM$3,AJ11<$AN$3),"K3","K4"))) -> K2 | AM11: =MAX(AI3:AI36)*1.1 -> 38.675798 | AN11: =$AN$3 -> 11.943857
X12: 19 | Y12: Produk dari Batu Bara dan Pengilangan Minyak Bumi | Z12: 4.9382715 | AA12: 4.3209877 | AB12: =IF(AND(Z12>=$AD$3,AA12>=$AE$3),"K1",IF(AND(Z12<$AD$3,AA12>=$AE$3),"K2",IF(AND(Z12<$AD$3,AA12<$AE$3),"K3","K4"))) -> K3 | AG12: 21 | AH12: Kepulauan Riau | AI12: 35.159817 | AJ12: 31.96347 | AK12: =IF(AND(AI12>=$AM$3,AJ12>=$AN$3),"K1",IF(AND(AI12<$AM$3,AJ12>=$AN$3),"K2",IF(AND(AI12<$AM$3,AJ12<$AN$3),"K3","K4"))) -> K1
X13: 20 | Y13: Bahan Kimia dan Barang dari Bahan Kimia | Z13: 10.813542 | AA13: 12.632643 | AB13: =IF(AND(Z13>=$AD$3,AA13>=$AE$3),"K1",IF(AND(Z13<$AD$3,AA13>=$AE$3),"K2",IF(AND(Z13<$AD$3,AA13<$AE$3),"K3","K4"))) -> K1 | AG13: 31 | AH13: Dki Jakarta | AI13: 5.096333 | AJ13: 5.3449349 | AK13: =IF(AND(AI13>=$AM$3,AJ13>=$AN$3),"K1",IF(AND(AI13<$AM$3,AJ13>=$AN$3),"K2",IF(AND(AI13<$AM$3,AJ13<$AN$3),"K3","K4"))) -> K4
X14: 21 | Y14: Farmasi, Produk Obat Kimia dan Obat Tradisional | Z14: 16.546762 | AA14: 7.1942449 | AB14: =IF(AND(Z14>=$AD$3,AA14>=$AE$3),"K1",IF(AND(Z14<$AD$3,AA14>=$AE$3),"K2",IF(AND(Z14<$AD$3,AA14<$AE$3),"K3","K4"))) -> K4 | AG14: 32 | AH14: Jawa Barat | AI14: 7.1264634 | AJ14: 8.25109 | AK14: =IF(AND(AI14>=$AM$3,AJ14>=$AN$3),"K1",IF(AND(AI14<$AM$3,AJ14>=$AN$3),"K2",IF(AND(AI14<$AM$3,AJ14<$AN$3),"K3","K4"))) -> K4
X15: 22 | Y15: Karet, Barang dari Karet dan Plastik | Z15: 9.992733 | AA15: 9.992733 | AB15: =IF(AND(Z15>=$AD$3,AA15>=$AE$3),"K1",IF(AND(Z15<$AD$3,AA15>=$AE$3),"K2",IF(AND(Z15<$AD$3,AA15<$AE$3),"K3","K4"))) -> K4 | AG15: 33 | AH15: Jawa Tengah | AI15: 8.0108624 | AJ15: 19.370899 | AK15: =IF(AND(AI15>=$AM$3,AJ15>=$AN$3),"K1",IF(AND(AI15<$AM$3,AJ15>=$AN$3),"K2",IF(AND(AI15<$AM$3,AJ15<$AN$3),"K3","K4"))) -> K1
X16: 23 | Y16: Barang Galian Bukan Logam | Z16: 4.006772 | AA16: 4.571106 | AB16: =IF(AND(Z16>=$AD$3,AA16>=$AE$3),"K1",IF(AND(Z16<$AD$3,AA16>=$AE$3),"K2",IF(AND(Z16<$AD$3,AA16<$AE$3),"K3","K4"))) -> K3 | AG16: 34 | AH16: Di Yogyakarta | AI16: 6.8222618 | AJ16: 24.057451 | AK16: =IF(AND(AI16>=$AM$3,AJ16>=$AN$3),"K1",IF(AND(AI16<$AM$3,AJ16>=$AN$3),"K2",IF(AND(AI16<$AM$3,AJ16<$AN$3),"K3","K4"))) -> K1
X17: 24 | Y17: Logam Dasar | Z17: 14.681892 | AA17: 14.845024 | AB17: =IF(AND(Z17>=$AD$3,AA17>=$AE$3),"K1",IF(AND(Z17<$AD$3,AA17>=$AE$3),"K2",IF(AND(Z17<$AD$3,AA17<$AE$3),"K3","K4"))) -> K1 | AG17: 35 | AH17: Jawa Timur | AI17: 8.1613216 | AJ17: 11.495713 | AK17: =IF(AND(AI17>=$AM$3,AJ17>=$AN$3),"K1",IF(AND(AI17<$AM$3,AJ17>=$AN$3),"K2",IF(AND(AI17<$AM$3,AJ17<$AN$3),"K3","K4"))) -> K4
X18: 25 | Y18: Barang Logam, Bukan Mesin dan Peralatannya | Z18: 9.32304 | AA18: 5.6413302 | AB18: =IF(AND(Z18>=$AD$3,AA18>=$AE$3),"K1",IF(AND(Z18<$AD$3,AA18>=$AE$3),"K2",IF(AND(Z18<$AD$3,AA18<$AE$3),"K3","K4"))) -> K4 | AG18: 36 | AH18: Banten | AI18: 6.2205958 | AJ18: 5.0967069 | AK18: =IF(AND(AI18>=$AM$3,AJ18>=$AN$3),"K1",IF(AND(AI18<$AM$3,AJ18>=$AN$3),"K2",IF(AND(AI18<$AM$3,AJ18<$AN$3),"K3","K4"))) -> K4
X19: 26 | Y19: Komputer, Barang Elektronik dan Optik | Z19: 18.181818 | AA19: 22.038567 | AB19: =IF(AND(Z19>=$AD$3,AA19>=$AE$3),"K1",IF(AND(Z19<$AD$3,AA19>=$AE$3),"K2",IF(AND(Z19<$AD$3,AA19<$AE$3),"K3","K4"))) -> K1 | AG19: 51 | AH19: Bali | AI19: 10.823529 | AJ19: 31.529411 | AK19: =IF(AND(AI19>=$AM$3,AJ19>=$AN$3),"K1",IF(AND(AI19<$AM$3,AJ19>=$AN$3),"K2",IF(AND(AI19<$AM$3,AJ19<$AN$3),"K3","K4"))) -> K1
X20: 27 | Y20: Peralatan Listrik | Z20: 15.242881 | AA20: 9.7152424 | AB20: =IF(AND(Z20>=$AD$3,AA20>=$AE$3),"K1",IF(AND(Z20<$AD$3,AA20>=$AE$3),"K2",IF(AND(Z20<$AD$3,AA20<$AE$3),"K3","K4"))) -> K4 | AG20: 52 | AH20: Nusa Tenggara Barat | AI20: 0 | AJ20: 0.94339621 | AK20: =IF(AND(AI20>=$AM$3,AJ20>=$AN$3),"K1",IF(AND(AI20<$AM$3,AJ20>=$AN$3),"K2",IF(AND(AI20<$AM$3,AJ20<$AN$3),"K3","K4"))) -> K3
X21: 28 | Y21: Mesin dan Perlengkapan ytdl | Z21: 10.887573 | AA21: 8.1656809 | AB21: =IF(AND(Z21>=$AD$3,AA21>=$AE$3),"K1",IF(AND(Z21<$AD$3,AA21>=$AE$3),"K2",IF(AND(Z21<$AD$3,AA21<$AE$3),"K3","K4"))) -> K4 | AG21: 53 | AH21: Nusa Tenggara Timur | AI21: 1.3157895 | AJ21: 1.3157895 | AK21: =IF(AND(AI21>=$AM$3,AJ21>=$AN$3),"K1",IF(AND(AI21<$AM$3,AJ21>=$AN$3),"K2",IF(AND(AI21<$AM$3,AJ21<$AN$3),"K3","K4"))) -> K3
X22: 29 | Y22: Kendaraan Bermotor, Trailer dan Semi Trailer | Z22: 7.4358978 | AA22: 7.5641026 | AB22: =IF(AND(Z22>=$AD$3,AA22>=$AE$3),"K1",IF(AND(Z22<$AD$3,AA22>=$AE$3),"K2",IF(AND(Z22<$AD$3,AA22<$AE$3),"K3","K4"))) -> K3 | AG22: 61 | AH22: Kalimantan Barat | AI22: 6.060606 | AJ22: 9.090909 | AK22: =IF(AND(AI22>=$AM$3,AJ22>=$AN$3),"K1",IF(AND(AI22<$AM$3,AJ22>=$AN$3),"K2",IF(AND(AI22<$AM$3,AJ22<$AN$3),"K3","K4"))) -> K4
X23: 30 | Y23: Alat Angkutan Lainnya | Z23: 10.126582 | AA23: 6.1181436 | AB23: =IF(AND(Z23>=$AD$3,AA23>=$AE$3),"K1",IF(AND(Z23<$AD$3,AA23>=$AE$3),"K2",IF(AND(Z23<$AD$3,AA23<$AE$3),"K3","K4"))) -> K4 | AG23: 62 | AH23: Kalimantan Tengah | AI23: 0 | AJ23: 6.6265063 | AK23: =IF(AND(AI23>=$AM$3,AJ23>=$AN$3),"K1",IF(AND(AI23<$AM$3,AJ23>=$AN$3),"K2",IF(AND(AI23<$AM$3,AJ23<$AN$3),"K3","K4"))) -> K3
... X26: 33 | Y26: Reparasi dan Pemasangan Mesin dan Peralatan | Z26: 5.0898204 | AA26: 1.7964072 | AB26: =IF(AND(Z26>=$AD$3,AA26>=$AE$3),"K1",IF(AND(Z26<$AD$3,AA26>=$AE$3),"K2",IF(AND(Z26<$AD$3,AA26<$AE$3),"K3","K4"))) -> K3 | AG26: 65 | AH26: Kalimantan Utara | AI26: 0 | AJ26: 21.052631 | AK26: =IF(AND(AI26>=$AM$3,AJ26>=$AN$3),"K1",IF(AND(AI26<$AM$3,AJ26>=$AN$3),"K2",IF(AND(AI26<$AM$3,AJ26<$AN$3),"K3","K4"))) -> K2
AG27: 71 | AH27: Sulawesi Utara | AI27: 7.4074073 | AJ27: 21.296297 | AK27: =IF(AND(AI27>=$AM$3,AJ27>=$AN$3),"K1",IF(AND(AI27<$AM$3,AJ27>=$AN$3),"K2",IF(AND(AI27<$AM$3,AJ27<$AN$3),"K3","K4"))) -> K1
AG28: 72 | AH28: Sulawesi Tengah | AI28: 6.3829789 | AJ28: 18.085106 | AK28: =IF(AND(AI28>=$AM$3,AJ28>=$AN$3),"K1",IF(AND(AI28<$AM$3,AJ28>=$AN$3),"K2",IF(AND(AI28<$AM$3,AJ28<$AN$3),"K3","K4"))) -> K1
AG29: 73 | AH29: Sulawesi Selatan | AI29: 2.1459227 | AJ29: 8.5836906 | AK29: =IF(AND(AI29>=$AM$3,AJ29>=$AN$3),"K1",IF(AND(AI29<$AM$3,AJ29>=$AN$3),"K2",IF(AND(AI29<$AM$3,AJ29<$AN$3),"K3","K4"))) -> K3
AG30: 74 | AH30: Sulawesi Tenggara | AI30: 0.74626863 | AJ30: 5.2238808 | AK30: =IF(AND(AI30>=$AM$3,AJ30>=$AN$3),"K1",IF(AND(AI30<$AM$3,AJ30>=$AN$3),"K2",IF(AND(AI30<$AM$3,AJ30<$AN$3),"K3","K4"))) -> K3
AG31: 75 | AH31: Gorontalo | AI31: 3.4482758 | AJ31: 3.4482758 | AK31: =IF(AND(AI31>=$AM$3,AJ31>=$AN$3),"K1",IF(AND(AI31<$AM$3,AJ31>=$AN$3),"K2",IF(AND(AI31<$AM$3,AJ31<$AN$3),"K3","K4"))) -> K3
AG32: 76 | AH32: Sulawesi Barat | AI32: 0 | AJ32: 11.111112 | AK32: =IF(AND(AI32>=$AM$3,AJ32>=$AN$3),"K1",IF(AND(AI32<$AM$3,AJ32>=$AN$3),"K2",IF(AND(AI32<$AM$3,AJ32<$AN$3),"K3","K4"))) -> K3
AG33: 81 | AH33: Maluku | AI33: 0 | AJ33: 21.052631 | AK33: =IF(AND(AI33>=$AM$3,AJ33>=$AN$3),"K1",IF(AND(AI33<$AM$3,AJ33>=$AN$3),"K2",IF(AND(AI33<$AM$3,AJ33<$AN$3),"K3","K4"))) -> K2
AG34: 82 | AH34: Maluku Utara | AI34: 0 | AJ34: 24.13793 | AK34: =IF(AND(AI34>=$AM$3,AJ34>=$AN$3),"K1",IF(AND(AI34<$AM$3,AJ34>=$AN$3),"K2",IF(AND(AI34<$AM$3,AJ34<$AN$3),"K3","K4"))) -> K2
AG35: 91 | AH35: Papua Barat | AI35: 2.5 | AJ35: 12.5 | AK35: =IF(AND(AI35>=$AM$3,AJ35>=$AN$3),"K1",IF(AND(AI35<$AM$3,AJ35>=$AN$3),"K2",IF(AND(AI35<$AM$3,AJ35<$AN$3),"K3","K4"))) -> K2
AG36: 94 | AH36: Papua | AI36: 0 | AJ36: 0 | AK36: =IF(AND(AI36>=$AM$3,AJ36>=$AN$3),"K1",IF(AND(AI36<$AM$3,AJ36>=$AN$3),"K2",IF(AND(AI36<$AM$3,AJ36<$AN$3),"K3","K4"))) -> K3
Y40: IBS 2015, by value | AD40: Impor (X) | AE40: Ekspor (Y) | AH40: IBS 2015, by value | AM40: Impor (X) | AN40: Ekspor (Y)
Y41: KBLI | Z41: Eksposur Impor | AA41: Eksposur Ekspor | AH41: Provinsi | AI41: Eksposur Impor | AJ41: Eksposur Ekspor
X42: 10 | Y42: Makanan | Z42: 10.286595 | AA42: 57.763515 | AB42: =IF(AND(Z42>=$AD$42,AA42>=$AE$42),"K1",IF(AND(Z42<$AD$42,AA42>=$AE$42),"K2",IF(AND(Z42<$AD$42,AA42<$AE$42),"K3","K4"))) -> K2 | AD42: =AVERAGE(Z42:Z65) -> 27.317001 | AE42: =AVERAGE(AA42:AA65) -> 39.456602 | AG42: 11 | AH42: Aceh | AI42: 1.9298599 | AJ42: 52.56 | AK42: =IF(AND(AI42>=$AM$42,AJ42>=$AN$42),"K1",IF(AND(AI42<$AM$42,AJ42>=$AN$42),"K2",IF(AND(AI42<$AM$42,AJ42<$AN$42),"K3","K4"))) -> K3 | AM42: =AVERAGE(AI42:AI75) -> 8.3122503 | AN42: =AVERAGE(AJ42:AJ75) -> 67.936142
X43: 11 | Y43: Minuman | Z43: 18.341961 | AA43: 12.082777 | AB43: =IF(AND(Z43>=$AD$42,AA43>=$AE$42),"K1",IF(AND(Z43<$AD$42,AA43>=$AE$42),"K2",IF(AND(Z43<$AD$42,AA43<$AE$42),"K3","K4"))) -> K3 | AG43: 12 | AH43: Sumatera Utara | AI43: 6.7991339 | AJ43: 73.708539 | AK43: =IF(AND(AI43>=$AM$42,AJ43>=$AN$42),"K1",IF(AND(AI43<$AM$42,AJ43>=$AN$42),"K2",IF(AND(AI43<$AM$42,AJ43<$AN$42),"K3","K4"))) -> K2
X44: 12 | Y44: Pengolahan Tembakau | Z44: 5.2597781 | AA44: 49.946392 | AB44: =IF(AND(Z44>=$AD$42,AA44>=$AE$42),"K1",IF(AND(Z44<$AD$42,AA44>=$AE$42),"K2",IF(AND(Z44<$AD$42,AA44<$AE$42),"K3","K4"))) -> K2 | AD44: Garis Vertikal | AG44: 13 | AH44: Sumatera Barat | AI44: 0.73298033 | AJ44: 62.238103 | AK44: =IF(AND(AI44>=$AM$42,AJ44>=$AN$42),"K1",IF(AND(AI44<$AM$42,AJ44>=$AN$42),"K2",IF(AND(AI44<$AM$42,AJ44<$AN$42),"K3","K4"))) -> K3 | AM44: Garis Vertikal
X45: 13 | Y45: Tekstil | Z45: 26.924796 | AA45: 40.829237 | AB45: =IF(AND(Z45>=$AD$42,AA45>=$AE$42),"K1",IF(AND(Z45<$AD$42,AA45>=$AE$42),"K2",IF(AND(Z45<$AD$42,AA45<$AE$42),"K3","K4"))) -> K2 | AD45: =$AD$42 -> 27.317001 | AE45: 0 | AG45: 14 | AH45: Riau | AI45: 0.47011442 | AJ45: 63.8541 | AK45: =IF(AND(AI45>=$AM$42,AJ45>=$AN$42),"K1",IF(AND(AI45<$AM$42,AJ45>=$AN$42),"K2",IF(AND(AI45<$AM$42,AJ45<$AN$42),"K3","K4"))) -> K3 | AM45: =$AM$42 -> 8.3122503 | AN45: 0
...

Sheet Summary
A2: IBS 2015, by value | F2: Impor (X) | G2: Ekspor (Y)
A3: KBLI | B3: Eksposur Impor | C3: Eksposur Ekspor
A4: Makanan | B4: 10.286595 | C4: 57.763515 | D4: =IF(AND(B4>=$F$4,C4>=$G$4),"K1",IF(AND(B4<$F$4,C4>=$G$4),"K2",IF(AND(B4<$F$4,C4<$G$4),"K3","K4"))) -> K2 | F4: =AVERAGE(B4:B27) -> 27.317001 | G4: =AVERAGE(C4:C27) -> 39.456602
A5: Minuman | B5: 18.341961 | C5: 12.082777 | D5: =IF(AND(B5>=$F$4,C5>=$G$4),"K1",IF(AND(B5<$F$4,C5>=$G$4),"K2",IF(AND(B5<$F$4,C5<$G$4),"K3","K4"))) -> K3
A6: Pengolahan Tembakau | B6: 5.2597781 | C6: 49.946392 | D6: =IF(AND(B6>=$F$4,C6>=$G$4),"K1",IF(AND(B6<$F$4,C6>=$G$4),"K2",IF(AND(B6<$F$4,C6<$G$4),"K3","K4"))) -> K2 | F6: Garis Vertikal
A7: Tekstil | B7: 26.924796 | C7: 40.829237 | D7: =IF(AND(B7>=$F$4,C7>=$G$4),"K1",IF(AND(B7<$F$4,C7>=$G$4),"K2",IF(AND(B7<$F$4,C7<$G$4),"K3","K4"))) -> K2 | F7: =$F$4 -> 27.317001 | G7: 0
A8: Pakaian Jadi | B8: 40.379095 | C8: 62.02848 | D8: =IF(AND(B8>=$F$4,C8>=$G$4),"K1",IF(AND(B8<$F$4,C8>=$G$4),"K2",IF(AND(B8<$F$4,C8<$G$4),"K3","K4"))) -> K1 | F8: =$F$4 -> 27.317001 | G8: =MAX(C4:C27)*1.1 -> 85.600601
A9: Kulit. Barang dari Kulit dan Alas Kaki | B9: 27.327825 | C9: 43.646983 | D9: =IF(AND(B9>=$F$4,C9>=$G$4),"K1",IF(AND(B9<$F$4,C9>=$G$4),"K2",IF(AND(B9<$F$4,C9<$G$4),"K3","K4"))) -> K1
A10: Kayu. Barang dari Kayu dan Gabus (Tidak Termasuk Furnitur) dan Barang Anyaman dari Bambu. Rotan dan Sejenisnya | B10: 6.8987478 | C10: 69.815778 | D10: =IF(AND(B10>=$F$4,C10>=$G$4),"K1",IF(AND(B10<$F$4,C10>=$G$4),"K2",IF(AND(B10<$F$4,C10<$G$4),"K3","K4"))) -> K2 | F10: Garis Horizontal
A11: Kertas dan Barang dari Kertas | B11: 14.748204 | C11: 26.22246 | D11: =IF(AND(B11>=$F$4,C11>=$G$4),"K1",IF(AND(B11<$F$4,C11>=$G$4),"K2",IF(AND(B11<$F$4,C11<$G$4),"K3","K4"))) -> K3 | F11: 0 | G11: =$G$4 -> 39.456602
A12: Pencetakan dan Reproduksi Media Rekaman | B12: 8.0606694 | C12: 22.251556 | D12: =IF(AND(B12>=$F$4,C12>=$G$4),"K1",IF(AND(B12<$F$4,C12>=$G$4),"K2",IF(AND(B12<$F$4,C12<$G$4),"K3","K4"))) -> K3 | F12: =MAX(B4:B27)*1.1 -> 71.8559 | G12: =$G$4 -> 39.456602
A13: Produk dari Batu Bara dan Pengilangan Minyak Bumi | B13: 11.986769 | C13: 38.045789 | D13: =IF(AND(B13>=$F$4,C13>=$G$4),"K1",IF(AND(B13<$F$4,C13>=$G$4),"K2",IF(AND(B13<$F$4,C13<$G$4),"K3","K4"))) -> K3
A14: Bahan Kimia dan Barang dari Bahan Kimia | B14: 36.000408 | C14: 32.896715 | D14: =IF(AND(B14>=$F$4,C14>=$G$4),"K1",IF(AND(B14<$F$4,C14>=$G$4),"K2",IF(AND(B14<$F$4,C14<$G$4),"K3","K4"))) -> K4 | F14: Impor (X) | G14: Ekspor (Y)
A15: Farmasi. Produk Obat Kimia dan Obat Tradisional | B15: 38.440681 | C15: 18.100142 | D15: =IF(AND(B15>=$F$4,C15>=$G$4),"K1",IF(AND(B15<$F$4,C15>=$G$4),"K2",IF(AND(B15<$F$4,C15<$G$4),"K3","K4"))) -> K4
A16: Karet. Barang dari Karet dan Plastik | B16: 16.748413 | C16: 43.045849 | D16: =IF(AND(B16>=$F$4,C16>=$G$4),"K1",IF(AND(B16<$F$4,C16>=$G$4),"K2",IF(AND(B16<$F$4,C16<$G$4),"K3","K4"))) -> K2 | F16: =MEDIAN(B4:B27) -> 28.53246 | G16: =MEDIAN(C4:C27) -> 35.471252
A17: Barang Galian Bukan Logam | B17: 20.696203 | C17: 29.722375 | D17: =IF(AND(B17>=$F$4,C17>=$G$4),"K1",IF(AND(B17<$F$4,C17>=$G$4),"K2",IF(AND(B17<$F$4,C17<$G$4),"K3","K4"))) -> K3
A18: Logam Dasar | B18: 38.924375 | C18: 47.999677 | D18: =IF(AND(B18>=$F$4,C18>=$G$4),"K1",IF(AND(B18<$F$4,C18>=$G$4),"K2",IF(AND(B18<$F$4,C18<$G$4),"K3","K4"))) -> K1 | F18: Garis Vertikal
A19: Barang Logam. Bukan Mesin dan Peralatannya | B19: 30.67352 | C19: 28.538671 | D19: =IF(AND(B19>=$F$4,C19>=$G$4),"K1",IF(AND(B19<$F$4,C19>=$G$4),"K2",IF(AND(B19<$F$4,C19<$G$4),"K3","K4"))) -> K4 | F19: =$F$16 -> 28.53246 | G19: 0
A20: Komputer. Barang Elektronik dan Optik | B20: 65.323545 | C20: 50.435337 | D20: =IF(AND(B20>=$F$4,C20>=$G$4),"K1",IF(AND(B20<$F$4,C20>=$G$4),"K2",IF(AND(B20<$F$4,C20<$G$4),"K3","K4"))) -> K1 | F20: =$F$16 -> 28.53246 | G20: =MAX(C4:C27)*1.1 -> 85.600601
A21: Peralatan Listrik | B21: 41.873258 | C21: 29.191353 | D21: =IF(AND(B21>=$F$4,C21>=$G$4),"K1",IF(AND(B21<$F$4,C21>=$G$4),"K2",IF(AND(B21<$F$4,C21<$G$4),"K3","K4"))) -> K4
A22: Mesin dan Perlengkapan ytdl | B22: 35.180478 | C22: 28.846573 | D22: =IF(AND(B22>=$F$4,C22>=$G$4),"K1",IF(AND(B22<$F$4,C22>=$G$4),"K2",IF(AND(B22<$F$4,C22<$G$4),"K3","K4"))) -> K4 | F22: Garis Horizontal
A23: Kendaraan Bermotor. Trailer dan Semi Trailer | B23: 33.579929 | C23: 31.315642 | D23: =IF(AND(B23>=$F$4,C23>=$G$4),"K1",IF(AND(B23<$F$4,C23>=$G$4),"K2",IF(AND(B23<$F$4,C23<$G$4),"K3","K4"))) -> K4 | F23: 0 | G23: =$G$16 -> 35.471252
A24: Alat Angkutan Lainnya | B24: 29.737096 | C24: 32.113344 | D24: =IF(AND(B24>=$F$4,C24>=$G$4),"K1",IF(AND(B24<$F$4,C24>=$G$4),"K2",IF(AND(B24<$F$4,C24<$G$4),"K3","K4"))) -> K4 | F24: =MAX(B4:B27)*1.1 -> 71.8559 | G24: =$G$16 -> 35.471252
A25: Furnitur | B25: 7.3534437 | C25: 77.818728 | D25: =IF(AND(B25>=$F$4,C25>=$G$4),"K1",IF(AND(B25<$F$4,C25>=$G$4),"K2",IF(AND(B25<$F$4,C25<$G$4),"K3","K4"))) -> K2
A26: Pengolahan Lainnya | B26: 54.077973 | C26: 70.967738 | D26: =IF(AND(B26>=$F$4,C26>=$G$4),"K1",IF(AND(B26<$F$4,C26>=$G$4),"K2",IF(AND(B26<$F$4,C26<$G$4),"K3","K4"))) -> K1
A27: Jasa Reparasi dan Pemasangan Mesin dan Peralatan | B27: 36.784252 | C27: 3.3333333 | D27: =IF(AND(B27>=$F$4,C27>=$G$4),"K1",IF(AND(B27<$F$4,C27>=$G$4),"K2",IF(AND(B27<$F$4,C27<$G$4),"K3","K4"))) -> K4
A29: IBS 2015, by value | F29: Impor (X) | G29: Ekspor (Y)
A30: Provinsi | B30: Eksposur Impor | C30: Eksposur Ekspor
A31: Aceh | B31: 1.9298599 | C31: 52.56 | D31: =IF(AND(B31>=$F$31,C31>=$G$31),"K1",IF(AND(B31<$F$31,C31>=$G$31),"K2",IF(AND(B31<$F$31,C31<$G$31),"K3","K4"))) -> K3 | F31: =AVERAGE(B31:B64) -> 8.3122503 | G31: =AVERAGE(C31:C64) -> 67.936142
A32: Sumatera Utara | B32: 6.7991339 | C32: 73.708539 | D32: =IF(AND(B32>=$F$31,C32>=$G$31),"K1",IF(AND(B32<$F$31,C32>=$G$31),"K2",IF(AND(B32<$F$31,C32<$G$31),"K3","K4"))) -> K2
A33: Sumatera Barat | B33: 0.73298033 | C33: 62.238103 | D33: =IF(AND(B33>=$F$31,C33>=$G$31),"K1",IF(AND(B33<$F$31,C33>=$G$31),"K2",IF(AND(B33<$F$31,C33<$G$31),"K3","K4"))) -> K3 | F33: Garis Vertikal
A34: Riau | B34: 0.47011442 | C34: 63.8541 | D34: =IF(AND(B34>=$F$31,C34>=$G$31),"K1",IF(AND(B34<$F$31,C34>=$G$31),"K2",IF(AND(B34<$F$31,C34<$G$31),"K3","K4"))) -> K3 | F34: =$F$31 -> 8.3122503 | G34: 0
A35: Jambi | B35: 0.46810596 | C35: 71.364534 | D35: =IF(AND(B35>=$F$31,C35>=$G$31),"K1",IF(AND(B35<$F$31,C35>=$G$31),"K2",IF(AND(B35<$F$31,C35<$G$31),"K3","K4"))) -> K2 | F35: =$F$31 -> 8.3122503 | G35: =MAX(C31:C64)*1.1 -> 110
A36: Sumatera Selatan | B36: 0.98438138 | C36: 82.283256 | D36: =IF(AND(B36>=$F$31,C36>=$G$31),"K1",IF(AND(B36<$F$31,C36>=$G$31),"K2",IF(AND(B36<$F$31,C36<$G$31),"K3","K4"))) -> K2
A37: Bengkulu | B37: 0.0077126133 | C37: 86.892 | D37: =IF(AND(B37>=$F$31,C37>=$G$31),"K1",IF(AND(B37<$F$31,C37>=$G$31),"K2",IF(AND(B37<$F$31,C37<$G$31),"K3","K4"))) -> K2 | F37: Garis Horizontal
A38: Lampung | B38: 13.29437 | C38: 66.907639 | D38: =IF(AND(B38>=$F$31,C38>=$G$31),"K1",IF(AND(B38<$F$31,C38>=$G$31),"K2",IF(AND(B38<$F$31,C38<$G$31),"K3","K4"))) -> K4 | F38: 0 | G38: =$G$31 -> 67.936142
A39: Bangka Belitung | B39: 0.39376654 | C39: 88.029707 | D39: =IF(AND(B39>=$F$31,C39>=$G$31),"K1",IF(AND(B39<$F$31,C39>=$G$31),"K2",IF(AND(B39<$F$31,C39<$G$31),"K3","K4"))) -> K2 | F39: =MAX(B31:B64)*1.1 -> 42.092049 | G39: =$G$31 -> 67.936142
A40: Kepulauan Riau | B40: 38.265499 | C40: 77.710719 | D40: =IF(AND(B40>=$F$31,C40>=$G$31),"K1",IF(AND(B40<$F$31,C40>=$G$31),"K2",IF(AND(B40<$F$31,C40<$G$31),"K3","K4"))) -> K1
A41: Dki Jakarta | B41: 30.348546 | C41: 38.218827 | D41: =IF(AND(B41>=$F$31,C41>=$G$31),"K1",IF(AND(B41<$F$31,C41>=$G$31),"K2",IF(AND(B41<$F$31,C41<$G$31),"K3","K4"))) -> K4
A42: Jawa Barat | B42: 38.159048 | C42: 36.321702 | D42: =IF(AND(B42>=$F$31,C42>=$G$31),"K1",IF(AND(B42<$F$31,C42>=$G$31),"K2",IF(AND(B42<$F$31,C42<$G$31),"K3","K4"))) -> K4
...

Sheet Comparables_Data IBS
A2: Per KBLI
A3: Kode KBLI | B3: Uraian Deskripsi | C3: Eksposur Ekspor | D3: Eksposur Impor | K3: Biaya Energi | R3: Biaya Tenaga Kerja
C4: 2015 | D4: 2015 | E4: 2017 | F4: 2018 | G4: 2019 | H4: 2020 | I4: 2021 | J4: 2022 | K4: 2015 | L4: 2017 | M4: 2018 | N4: 2019 | O4: 2020 | P4: 2021 | Q4: 2022 | R4: 2015 | S4: 2017 | T4: 2018 | U4: 2019 | V4: 2020 | W4: 2021 | X4: 2022
A5: 10 | B5: Makanan | C5: ='Data IBS per Tahun'!C5 -> 57.76 | D5: ='Data IBS per Tahun'!F5 -> 10.286595 | E5: ='Data IBS per Tahun'!O5 -> 3.9071189 | F5: ='Data IBS per Tahun'!X5 -> 6.0050081 | G5: ='Data IBS per Tahun'!AG5 -> 7.9811348 | H5: ='Data IBS per Tahun'!AP5 -> 10.876492 | I5: ='Data IBS per Tahun'!AY5 -> 8.0643363 | J5: ='Data IBS per Tahun'!BH5 -> 8.022286 | K5: ='Data IBS per Tahun'!I5 -> 4.9471794 | L5: ='Data IBS per Tahun'!R5 -> 2.1335904 | M5: ='Data IBS per Tahun'!AA5 -> 2.777781 | N5: ='Data IBS per Tahun'!AJ5 -> 1.7362296 | O5: ='Data IBS per Tahun'!AS5 -> 1.631643 | P5: ='Data IBS per Tahun'!BB5 -> 1.2295314 | Q5: ='Data IBS per Tahun'!BK5 -> 1.7244097 | R5: ='Data IBS per Tahun'!L5 -> 4.249545 | S5: ='Data IBS per Tahun'!U5 -> 4.1298754 | T5: ='Data IBS per Tahun'!AD5 -> 4.6004015 | U5: ='Data IBS per Tahun'!AM5 -> 4.689495 | V5: ='Data IBS per Tahun'!AV5 -> 4.5262182 | W5: ='Data IBS per Tahun'!BE5 -> 4.0736086 | X5: ='Data IBS per Tahun'!BN5 -> 3.7494466
A6: 11 | B6: Minuman | C6: ='Data IBS per Tahun'!C6 -> 12.08 | D6: ='Data IBS per Tahun'!F6 -> 18.341961 | E6: ='Data IBS per Tahun'!O6 -> 8.3242182 | F6: ='Data IBS per Tahun'!X6 -> 8.9451197 | G6: ='Data IBS per Tahun'!AG6 -> 4.9321992 | H6: ='Data IBS per Tahun'!AP6 -> 7.6222475 | I6: ='Data IBS per Tahun'!AY6 -> 11.781227 | J6: ='Data IBS per Tahun'!BH6 -> 14.659392 | K6: ='Data IBS per Tahun'!I6 -> 11.358543 | L6: ='Data IBS per Tahun'!R6 -> 9.0520401 | M6: ='Data IBS per Tahun'!AA6 -> 8.6007802 | N6: ='Data IBS per Tahun'!AJ6 -> 4.1983327 | O6: ='Data IBS per Tahun'!AS6 -> 6.7975943 | P6: ='Data IBS per Tahun'!BB6 -> 9.5615079 | Q6: ='Data IBS per Tahun'!BK6 -> 9.6004284 | R6: ='Data IBS per Tahun'!L6 -> 20.340764 | S6: ='Data IBS per Tahun'!U6 -> 30.062742 | T6: ='Data IBS per Tahun'!AD6 -> 16.604686 | U6: ='Data IBS per Tahun'!AM6 -> 16.059616 | V6: ='Data IBS per Tahun'!AV6 -> 16.303495 | W6: ='Data IBS per Tahun'!BE6 -> 22.352723 | X6: ='Data IBS per Tahun'!BN6 -> 23.955096
A7: 12 | B7: Pengolahan Tembakau | C7: ='Data IBS per Tahun'!C7 -> 49.95 | D7: ='Data IBS per Tahun'!F7 -> 5.2597781 | E7: ='Data IBS per Tahun'!O7 -> 6.7192596 | F7: ='Data IBS per Tahun'!X7 -> 2.280357 | G7: ='Data IBS per Tahun'!AG7 -> 10.604225 | H7: ='Data IBS per Tahun'!AP7 -> 3.5517356 | I7: ='Data IBS per Tahun'!AY7 -> 4.1333655 | J7: ='Data IBS per Tahun'!BH7 -> 6.8926004 | K7: ='Data IBS per Tahun'!I7 -> 7.4135049 | L7: ='Data IBS per Tahun'!R7 -> 1.7253626 | M7: ='Data IBS per Tahun'!AA7 -> 1.558403 | N7: ='Data IBS per Tahun'!AJ7 -> 0.71497095 | O7: ='Data IBS per Tahun'!AS7 -> 0.5439276 | P7: ='Data IBS per Tahun'!BB7 -> 1.7836268 | Q7: ='Data IBS per Tahun'!BK7 -> 0.83883462 | R7: ='Data IBS per Tahun'!L7 -> 10.040084 | S7: ='Data IBS per Tahun'!U7 -> 15.755684 | T7: ='Data IBS per Tahun'!AD7 -> 6.1901252 | U7: ='Data IBS per Tahun'!AM7 -> 12.808096 | V7: ='Data IBS per Tahun'!AV7 -> 11.889189 | W7: ='Data IBS per Tahun'!BE7 -> 12.486688 | X7: ='Data IBS per Tahun'!BN7 -> 11.533097
A8: 13 | B8: Tekstil | C8: ='Data IBS per Tahun'!C8 -> 40.83 | D8: ='Data IBS per Tahun'!F8 -> 23.877255 | E8: ='Data IBS per Tahun'!O8 -> 28.023789 | F8: ='Data IBS per Tahun'!X8 -> 28.705487 | G8: ='Data IBS per Tahun'!AG8 -> 22.757643 | H8: ='Data IBS per Tahun'!AP8 -> 30.603991 | I8: ='Data IBS per Tahun'!AY8 -> 20.838298 | J8: ='Data IBS per Tahun'!BH8 -> 34.801635 | K8: ='Data IBS per Tahun'!I8 -> 17.823805 | L8: ='Data IBS per Tahun'!R8 -> 13.05477 | M8: ='Data IBS per Tahun'!AA8 -> 10.635997 | N8: ='Data IBS per Tahun'!AJ8 -> 5.6076435 | O8: ='Data IBS per Tahun'!AS8 -> 5.6081108 | P8: ='Data IBS per Tahun'!BB8 -> 3.8396151 | Q8: ='Data IBS per Tahun'!BK8 -> 8.3422448 | R8: ='Data IBS per Tahun'!L8 -> 7.6056083 | S8: ='Data IBS per Tahun'!U8 -> 18.543663 | T8: ='Data IBS per Tahun'!AD8 -> 12.733929 | U8: ='Data IBS per Tahun'!AM8 -> 12.408387 | V8: ='Data IBS per Tahun'!AV8 -> 11.139974 | W8: ='Data IBS per Tahun'!BE8 -> 11.087166 | X8: ='Data IBS per Tahun'!BN8 -> 13.701183
A9: 14 | B9: Pakaian Jadi | C9: ='Data IBS per Tahun'!C9 -> 62.03 | D9: ='Data IBS per Tahun'!F9 -> 40.379095 | E9: ='Data IBS per Tahun'!O9 -> 56.64104 | F9: ='Data IBS per Tahun'!X9 -> 56.414638 | G9: ='Data IBS per Tahun'!AG9 -> 44.477051 | H9: ='Data IBS per Tahun'!AP9 -> 55.366891 | I9: ='Data IBS per Tahun'!AY9 -> 78.39551 | J9: ='Data IBS per Tahun'!BH9 -> 70.847882 | K9: ='Data IBS per Tahun'!I9 -> 10.80069 | L9: ='Data IBS per Tahun'!R9 -> 8.3919588 | M9: ='Data IBS per Tahun'!AA9 -> 4.2742892 | N9: ='Data IBS per Tahun'!AJ9 -> 3.0782239 | O9: ='Data IBS per Tahun'!AS9 -> 5.504098 | P9: ='Data IBS per Tahun'!BB9 -> 2.8376337 | Q9: ='Data IBS per Tahun'!BK9 -> 4.054556 | R9: ='Data IBS per Tahun'!L9 -> 24.345768 | S9: ='Data IBS per Tahun'!U9 -> 80.849355 | T9: ='Data IBS per Tahun'!AD9 -> 48.754277 | U9: ='Data IBS per Tahun'!AM9 -> 33.690628 | V9: ='Data IBS per Tahun'!AV9 -> 36.721967 | W9: ='Data IBS per Tahun'!BE9 -> 22.259562 | X9: ='Data IBS per Tahun'!BN9 -> 30.579504
A10: 15 | B10: Kulit. Barang dari Kulit dan Alas Kaki | C10: ='Data IBS per Tahun'!C10 -> 43.65 | D10: ='Data IBS per Tahun'!F10 -> 27.327825 | E10: ='Data IBS per Tahun'!O10 -> 33.007514 | F10: ='Data IBS per Tahun'!X10 -> 36.167703 | G10: ='Data IBS per Tahun'!AG10 -> 41.880489 | H10: ='Data IBS per Tahun'!AP10 -> 43.654115 | I10: ='Data IBS per Tahun'!AY10 -> 51.82807 | J10: ='Data IBS per Tahun'!BH10 -> 34.884554 | K10: ='Data IBS per Tahun'!I10 -> 11.240078 | L10: ='Data IBS per Tahun'!R10 -> 4.9154874 | M10: ='Data IBS per Tahun'!AA10 -> 10.483626 | N10: ='Data IBS per Tahun'!AJ10 -> 28.749538 | O10: ='Data IBS per Tahun'!AS10 -> 2.9476272 | P10: ='Data IBS per Tahun'!BB10 -> 0.87392719 | Q10: ='Data IBS per Tahun'!BK10 -> 2.2432006 | R10: ='Data IBS per Tahun'!L10 -> 32.537282 | S10: ='Data IBS per Tahun'!U10 -> 38.631894 | T10: ='Data IBS per Tahun'!AD10 -> 26.456134 | U10: ='Data IBS per Tahun'!AM10 -> 53.068453 | V10: ='Data IBS per Tahun'!AV10 -> 41.376521 | W10: ='Data IBS per Tahun'!BE10 -> 28.334449 | X10: ='Data IBS per Tahun'!BN10 -> 34.188985
A11: 16 | B11: Kayu. Barang dari Kayu dan Gabus (Tidak Termasuk Furnitur) dan Barang Anyaman dari Bambu. Rotan dan Sejenisnya | C11: ='Data IBS per Tahun'!C11 -> 69.82 | D11: ='Data IBS per Tahun'!F11 -> 6.8987478 | E11: ='Data IBS per Tahun'!O11 -> 6.3386315 | F11: ='Data IBS per Tahun'!X11 -> 5.2276788 | G11: ='Data IBS per Tahun'!AG11 -> 4.70815 | H11: ='Data IBS per Tahun'!AP11 -> 4.9220473 | I11: ='Data IBS per Tahun'!AY11 -> 4.6126491 | J11: ='Data IBS per Tahun'!BH11 -> 6.4480895 | K11: ='Data IBS per Tahun'!I11 -> 9.1308046 | L11: ='Data IBS per Tahun'!R11 -> 9.7327499 | M11: ='Data IBS per Tahun'!AA11 -> 5.4215583 | N11: ='Data IBS per Tahun'!AJ11 -> 6.503116 | O11: ='Data IBS per Tahun'!AS11 -> 4.3665723 | P11: ='Data IBS per Tahun'!BB11 -> 5.1779452 | Q11: ='Data IBS per Tahun'!BK11 -> 7.1492164 | R11: ='Data IBS per Tahun'!L11 -> 26.452061 | S11: ='Data IBS per Tahun'!U11 -> 22.606136 | T11: ='Data IBS per Tahun'!AD11 -> 16.830829 | U11: ='Data IBS per Tahun'!AM11 -> 22.600758 | V11: ='Data IBS per Tahun'!AV11 -> 22.457655 | W11: ='Data IBS per Tahun'!BE11 -> 25.741451 | X11: ='Data IBS per Tahun'!BN11 -> 26.010911
A12: 17 | B12: Kertas dan Barang dari Kertas | C12: ='Data IBS per Tahun'!C12 -> 26.22 | D12: ='Data IBS per Tahun'!F12 -> 14.748204 | E12: ='Data IBS per Tahun'!O12 -> 12.206216 | F12: ='Data IBS per Tahun'!X12 -> 9.219786 | G12: ='Data IBS per Tahun'!AG12 -> 11.282842 | H12: ='Data IBS per Tahun'!AP12 -> 14.79878 | I12: ='Data IBS per Tahun'!AY12 -> 12.367185 | J12: ='Data IBS per Tahun'!BH12 -> 12.64029 | K12: ='Data IBS per Tahun'!I12 -> 15.578901 | L12: ='Data IBS per Tahun'!R12 -> 13.859415 | M12: ='Data IBS per Tahun'!AA12 -> 12.828293 | N12: ='Data IBS per Tahun'!AJ12 -> 2.9268061 | O12: ='Data IBS per Tahun'!AS12 -> 9.9251514 | P12: ='Data IBS per Tahun'!BB12 -> 4.5552606 | Q12: ='Data IBS per Tahun'!BK12 -> 6.9845549 | R12: ='Data IBS per Tahun'!L12 -> 7.9318925 | S12: ='Data IBS per Tahun'!U12 -> 17.856856 | T12: ='Data IBS per Tahun'!AD12 -> 11.058908 | U12: ='Data IBS per Tahun'!AM12 -> 7.0895334 | V12: ='Data IBS per Tahun'!AV12 -> 7.868275 | W12: ='Data IBS per Tahun'!BE12 -> 10.128308 | X12: ='Data IBS per Tahun'!BN12 -> 9.4763915
A13: 18 | B13: Pencetakan dan Reproduksi Media Rekaman | C13: ='Data IBS per Tahun'!C13 -> 22.25 | D13: ='Data IBS per Tahun'!F13 -> 7.1621298 | E13: ='Data IBS per Tahun'!O13 -> 5.5996008 | F13: ='Data IBS per Tahun'!X13 -> 7.2843422 | G13: ='Data IBS per Tahun'!AG13 -> 11.476961 | H13: ='Data IBS per Tahun'!AP13 -> 23.298253 | I13: ='Data IBS per Tahun'!AY13 -> 6.7337378 | J13: ='Data IBS per Tahun'!BH13 -> 10.305336 | K13: ='Data IBS per Tahun'!I13 -> 10.184928 | L13: ='Data IBS per Tahun'!R13 -> 7.7783227 | M13: ='Data IBS per Tahun'!AA13 -> 4.8277924 | N13: ='Data IBS per Tahun'!AJ13 -> 1.7376258 | O13: ='Data IBS per Tahun'!AS13 -> 1.5722909 | P13: ='Data IBS per Tahun'!BB13 -> 1.8491489 | Q13: ='Data IBS per Tahun'!BK13 -> 3.0821703 | R13: ='Data IBS per Tahun'!L13 -> 16.282539 | S13: ='Data IBS per Tahun'!U13 -> 64.388293 | T13: ='Data IBS per Tahun'!AD13 -> 13.232599 | U13: ='Data IBS per Tahun'!AM13 -> 12.261791 | V13: ='Data IBS per Tahun'!AV13 -> 13.435607 | W13: ='Data IBS per Tahun'!BE13 -> 25.34682 | X13: ='Data IBS per Tahun'!BN13 -> 27.359873
A14: 19 | B14: Produk dari Batu Bara dan Pengilangan Minyak Bumi | C14: ='Data IBS per Tahun'!C14 -> 38.05 | D14: ='Data IBS per Tahun'!F14 -> 11.986769 | E14: ='Data IBS per Tahun'!O14 -> 20.453907 | F14: ='Data IBS per Tahun'!X14 -> 29.108167 | G14: ='Data IBS per Tahun'!AG14 -> 23.010713 | H14: ='Data IBS per Tahun'!AP14 -> 23.25549 | I14: ='Data IBS per Tahun'!AY14 -> 7.8359927 | J14: ='Data IBS per Tahun'!BH14 -> 35.282602 | K14: ='Data IBS per Tahun'!I14 -> 24.924531 | L14: ='Data IBS per Tahun'!R14 -> 3.6877566 | M14: ='Data IBS per Tahun'!AA14 -> 0.19229015 | N14: ='Data IBS per Tahun'!AJ14 -> 0.63035891 | O14: ='Data IBS per Tahun'!AS14 -> 3.9411892 | P14: ='Data IBS per Tahun'!BB14 -> 0.72427097 | Q14: ='Data IBS per Tahun'!BK14 -> 1.2662514 | R14: ='Data IBS per Tahun'!L14 -> 13.89076 | S14: ='Data IBS per Tahun'!U14 -> 5.281684 | T14: ='Data IBS per Tahun'!AD14 -> 1.1570151 | U14: ='Data IBS per Tahun'!AM14 -> 0.84953266 | V14: ='Data IBS per Tahun'!AV14 -> 2.3310103 | W14: ='Data IBS per Tahun'!BE14 -> 1.5088109 | X14: ='Data IBS per Tahun'!BN14 -> 1.5218295
A15: 20 | B15: Bahan Kimia dan Barang dari Bahan Kimia | C15: ='Data IBS per Tahun'!C15 -> 32.9 | D15: ='Data IBS per Tahun'!F15 -> 36.000408 | E15: ='Data IBS per Tahun'!O15 -> 21.140298 | F15: ='Data IBS per Tahun'!X15 -> 29.858577 | G15: ='Data IBS per Tahun'!AG15 -> 27.208118 | H15: ='Data IBS per Tahun'!AP15 -> 44.884505 | I15: ='Data IBS per Tahun'!AY15 -> 28.222592 | J15: ='Data IBS per Tahun'!BH15 -> 28.450133 | K15: ='Data IBS per Tahun'!I15 -> 19.092618 | L15: ='Data IBS per Tahun'!R15 -> 12.065865 | M15: ='Data IBS per Tahun'!AA15 -> 8.8959129 | N15: ='Data IBS per Tahun'!AJ15 -> 5.8422486 | O15: ='Data IBS per Tahun'!AS15 -> 3.646951 | P15: ='Data IBS per Tahun'!BB15 -> 3.6754013 | Q15: ='Data IBS per Tahun'!BK15 -> 4.417136 | R15: ='Data IBS per Tahun'!L15 -> 5.6000968 | S15: ='Data IBS per Tahun'!U15 -> 8.8252403 | T15: ='Data IBS per Tahun'!AD15 -> 9.6636696 | U15: ='Data IBS per Tahun'!AM15 -> 5.3321269 | V15: ='Data IBS per Tahun'!AV15 -> 4.4688099 | W15: ='Data IBS per Tahun'!BE15 -> 4.4696787 | X15: ='Data IBS per Tahun'!BN15 -> 5.162486
A16: 21 | B16: Farmasi. Produk Obat Kimia dan Obat Tradisional | C16: ='Data IBS per Tahun'!C16 -> 18.1 | D16: ='Data IBS per Tahun'!F16 -> 38.440681 | E16: ='Data IBS per Tahun'!O16 -> 49.359729 | F16: ='Data IBS per Tahun'!X16 -> 33.077772 | G16: ='Data IBS per Tahun'!AG16 -> 42.474842 | H16: ='Data IBS per Tahun'!AP16 -> 36.617124 | I16: ='Data IBS per Tahun'!AY16 -> 48.235757 | J16: ='Data IBS per Tahun'!BH16 -> 51.70402 | K16: ='Data IBS per Tahun'!I16 -> 19.647533 | L16: ='Data IBS per Tahun'!R16 -> 3.757599 | M16: ='Data IBS per Tahun'!AA16 -> 5.1069985 | N16: ='Data IBS per Tahun'!AJ16 -> 2.5123088 | O16: ='Data IBS per Tahun'!AS16 -> 4.5950795 | P16: ='Data IBS per Tahun'!BB16 -> 1.6151952 | Q16: ='Data IBS per Tahun'!BK16 -> 2.5846722 | R16: ='Data IBS per Tahun'!L16 -> 22.781011 | S16: ='Data IBS per Tahun'!U16 -> 25.862947 | T16: ='Data IBS per Tahun'!AD16 -> 16.955575 | U16: ='Data IBS per Tahun'!AM16 -> 21.226718 | V16: ='Data IBS per Tahun'!AV16 -> 15.366898 | W16: ='Data IBS per Tahun'!BE16 -> 13.85809 | X16: ='Data IBS per Tahun'!BN16 -> 14.629665
... A28: 33 | B28: Jasa Reparasi dan Pemasangan Mesin dan Peralatan | C28: ='Data IBS per Tahun'!C28 -> 3.33 | D28: ='Data IBS per Tahun'!F28 -> 36.784252 | E28: ='Data IBS per Tahun'!O28 -> 20.383268 | F28: ='Data IBS per Tahun'!X28 -> 0.39330311 | G28: ='Data IBS per Tahun'!AG28 -> 7.6597826 | H28: ='Data IBS per Tahun'!AP28 -> 3.4746887 | I28: ='Data IBS per Tahun'!AY28 -> 24.26511 | J28: ='Data IBS per Tahun'!BH28 -> 36.606967 | K28: ='Data IBS per Tahun'!I28 -> 40.142892 | L28: ='Data IBS per Tahun'!R28 -> 8.1247782 | M28: ='Data IBS per Tahun'!AA28 -> 5.0692507 | N28: ='Data IBS per Tahun'!AJ28 -> 17.360277 | O28: ='Data IBS per Tahun'!AS28 -> 2.2536718 | P28: ='Data IBS per Tahun'!BB28 -> 47.663581 | Q28: ='Data IBS per Tahun'!BK28 -> 18.278673 | R28: ='Data IBS per Tahun'!L28 -> 70.102767 | S28: ='Data IBS per Tahun'!U28 -> 34.700612 | T28: ='Data IBS per Tahun'!AD28 -> 22.461973 | U28: ='Data IBS per Tahun'!AM28 -> 19.919636 | V28: ='Data IBS per Tahun'!AV28 -> 16.597704 | W28: ='Data IBS per Tahun'!BE28 -> 219.26592 | X28: ='Data IBS per Tahun'!BN28 -> 47.627115
A31: Per Provinsi
A32: Kode Prov | B32: Uraian Deskripsi | C32: Eksposur Ekspor | D32: Eksposur Impor | K32: Biaya Energi | R32: Biaya Tenaga Kerja
C33: 2015 | D33: 2015 | E33: 2017 | F33: 2018 | G33: 2019 | H33: 2020 | I33: 2021 | J33: 2022 | K33: 2015 | L33: 2017 | M33: 2018 | N33: 2019 | O33: 2020 | P33: 2021 | Q33: 2022 | R33: 2015 | S33: 2017 | T33: 2018 | U33: 2019 | V33: 2020 | W33: 2021 | X33: 2022
A34: 11 | B34: Aceh | C34: ='Data IBS per Tahun'!C34 -> 52.56 | D34: ='Data IBS per Tahun'!F34 -> 1.9298599 | E34: ='Data IBS per Tahun'!O34 -> 5.3042313 | F34: ='Data IBS per Tahun'!X34 -> 0.33096501 | G34: ='Data IBS per Tahun'!AG34 -> 0.60668051 | H34: ='Data IBS per Tahun'!AP34 -> 2.2340829 | I34: ='Data IBS per Tahun'!AY34 -> 0.28026889 | J34: ='Data IBS per Tahun'!BH34 -> 1.6875567 | K34: ='Data IBS per Tahun'!I34 -> 22.881793 | L34: ='Data IBS per Tahun'!R34 -> 2.3096216 | M34: ='Data IBS per Tahun'!AA34 -> 3.9144696 | N34: ='Data IBS per Tahun'!AJ34 -> 4.6439732 | O34: ='Data IBS per Tahun'!AS34 -> 2.4045964 | P34: ='Data IBS per Tahun'!BB34 -> 2.523839 | Q34: ='Data IBS per Tahun'!BK34 -> 3.7841139 | R34: ='Data IBS per Tahun'!L34 -> 7.8270718 | S34: ='Data IBS per Tahun'!U34 -> 3.6555693 | T34: ='Data IBS per Tahun'!AD34 -> 11.78593 | U34: ='Data IBS per Tahun'!AM34 -> 9.6337763 | V34: ='Data IBS per Tahun'!AV34 -> 6.6508288 | W34: ='Data IBS per Tahun'!BE34 -> 6.0727701 | X34: ='Data IBS per Tahun'!BN34 -> 6.556044
A35: 12 | B35: Sumatera Utara | C35: ='Data IBS per Tahun'!C35 -> 73.708539 | D35: ='Data IBS per Tahun'!F35 -> 6.7991339 | E35: ='Data IBS per Tahun'!O35 -> 6.0327164 | F35: ='Data IBS per Tahun'!X35 -> 10.943522 | G35: ='Data IBS per Tahun'!AG35 -> 11.982184 | H35: ='Data IBS per Tahun'!AP35 -> 10.156831 | I35: ='Data IBS per Tahun'!AY35 -> 11.017647 | J35: ='Data IBS per Tahun'!BH35 -> 7.9632771 | K35: ='Data IBS per Tahun'!I35 -> 3.6896007 | L35: ='Data IBS per Tahun'!R35 -> 2.7997304 | M35: ='Data IBS per Tahun'!AA35 -> 3.4644919 | N35: ='Data IBS per Tahun'!AJ35 -> 2.9233244 | O35: ='Data IBS per Tahun'!AS35 -> 2.973817 | P35: ='Data IBS per Tahun'!BB35 -> 2.6381687 | Q35: ='Data IBS per Tahun'!BK35 -> 2.9654109 | R35: ='Data IBS per Tahun'!L35 -> 5.5291612 | S35: ='Data IBS per Tahun'!U35 -> 4.9645737 | T35: ='Data IBS per Tahun'!AD35 -> 5.7166129 | U35: ='Data IBS per Tahun'!AM35 -> 6.3567055 | V35: ='Data IBS per Tahun'!AV35 -> 6.0641202 | W35: ='Data IBS per Tahun'!BE35 -> 5.8565947 | X35: ='Data IBS per Tahun'!BN35 -> 5.1696765
A36: 13 | B36: Sumatera Barat | C36: ='Data IBS per Tahun'!C36 -> 62.238103 | D36: ='Data IBS per Tahun'!F36 -> 0.73298033 | E36: ='Data IBS per Tahun'!O36 -> 0.55905285 | F36: ='Data IBS per Tahun'!X36 -> 3.1384832 | G36: ='Data IBS per Tahun'!AG36 -> 5.5060856 | H36: ='Data IBS per Tahun'!AP36 -> 4.3839972 | I36: ='Data IBS per Tahun'!AY36 -> 3.5009209 | J36: ='Data IBS per Tahun'!BH36 -> 0.96051259 | K36: ='Data IBS per Tahun'!I36 -> 10.973861 | L36: ='Data IBS per Tahun'!R36 -> 6.7440372 | M36: ='Data IBS per Tahun'!AA36 -> 7.7603509 | N36: ='Data IBS per Tahun'!AJ36 -> 8.5536036 | O36: ='Data IBS per Tahun'!AS36 -> 7.5652911 | P36: ='Data IBS per Tahun'!BB36 -> 6.9155869 | Q36: ='Data IBS per Tahun'!BK36 -> 5.1537691 | R36: ='Data IBS per Tahun'!L36 -> 7.9833115 | S36: ='Data IBS per Tahun'!U36 -> 5.3912249 | T36: ='Data IBS per Tahun'!AD36 -> 7.5249437 | U36: ='Data IBS per Tahun'!AM36 -> 6.3402069 | V36: ='Data IBS per Tahun'!AV36 -> 5.174305 | W36: ='Data IBS per Tahun'!BE36 -> 5.068838 | X36: ='Data IBS per Tahun'!BN36 -> 2.3006415
A37: 14 | B37: Riau | C37: ='Data IBS per Tahun'!C37 -> 63.8541 | D37: ='Data IBS per Tahun'!F37 -> 0.47011442 | E37: ='Data IBS per Tahun'!O37 -> 1.0916159 | F37: ='Data IBS per Tahun'!X37 -> 5.3070037 | G37: ='Data IBS per Tahun'!AG37 -> 3.3554431 | H37: ='Data IBS per Tahun'!AP37 -> 3.8444344 | I37: ='Data IBS per Tahun'!AY37 -> 1.3072317 | J37: ='Data IBS per Tahun'!BH37 -> 0.76063299 | K37: ='Data IBS per Tahun'!I37 -> 1.388774 | L37: ='Data IBS per Tahun'!R37 -> 1.997758 | M37: ='Data IBS per Tahun'!AA37 -> 2.3793374 | N37: ='Data IBS per Tahun'!AJ37 -> 1.3154146 | O37: ='Data IBS per Tahun'!AS37 -> 1.7613692 | P37: ='Data IBS per Tahun'!BB37 -> 1.1833141 | Q37: ='Data IBS per Tahun'!BK37 -> 1.6420371 | R37: ='Data IBS per Tahun'!L37 -> 2.4224518 | S37: ='Data IBS per Tahun'!U37 -> 2.8913819 | T37: ='Data IBS per Tahun'!AD37 -> 2.4893289 | U37: ='Data IBS per Tahun'!AM37 -> 2.3944758 | V37: ='Data IBS per Tahun'!AV37 -> 2.0887252 | W37: ='Data IBS per Tahun'!BE37 -> 1.8133846 | X37: ='Data IBS per Tahun'!BN37 -> 1.7322497
A38: 17 | B38: Jambi | C38: ='Data IBS per Tahun'!C38 -> 71.364534 | D38: ='Data IBS per Tahun'!F38 -> 0.46810596 | E38: ='Data IBS per Tahun'!O38 -> 4.4745271 | F38: ='Data IBS per Tahun'!X38 -> 0.066281145 | G38: ='Data IBS per Tahun'!AG38 -> 0.066519508 | H38: ='Data IBS per Tahun'!AP38 -> 0.23526625 | I38: ='Data IBS per Tahun'!AY38 -> 1.0256564 | J38: ='Data IBS per Tahun'!BH38 -> 0.97251384 | K38: ='Data IBS per Tahun'!I38 -> 5.6438125 | L38: ='Data IBS per Tahun'!R38 -> 3.6249693 | M38: ='Data IBS per Tahun'!AA38 -> 9.0810614 | N38: ='Data IBS per Tahun'!AJ38 -> 3.2356237 | O38: ='Data IBS per Tahun'!AS38 -> 1.615057 | P38: ='Data IBS per Tahun'!BB38 -> 1.7562398 | Q38: ='Data IBS per Tahun'!BK38 -> 1.6218861 | R38: ='Data IBS per Tahun'!L38 -> 3.2442293 | S38: ='Data IBS per Tahun'!U38 -> 3.0626912 | T38: ='Data IBS per Tahun'!AD38 -> 5.2303399 | U38: ='Data IBS per Tahun'!AM38 -> 4.4170698 | V38: ='Data IBS per Tahun'!AV38 -> 4.0651347 | W38: ='Data IBS per Tahun'!BE38 -> 4.6143971 | X38: ='Data IBS per Tahun'!BN38 -> 5.0820267
A39: 16 | B39: Sumatera Selatan | C39: ='Data IBS per Tahun'!C39 -> 82.283256 | D39: ='Data IBS per Tahun'!F39 -> 0.98438138 | E39: ='Data IBS per Tahun'!O39 -> 0.91670591 | F39: ='Data IBS per Tahun'!X39 -> 13.531113 | G39: ='Data IBS per Tahun'!AG39 -> 9.3381953 | H39: ='Data IBS per Tahun'!AP39 -> 8.0163941 | I39: ='Data IBS per Tahun'!AY39 -> 21.10761 | J39: ='Data IBS per Tahun'!BH39 -> 5.9905761 | K39: ='Data IBS per Tahun'!I39 -> 4.4945637 | L39: ='Data IBS per Tahun'!R39 -> 6.0327129 | M39: ='Data IBS per Tahun'!AA39 -> 2.6835507 | N39: ='Data IBS per Tahun'!AJ39 -> 4.5004271 | O39: ='Data IBS per Tahun'!AS39 -> 5.2654355 | P39: ='Data IBS per Tahun'!BB39 -> 4.501143 | Q39: ='Data IBS per Tahun'!BK39 -> 6.0315825 | R39: ='Data IBS per Tahun'!L39 -> 8.139609 | S39: ='Data IBS per Tahun'!U39 -> 5.639923 | T39: ='Data IBS per Tahun'!AD39 -> 5.5190154 | U39: ='Data IBS per Tahun'!AM39 -> 5.6554831 | V39: ='Data IBS per Tahun'!AV39 -> 6.2131364 | W39: ='Data IBS per Tahun'!BE39 -> 6.059346 | X39: ='Data IBS per Tahun'!BN39 -> 6.4448753
A40: 17 | B40: Bengkulu | C40: ='Data IBS per Tahun'!C40 -> 86.892 | D40: ='Data IBS per Tahun'!F40 -> 0.0077126133 | E40: ='Data IBS per Tahun'!O40 -> 0.21943553 | F40: ='Data IBS per Tahun'!X40 -> 0.055701258 | G40: ='Data IBS per Tahun'!AG40 -> 0.4941638 | H40: ='Data IBS per Tahun'!AP40 -> 0.011206221 | I40: ='Data IBS per Tahun'!AY40 -> 0.014670293 | J40: ='Data IBS per Tahun'!BH40 -> 0.0046269137 | K40: ='Data IBS per Tahun'!I40 -> 1.8099967 | L40: ='Data IBS per Tahun'!R40 -> 1.4813897 | M40: ='Data IBS per Tahun'!AA40 -> 2.1785627 | N40: ='Data IBS per Tahun'!AJ40 -> 1.7469988 | O40: ='Data IBS per Tahun'!AS40 -> 1.2974416 | P40: ='Data IBS per Tahun'!BB40 -> 1.4274611 | Q40: ='Data IBS per Tahun'!BK40 -> 1.3979569 | R40: ='Data IBS per Tahun'!L40 -> 3.7773048 | S40: ='Data IBS per Tahun'!U40 -> 4.4400558 | T40: ='Data IBS per Tahun'!AD40 -> 3.6638732 | U40: ='Data IBS per Tahun'!AM40 -> 5.177268 | V40: ='Data IBS per Tahun'!AV40 -> 4.1512705 | W40: ='Data IBS per Tahun'!BE40 -> 3.0734201 | X40: ='Data IBS per Tahun'!BN40 -> 2.8383428
A41: 18 | B41: Lampung | C41: ='Data IBS per Tahun'!C41 -> 66.907639 | D41: ='Data IBS per Tahun'!F41 -> 13.29437 | E41: ='Data IBS per Tahun'!O41 -> 8.9576921 | F41: ='Data IBS per Tahun'!X41 -> 9.0841073 | G41: ='Data IBS per Tahun'!AG41 -> 11.332659 | H41: ='Data IBS per Tahun'!AP41 -> 16.6745 | I41: ='Data IBS per Tahun'!AY41 -> 6.4326442 | J41: ='Data IBS per Tahun'!BH41 -> 9.3969149 | K41: ='Data IBS per Tahun'!I41 -> 5.6245233 | L41: ='Data IBS per Tahun'!R41 -> 8.0669281 | M41: ='Data IBS per Tahun'!AA41 -> 6.4987331 | N41: ='Data IBS per Tahun'!AJ41 -> 2.0131575 | O41: ='Data IBS per Tahun'!AS41 -> 5.0594911 | P41: ='Data IBS per Tahun'!BB41 -> 2.0529966 | Q41: ='Data IBS per Tahun'!BK41 -> 3.7835383 | R41: ='Data IBS per Tahun'!L41 -> 5.9695598 | S41: ='Data IBS per Tahun'!U41 -> 5.9911926 | T41: ='Data IBS per Tahun'!AD41 -> 7.3260718 | U41: ='Data IBS per Tahun'!AM41 -> 7.2725682 | V41: ='Data IBS per Tahun'!AV41 -> 7.1616367 | W41: ='Data IBS per Tahun'!BE41 -> 4.6852055 | X41: ='Data IBS per Tahun'!BN41 -> 5.3641221
A42: 19 | B42: Bangka Belitung | C42: ='Data IBS per Tahun'!C42 -> 88.029707 | D42: ='Data IBS per Tahun'!F42 -> 0.39376654 | E42: ='Data IBS per Tahun'!O42 -> 0.26802744 | F42: ='Data IBS per Tahun'!X42 -> 1.183796 | G42: ='Data IBS per Tahun'!AG42 -> 0.59892423 | H42: ='Data IBS per Tahun'!AP42 -> 1.4427549 | I42: ='Data IBS per Tahun'!AY42 -> 0.40064984 | J42: ='Data IBS per Tahun'!BH42 -> 0.2130717 | K42: ='Data IBS per Tahun'!I42 -> 5.2130415 | L42: ='Data IBS per Tahun'!R42 -> 2.1119795 | M42: ='Data IBS per Tahun'!AA42 -> 2.7540223 | N42: ='Data IBS per Tahun'!AJ42 -> 1.8947255 | O42: ='Data IBS per Tahun'!AS42 -> 2.0351766 | P42: ='Data IBS per Tahun'!BB42 -> 1.9676743 | Q42: ='Data IBS per Tahun'!BK42 -> 1.6920474 | R42: ='Data IBS per Tahun'!L42 -> 4.2152207 | S42: ='Data IBS per Tahun'!U42 -> 8.354891 | T42: ='Data IBS per Tahun'!AD42 -> 4.7135712 | U42: ='Data IBS per Tahun'!AM42 -> 2.9513218 | V42: ='Data IBS per Tahun'!AV42 -> 3.2503557 | W42: ='Data IBS per Tahun'!BE42 -> 4.0147823 | X42: ='Data IBS per Tahun'!BN42 -> 3.8436936
A43: 21 | B43: Kepulauan Riau | C43: ='Data IBS per Tahun'!C43 -> 77.710719 | D43: ='Data IBS per Tahun'!F43 -> 38.265499 | E43: ='Data IBS per Tahun'!O43 -> 60.58307 | F43: ='Data IBS per Tahun'!X43 -> 67.879696 | G43: ='Data IBS per Tahun'!AG43 -> 49.23977 | H43: ='Data IBS per Tahun'!AP43 -> 61.543693 | I43: ='Data IBS per Tahun'!AY43 -> 49.970921 | J43: ='Data IBS per Tahun'!BH43 -> 52.639084 | K43: ='Data IBS per Tahun'!I43 -> 14.589796 | L43: ='Data IBS per Tahun'!R43 -> 8.8213263 | M43: ='Data IBS per Tahun'!AA43 -> 30.212966 | N43: ='Data IBS per Tahun'!AJ43 -> 5.8262503 | O43: ='Data IBS per Tahun'!AS43 -> 4.5814517 | P43: ='Data IBS per Tahun'!BB43 -> 5.9288808 | Q43: ='Data IBS per Tahun'!BK43 -> 10.280832 | R43: ='Data IBS per Tahun'!L43 -> 17.423993 | S43: ='Data IBS per Tahun'!U43 -> 32.34264 | T43: ='Data IBS per Tahun'!AD43 -> 41.025829 | U43: ='Data IBS per Tahun'!AM43 -> 21.151589 | V43: ='Data IBS per Tahun'!AV43 -> 20.853986 | W43: ='Data IBS per Tahun'!BE43 -> 26.572015 | X43: ='Data IBS per Tahun'!BN43 -> 16.57621
