Workbook

Sheet Kebutuhan Data
A1: Sumber Data | B1: Indikator | C1: Granularitas | D1: Level Data | E1: Literature Review | F1: Arah korelasi terhadap PHK | G1: R-squared
A2: Data Ketenagakerjaan
A3: Sakernas | B3: Jumlah penduduk bekerja | C3: Triwulanan | D3: Provinsi | F3: + | G3: 0.44
B4: % TPT | C4: Triwulanan | D4: Provinsi | F4: + | G4: 0.15
B5: % TPT Laki-laki | C5: Triwulanan | D5: Provinsi | F5: + | G5: 0.2
B6: % TPT Perempuan | C6: Triwulanan | D6: Provinsi | F6: + | G6: 0.04
B7: % TPAK | C7: Triwulanan | D7: Provinsi | F7: - | G7: 0.02
B8: % TPAK Laki-laki | C8: Triwulanan | D8: Provinsi | F8: - | G8: 0
B9: % TPAK Perempuan | C9: Triwulanan | D9: Provinsi | F9: - | G9: 0.02
B10: % Pekerja Formal | C10: Triwulanan | D10: Provinsi | E10: Sebagai proxy PHK -- tenaga kerja formal menurun. "Implikasi adanya potensi tambahan jumlah PHK ini adalah naiknya jumlah angkatan kerja yang menganggur dan/atau naiknya tenaga kerja di sektor informal, yang per Februari 2026 sudah mencapai 87,74 juta jiwa, atau kurang lebih 59,42 persen dari total tenaga kerja aktif di Indonesia." Bu vivi: agak banyak efek lainnya | F10: + | G10: 0.09
B11: Berusaha Sendiri | C11: Triwulanan | D11: Provinsi | F11: + | G11: 0.46
B12: Buruh/karyawan/pegawai | C12: Triwulanan | D12: Provinsi | F12: + | G12: 0.53
B13: Pekerja Keluarga Tidak Dibayar | C13: Triwulanan | D13: Provinsi | F13: + | G13: 0.27
B14: % Setengah pengangguran | C14: Triwulanan | D14: Provinsi | F14: - | G14: 0.05
B15: Penduduk Bekerja Setengah Penganggur | C15: Triwulanan | D15: Provinsi | F15: + | G15: 0.42
B16: Jam Kerja | C16: Triwulanan | D16: Provinsi | E16: Sebagai proxy "PHK" -- perusahaan yang tertekan biaya produksi diperkirakan akan menempuh langkah seperti tidak memperpanjang kontrak PKWT, memotong jam kerja, atau menahan rekruitmen pengganti karyawan yang mengundurkan diri. Saluran-saluran non-PHK tersebut tidak masuk pelaporan PHK formal di Kemenaker. | F16: + | G16: 0.11
B17: UMP (IDR th) | C17: Triwulanan | D17: Provinsi | F17: - | G17: 0.01
B18: Growth UMP | C18: Triwulanan | D18: Provinsi | F18: + | G18: 0.01
B19: Upah buruh/karyawan/pegawai (IDR) | C19: Triwulanan | D19: Provinsi | F19: + | G19: 0.11
B20: Kaitz Index | C20: Triwulanan | D20: Provinsi | F20: - | G20: 0.21
B21: Proporsi Lapangan Kerja Informal Sektor Non-Pertanian | C21: Triwulanan | D21: Provinsi | F21: - | G21: 0.02
B22: Proporsi Lapangan Kerja Informal | C22: Triwulanan | D22: Provinsi | F22: - | G22: 0.07
B23: Pencari Kerja Terdaftar - Jumlah | D23: Provinsi | F23: + | G23: 0.5
B24: Lowongan Kerja Terdaftar - Jumlah | D24: Provinsi | F24: + | G24: 0.45
B25: Penempatan/Pemenuhan Tenaga Kerja - Jumlah | D25: Provinsi | F25: + | G25: 0.58
A26: BPJS Ketenagakerjaan | B26: BPJSTK - Peserta Aktif PU | C26: Bulanan | D26: Provinsi | F26: + | G26: 0.57
B27: BPJSTK - Peserta Aktif BPU | C27: Bulanan | D27: Provinsi | F27: + | G27: 0.59
B28: BPJSTK - PHK | C28: Bulanan | D28: Provinsi | F28: + | G28: 0.61
B29: BPJSTK - JHT PHK | C29: Bulanan | D29: Provinsi | F29: + | G29: 0.17
B30: BPJSTK - JKP PHK | C30: Bulanan | D30: Provinsi | F30: + | G30: 0.81
A31: Satudata Kemnaker | B31: PHK | C31: Bulanan | D31: Provinsi
A32: Data Makroekonomi
A33: CEIC | B33: PDRB | C33: Triwulanan | E33: PDRB ↑ → output & permintaan tenaga kerja ↑ → PHK ↓
B34: PDRB per sektor | C34: Triwulanan | E34: Output sektor ↑ → kebutuhan tenaga kerja ↑ → PHK ↓
B35: FDI | C35: Triwulanan | E35: FDI ↑ → investasi & ekspansi usaha ↑ → tenaga kerja ↑ → PHK ↓
B36: Manufacturing share (%) | C36: Triwulanan | E36: Manufacturing share ↑ → peran sektor manufaktur dalam ekonomi ↑ → aktivitas produksi & penyerapan tenaga kerja ↑ → PHK ↓
B37: GDP per worker | E37: ILO - Economic factor for wage setting
A38: BPS | B38: Inflasi | C38: Bulanan | E38: Inflasi ↑ → daya beli/profit turun → PHK ↑
B39: ICOR | C39: Tahunan | E39: ICOR ↑ → efisiensi investasi ↓ → pertumbuhan melambat → PHK ↑
B40: Export value
...

Sheet Kesimpulan Awal
A1: 1. PHK terutama terlihat sebagai fenomena pasar kerja formal
A2: Indikator | B2: Arah korelasi | C2: R-squared | D2: Kesimpulan awal
A3: Jumlah penduduk bekerja | B3: + | C3: 0.44 | D3: PHK tercatat cenderung lebih terkonsentrasi pada wilayah dengan struktur pasar kerja yang relatif formal dan basis pekerja penerima upah yang lebih besar.
A4: Buruh/karyawan/pegawai | B4: + | C4: 0.53
A5: % Pekerja Formal | B5: + | C5: 0.09
A6: Proporsi Lapangan Kerja Informal Sektor Non-Pertanian | B6: - | C6: 0.02
A7: Proporsi Lapangan Kerja Informal | B7: - | C7: 0.07
A30: 2. PHK mengikuti skala industri
A31: Indikator | B31: Arah korelasi | C31: R-squared | D31: Kesimpulan awal
A32: Jumlah perusahaan industri sedang dan besar | B32: + | C32: 0.53–0.65 | D32: PHK saat ini tercatat banyak muncul di wilayah dengan ekosistem industri yang besar: Lebih banyak perusahaan industri → lebih banyak pekerja industri → lebih besar exposure terhadap shock usaha → jumlah PHK tercatat lebih tinggi
A33: Tenaga kerja industri sedang dan besar | B33: + | C33: 0.54-0.65
A34: Pengeluaran untuk pekerja | B34: + | C34: 0.63
A35: Biaya input | B35: + | C35: 0.55
A36: Nilai output | B36: + | C36: 0.59
A37: Nilai tambah | B37: + | C37: 0.62
A38: Jumlah perusahaan PMDN | B38: + | C38: 0.47
A39: Jumlah perusahaan PMA | B39: + | C39: 0.64
A73: 3. Tekanan pasar kerja
A74: Indikator | B74: Arah korelasi | C74: R-squared | D74: Kesimpulan awal
A75: % Pekerja Formal | B75: + | C75: 0.09 | D75: Tekanan pasar kerja tidak selalu muncul dalam bentuk kehilangan pekerjaan secara eksplisit. Di wilayah dengan pasar kerja formal, tekanan lebih mudah terlihat sebagai PHK. Di wilayah dengan pasar kerja informal, penyesuaian dapat terjadi tanpa pekerja sepenuhnya keluar dari pekerjaan.
A76: Proporsi Lapangan Kerja Informal | B76: - | C76: 0.07
A77: Penduduk Bekerja Setengah Penganggur | B77: + | C77: 0.42
A78: % Setengah Pengangguran | B78: - | C78: 0.05
A79: TPT | B79: + | C79: 0.15
A80: TPT Laki-laki | B80: + | C80: 0.2
A99: 4. Pencari kerja, lowongan kerja, dll
A100: Indikator | B100: Arah korelasi | C100: R-squared | D100: Kesimpulan awal
A101: Pencari Kerja Terdaftar - Jumlah | B101: + | C101: 0.5 | D101: Angka PHK tinggi → lebih banyak orang mencari pekerjaan baru → jumlah pencari kerja terdaftar meningkat
A102: Lowongan Kerja Terdaftar - Jumlah | B102: + | C102: 0.45
A103: Penempatan/Pemenuhan Tenaga Kerja - Jumlah | B103: + | C103: 0.58
A122: 5. Data BPJS sebagai alternatif indikator PHK
A123: Indikator | B123: Arah korelasi | C123: R-squared
A124: BPJSTK - Peserta Aktif PU | B124: + | C124: 0.57
A125: BPJSTK - Peserta Aktif BPU | B125: + | C125: 0.59
A126: BPJSTK - PHK | B126: + | C126: 0.61
A127: BPJSTK - JHT PHK | B127: + | C127: 0.17
A128: BPJSTK - JKP PHK | B128: + | C128: 0.81

Sheet Database (Tahun)
A1: Provinsi | B1: Tahun | C1: PHK | D1: % Pekerja Formal | E1: % Pekerja Formal (2019) | F1: % Pekerja Formal (Growth from 2019, pp) | G1: Jumlah Pekerja Memiliki Kontrak Tertulis | H1: Jumlah Pekerja Formal | I1: % Pekerja Memiliki Kontrak Tertulis | J1: % Pekerja Memiliki Kontrak Tertulis (2019) | K1: % Pekerja Memiliki Kontrak Tertulis (Growth from 2019, pp) | L1: Jumlah Penduduk Bekerja | M1: % TPT | N1: % TPT Laki-laki | O1: % TPT Perempuan | P1: % TPAK | Q1: % TPAK Laki-laki | R1: % TPAK Perempuan | S1: Berusaha Sendiri | T1: Buruh/karyawan/pegawai | U1: Pekerja Keluarga Tidak Dibayar | V1: Penduduk Bekerja Setengah Penganggur | W1: % Pekerja Penuh Waktu | X1: % Pekerja Paruh Waktu | Y1: % Setengah Pengangguran | Z1: Tenaga Kerja - Pertanian, Kehutanan dan Perikanan | AA1: Tenaga Kerja - Pertambangan dan Penggalian | AB1: Tenaga Kerja - Industri Pengolahan | AC1: Tenaga Kerja - Pengadaan Listrik dan Gas | AD1: Tenaga Kerja - Pengadaan Air, Pengelolaan Sampah, Limbah dan Daur Ulang | AE1: Tenaga Kerja - Konstruksi | AF1: Tenaga Kerja - Perdagangan Besar dan Eceran, Reparasi Mobil dan Sepeda Motor | AG1: Tenaga Kerja - Transportasi dan Pergudangan | AH1: Tenaga Kerja - Penyediaan Akomodasi dan Makan Minum | AI1: Tenaga Kerja - Informasi dan Komunikasi | AJ1: Tenaga Kerja - Jasa Keuangan dan Asuransi | AK1: Tenaga Kerja - Real Estate | AL1: Tenaga Kerja - Jasa Perusahaan | AM1: Tenaga Kerja - Administrasi Pemerintahan, Pertahanan dan Jaminan Sosial Wajib | AN1: Tenaga Kerja - Jasa Pendidikan | AO1: Tenaga Kerja - Jasa Kesehatan dan Kegiatan Sosial | AP1: Tenaga Kerja - Jasa Lainnya | AQ1: % Share Tenaga Kerja - Pertanian, Kehutanan dan Perikanan | AR1: % Share Tenaga Kerja - Pertambangan dan Penggalian | AS1: % Share Tenaga Kerja - Industri Pengolahan | AT1: % Share Tenaga Kerja - Pengadaan Listrik dan Gas | AU1: % Share Tenaga Kerja - Pengadaan Air, Pengelolaan Sampah, Limbah dan Daur Ulang | AV1: % Share Tenaga Kerja - Konstruksi | AW1: % Share Tenaga Kerja - Perdagangan Besar dan Eceran, Reparasi Mobil dan Sepeda Motor | AX1: % Share Tenaga Kerja - Transportasi dan Pergudangan | AY1: % Share Tenaga Kerja - Penyediaan Akomodasi dan Makan Minum | AZ1: % Share Tenaga Kerja - Informasi dan Komunikasi | BA1: % Share Tenaga Kerja - Jasa Keuangan dan Asuransi | BB1: % Share Tenaga Kerja - Real Estate | BC1: % Share Tenaga Kerja - Jasa Perusahaan | BD1: % Share Tenaga Kerja - Administrasi Pemerintahan, Pertahanan dan Jaminan Sosial Wajib | BE1: % Share Tenaga Kerja - Jasa Pendidikan | BF1: % Share Tenaga Kerja - Jasa Kesehatan dan Kegiatan Sosial | BG1: % Share Tenaga Kerja - Jasa Lainnya | BH1: Jam Kerja | BI1: UMP (IDR) | BJ1: Growth UMP | BK1: Upah buruh/karyawan/pegawai (IDR) | BL1: Kaitz Index | BM1: Proporsi Lapangan Kerja Informal Sektor Non-Pertanian | BN1: Proporsi Lapangan Kerja Informal | BO1: Pencari Kerja Terdaftar - Jumlah | BP1: Lowongan Kerja Terdaftar - Jumlah | BQ1: Penempatan/Pemenuhan Tenaga Kerja - Jumlah | BR1: BPJSTK - Peserta Aktif PU | BS1: BPJSTK - Peserta Aktif BPU | BT1: BPJSTK - PHK | BU1: BPJSTK - JHT PHK | BV1: BPJSTK - JKP PHK | BW1: Pertumbuhan Bekerja | BX1: Pertumbuhan Buruh/Karyawan/Pegawai | BY1: Pertumbuhan Pekerja Keluarga Tidak Dibayar | BZ1: Pertumbuhan % Pekerja Formal | CA1: Pertumbuhan % Pekerja Memiliki Kontrak Tertulis | CB1: Pertumbuhan % Pekerja Penuh Waktu | CC1: Pertumbuhan % Pekerja Paruh Waktu | CD1: Pertumbuhan % Setengah Pengangguran | CE1: Pertumbuhan Jam Kerja | CF1: Pertumbuhan TPT | CG1: Pertumbuhan TPT Laki-laki | CH1: Pertumbuhan TPT Perempuan | CI1: Pertumbuhan TPAK | CJ1: Pertumbuhan TPAK Laki-laki | CK1: Pertumbuhan TPAK Perempuan | CL1: Pertumbuhan Upah | CM1: Pertumbuhan BPJSTK - Peserta Aktif PU | CN1: Pertumbuhan BPJSTK - Peserta Aktif BPU | CO1: Pertumbuhan BPJSTK - PHK | CP1: Pertumbuhan BPJSTK - JHT PHK | CQ1: Pertumbuhan BPJSTK - JKP PHK | CR1: Lag_1 PHK | CS1: Lag_1 % Pekerja Formal | CT1: Lag_1 % Pekerja Memiliki Kontrak Tertulis | CU1: Lag_1 Growth UMP | CV1: Lag_1 BPJSTK - Peserta Aktif PU | CW1: Lag_1 BPJSTK - Peserta Aktif BPU | CX1: Lag_1 BPJSTK - PHK | CY1: Lag_1 BPJSTK - JHT PHK | CZ1: Lag_1 BPJSTK - JKP PHK | DA1: Perusahaan Industri Sedang | DB1: Perusahaan Industri Besar | DC1: Jumlah Perusahaan | DD1: Tenaga Kerja Industri Sedang | DE1: Tenaga Kerja Industri Besar | DF1: Jumlah Tenaga Kerja Produksi | DG1: Jumlah Tenaga Kerja Lainnya | DH1: Jumlah Tenaga Kerja | DI1: Pengeluaran untuk Pekerja Produksi Upah/Gaji, Upah Lembur, Tunjangan | DJ1: Pengeluaran untuk Pekerja Produksi Lainnya | DK1: Jumlah Pengeluaran untuk Pekerja Produksi | DL1: Pengeluaran untuk Pekerja Lainnya Upah/Gaji, Upah Lembur, Tunjangan | DM1: Pengeluaran untuk Pekerja Lainnya Lainnya | DN1: Jumlah Pengeluaran untuk Pekerja Lainnya | DO1: Jumlah Pengeluaran Seluruh Pekerja | DP1: Biaya Input | DQ1: Nilai Output | DR1: Nilai Tambah (harga pasar) | DS1: Nilai Tambah (biaya faktor produksi) | DT1: Jumlah Perusahaan PMDN | DU1: Jumlah Perusahaan PMA | DV1: Jumlah Tenaga Kerja/Jumlah Perusahaan | DW1: Jumlah Tenaga Kerja Produksi/Jumlah Tenaga Kerja | DX1: Jumlah Tenaga Kerja/Biaya Input | DY1: Jumlah Tenaga Kerja/Nilai Output | DZ1: Jumlah Tenaga Kerja/Nilai Tambah (harga pasar) | EA1: Jumlah Tenaga Kerja/Nilai Tambah (biaya faktor produksi) | EB1: Biaya Pekerja/Biaya Input | EC1: Biaya Pekerja/Nilai Output | ED1: Biaya Pekerja/Nilai Tambah Pasar | EE1: Biaya Pekerja/Nilai Tambah Produksi | EF1: Biaya Pekerja/Tenaga Kerja | EG1: Nilai Output/Tenaga Kerja | EH1: Nilai Tambah Pasar/Tenaga Kerja | EI1: Nilai Tambah Produksi/Tenaga Kerja | EJ1: Biaya Input/Nilai Output | EK1: Nilai Tambah Pasar/Nilai Output | EL1: Nilai Tambah Produksi/Nilai Output | EM1: Biaya Pekerja Produksi/Total Biaya Pekerja | EN1: Biaya Pekerja Lainnya/Total Biaya Pekerja | EO1: Upah Pekerja Produksi/Jumlah Tenaga Kerja Produksi | EP1: Upah Pekerja Lainnya/Jumlah Tenaga Kerja Lainnya | EQ1: Proporsi Perusahaan PMDN | ER1: Proporsi Perusahaan PMA | ES1: Pertumbuhan Nilai Output | ET1: Pertumbuhan Biaya Input | EU1: Pertumbuhan Nilai Tambah Pasar | EV1: Pertumbuhan Nilai Tambah Produksi | EW1: Pertumbuhan Tenaga Kerja | EX1: Pertumbuhan Jumlah Perusahaan | EY1: Pertumbuhan Pengeluaran Tenaga Kerja | EZ1: Pertumbuhan Produktivitas (Nilai Tambah Pasar) Tenaga Kerja | FA1: Pertumbuhan Produktivitas (Nilai Tambah Produksi) Tenaga Kerja | FB1: Selisih Pertumbuhan Biaya Input dan Pertumbuhan Nilai Output | FC1: Selisih Pertumbuhan Biaya Pekerja dan Nilai Output | FD1: PDRB Riil (IDR miliar) | FE1: PDRB Riil (IDR juta) | FF1: PDRB Manufaktur (IDR juta) | FG1: Manufacturing Share | FH1: Laju Pertumbuhan PDB Industri Manufaktur | FI1: PMI Manufaktur | FJ1: FDI | FK1: PDRB/Pekerja | FL1: Laju Pertumbuhan PDB Per Tenaga Kerja | FM1: ICOR | FN1: Inflasi YoY (per IV) | FO1: Inflasi YoY (Average) | FP1: IHP (2016=100) | FQ1: IHK (2010=100) | FR1: Perubahan harga produsen (%) | FS1: Perubahan harga konsumen (%) | FT1: Nilai Ekspor BPS | FU1: Nilai Ekspor | FV1: Nilai Impor | FW1: Neraca Perdagangan | FX1: NPL | FY1: BI Rate (Average)* | FZ1: Kurs | GA1: IKK
A2: Aceh | B2: 2022 | C2: 84 | D2: 38.55 | E2: 0.25703192 | F2: =D2-E2 -> 38.292968 | G2: 396068 | H2: =D2*L2/100 -> 923270.19 | I2: 0.46985719 | J2: 0.49237172 | K2: =I2-J2 -> -0.022514528 | L2: 2394994 | M2: 6.17 | N2: 5.68 | O2: 7.02 | P2: 63.5 | Q2: 81.06 | R2: 46.15 | S2: 604272 | T2: 842954 | U2: 300164 | V2: 250455 | W2: =100-X2-Y2 -> 61.5 | X2: 28.04 | Y2: 10.46 | Z2: 969992 | AA2: 21670 | AB2: 175231 | AC2: 5769 | AD2: 3586 | AE2: 158823 | AF2: 320127 | AG2: 75172 | AH2: 118304 | AI2: 9444 | AJ2: 10724 | AK2: 870 | AL2: 26719 | AM2: 159044 | AN2: 176663 | AO2: 66276 | AP2: 96580 | AQ2: =Z2/sum($Z2:$AP2) -> 0.40500811 | AR2: =AA2/sum($Z2:$AP2) -> 0.0090480394 | AS2: =AB2/sum($Z2:$AP2) -> 0.073165528 | AT2: =AC2/sum($Z2:$AP2) -> 0.0024087743 | AU2: =AD2/sum($Z2:$AP2) -> 0.0014972898 | AV2: =AE2/sum($Z2:$AP2) -> 0.066314571 | AW2: =AF2/sum($Z2:$AP2) -> 0.13366505 | AX2: =AG2/sum($Z2:$AP2) -> 0.031387135 | ... BG2: =AP2/sum($Z2:$AP2) -> 0.04032578 | BH2: 38 | BI2: 3166.46 | BJ2: 0.045149637 | BK2: 2327990 | BL2: =BI2*1000/BK2 -> 1.3601691 | BM2: 44.13 | BN2: 61.45 | BO2: 11600 | BP2: 1553 | BQ2: 1549 | BR2: 315935 | BS2: 56888 | BT2: 1448 | BU2: 3939 | DA2: 57 | DB2: 30 | DC2: 87 | DD2: 1849 | DE2: 8755 | DF2: 7168 | DG2: 3436 | DH2: 10604 | DI2: 397366109 | DJ2: 34909199 | DK2: 432275308 | DL2: 193818007 | DM2: 11138177 | DN2: 204956184 | DO2: 637231492 | DP2: 10652661077 | DQ2: 21273885572 | DR2: =DQ2-DP2 -> 10621224495 | DS2: 10379820664 | DT2: 81 | DU2: 6 | DV2: =DH2/DC2 -> 121.88506 | DW2: =DF2/DH2 -> 0.67597133 | DX2: =DH2/DP2 -> 9.9543203e-07 | DY2: =DH2/DQ2 -> 4.9845149e-07 | DZ2: =DH2/DR2 -> 9.9837829e-07 | EA2: =DH2/DS2 -> 1.0215976e-06 | EB2: =DO2/DP2 -> 0.059818996 | EC2: =DO2/DQ2 -> 0.029953696 | ED2: =DO2/DR2 -> 0.059996048 | EE2: =DO2/DS2 -> 0.061391378 | EF2: =DO2/DH2 -> 60093.502 | EG2: =DQ2/DH2 -> 2006213.3 | EH2: =DR2/DH2 -> 1001624.3 | EI2: =DS2/DH2 -> 978858.98 | EJ2: =DP2/DQ2 -> 0.50073885 | EK2: =DR2/DQ2 -> 0.49926115 | EL2: =DS2/DQ2 -> 0.48791372 | EM2: =DK2/DO2 -> 0.67836463 | EN2: =DN2/DO2 -> 0.32163537 | EO2: =DI2/DF2 -> 55436.12 | EP2: =DL2/DG2 -> 56408.035 | EQ2: =DT2/DC2 -> 0.93103448 | ER2: =DU2/DC2 -> 0.068965517 | FD2: 140971.7 | FE2: 140971700 | FF2: 6472363.2 | FG2: =(FF2/FE2)*100 -> 4.59125 | FH2: 4.19 | FI2: 51.8 | FJ2: 127.6 | FK2: =FD2/L2 -> 0.058860983 | FL2: 2.75 | FM2: 6.02 | FN2: 5.94 | FO2: 4.48 | FP2: 130.8 | FQ2: 163.1 | FR2: 10 | FS2: 4.2 | FT2: 745.8 | FU2: 692.5 | FV2: 167.3 | FW2: =FU2-FV2 -> 525.2 | FX2: 605.4 | FY2: 4 | FZ2: 14875.93 | GA2: 119.9
A3: Sumatera Utara | B3: 2022 | C3: 70 | D3: 40.93 | E3: 0.29822611 | F3: =D3-E3 -> 40.631774 | G3: 1158119 | H3: =D3*L3/100 -> 2945885.2 | I3: 0.43182733 | J3: 0.40538524 | K3: =I3-J3 -> 0.026442083 | L3: 7197374 | M3: 6.16 | N3: 5.9 | O3: 6.55 | P3: 69.53 | Q3: 83.89 | R3: 55.37 | S3: 1442845 | T3: 2681903 | U3: 1119422 | V3: 491786 | W3: =100-X3-Y3 -> 68.93 | X3: 24.24 | Y3: 6.83 | Z3: 2493755 | AA3: 32908 | AB3: 720482 | AC3: 16080 | AD3: 18074 | AE3: 435285 | AF3: 1304741 | AG3: 316982 | AH3: 542897 | AI3: 42634 | AJ3: 57805 | AK3: 14570 | AL3: 90623 | AM3: 312989 | AN3: 366511 | AO3: 107116 | AP3: 323922 | AQ3: =Z3/sum(Z3:AP3) -> 0.34648123 | AR3: =AA3/sum($Z3:$AP3) -> 0.0045722231 | AS3: =AB3/sum($Z3:$AP3) -> 0.10010345 | AT3: =AC3/sum($Z3:$AP3) -> 0.0022341482 | AU3: =AD3/sum($Z3:$AP3) -> 0.0025111937 | AV3: =AE3/sum($Z3:$AP3) -> 0.060478308 | AW3: =AF3/sum($Z3:$AP3) -> 0.18128014 | AX3: =AG3/sum($Z3:$AP3) -> 0.044041341 | AY3: =AH3/sum($Z3:$AP3) -> 0.075429872 | ... BG3: =AP3/sum($Z3:$AP3) -> 0.045005581 | BH3: 42 | BI3: 2522.6099 | BJ3: 0.92769171 | BK3: 2576442 | BL3: =BI3*1000/BK3 -> 0.97910605 | BM3: 46.45 | BN3: 59.07 | BO3: 27722 | BP3: 1526 | BQ3: 1368 | BR3: 1201977 | BS3: 282555 | BT3: 10740 | BU3: 25807 | DA3: 832 | DB3: 432 | DC3: 1264 | DD3: 32479 | DE3: 138586 | DF3: 137378 | DG3: 33767 | DH3: 171145 | DI3: 6546111198 | DJ3: 439161312 | DK3: 6985272510 | DL3: 2301046792 | DM3: 153495166 | DN3: 2454541958 | DO3: 9439814468 | DP3: 196870314607 | DQ3: 288425631608 | DR3: =DQ3-DP3 -> 91555317001 | DS3: 89561384425 | DT3: 1178 | DU3: 86 | DV3: =DH3/DC3 -> 135.39953 | DW3: =DF3/DH3 -> 0.80269947 | DX3: =DH3/DP3 -> 8.6932863e-07 | DY3: =DH3/DQ3 -> 5.9337653e-07 | DZ3: =DH3/DR3 -> 1.8693071e-06 | EA3: =DH3/DS3 -> 1.910924e-06 | EB3: =DO3/DP3 -> 0.047949405 | EC3: =DO3/DQ3 -> 0.032728764 | ED3: =DO3/DR3 -> 0.10310504 | EE3: =DO3/DS3 -> 0.1054005 | EF3: =DO3/DH3 -> 55156.823 | EG3: =DQ3/DH3 -> 1685270.6 | EH3: =DR3/DH3 -> 534957.59 | EI3: =DS3/DH3 -> 523307.05 | EJ3: =DP3/DQ3 -> 0.68256872 | EK3: =DR3/DQ3 -> 0.31743128 | EL3: =DS3/DQ3 -> 0.31051812 | EM3: =DK3/DO3 -> 0.73997985 | EN3: =DN3/DO3 -> 0.26002015 | EO3: =DI3/DF3 -> 47650.36 | EP3: =DL3/DG3 -> 68144.839 | EQ3: =DT3/DC3 -> 0.93196203 | ER3: =DU3/DC3 -> 0.068037975 | FD3: 573528.8 | FE3: 573528800 | FF3: 99869074 | FG3: =(FF3/FE3)*100 -> 17.413088 | FH3: 1.98 | FI3: 51.8 | FJ3: 1316.1 | FK3: =FD3/L3 -> 0.079685841 | FL3: 2.37 | FM3: 6.02 | FN3: 6.12 | FO3: 4.84 | FP3: 130.8 | FQ3: 163.1 | FR3: 10 | FS3: 4.2 | FT3: 12717 | FU3: 12108.9 | FV3: 6837.5 | FW3: =FU3-FV3 -> 5271.4 | FX3: 5638.3 | FY3: 4 | FZ3: 14875.93 | GA3: 119.9
A4: Sumatera Barat | B4: 2022 | C4: 35 | D4: 34.74 | E4: 0.23942157 | F4: =D4-E4 -> 34.500578 | G4: 429172 | H4: =D4*L4/100 -> 933868.17 | I4: 0.51049242 | J4: 0.46317085 | K4: =I4-J4 -> 0.047321577 | L4: 2688164 | M4: 6.28 | N4: 6.2 | O4: 6.39 | P4: 69.3 | Q4: 82.58 | R4: 56.28 | S4: 653862 | T4: 840702 | U4: 387302 | V4: 233244 | W4: =100-X4-Y4 -> 65.74 | X4: 25.58 | Y4: 8.68 | Z4: 939746 | AA4: 38347 | AB4: 230775 | AC4: 7828 | AD4: 4751 | AE4: 117992 | AF4: 543335 | AG4: 89098 | AH4: 212594 | AI4: 18413 | AJ4: 23335 | AK4: 1388 | AL4: 32739 | AM4: 122595 | AN4: 169700 | AO4: 55036 | AP4: 80492 | AQ4: =Z4/sum(Z4:AP4) -> 0.34958656 | AR4: =AA4/sum($Z4:$AP4) -> 0.014265127 | AS4: =AB4/sum($Z4:$AP4) -> 0.085848557 | AT4: =AC4/sum($Z4:$AP4) -> 0.0029120247 | AU4: =AD4/sum($Z4:$AP4) -> 0.0017673773 | AV4: =AE4/sum($Z4:$AP4) -> 0.043893155 | AW4: =AF4/sum($Z4:$AP4) -> 0.20212122 | AX4: =AG4/sum($Z4:$AP4) -> 0.033144555 | AY4: =AH4/sum($Z4:$AP4) -> 0.079085205 | ... BG4: =AP4/sum($Z4:$AP4) -> 0.029943114 | BH4: 39 | BI4: 2512.539 | BJ4: 1.1472435 | BK4: 2655767 | BL4: =BI4*1000/BK4 -> 0.94606906 | BM4: 52.38 | BN4: 65.26 | BO4: 20304 | BP4: 1907 | BQ4: 1725 | BR4: 373923 | BS4: 111406 | BT4: 2681 | BU4: 7889 | DA4: 136 | DB4: 60 | DC4: 196 | DD4: 4139 | DE4: 12644 | DF4: 13030 | DG4: 3753 | DH4: 16783 | DI4: 586601645 | DJ4: 34221055 | DK4: 620822700 | DL4: 199240416 | DM4: 19188839 | DN4: 218429255 | DO4: 839251955 | DP4: 40419965393 | DQ4: 64948317682 | DR4: =DQ4-DP4 -> 24528352289 | DS4: 24215698280 | DT4: 179 | DU4: 17 | DV4: =DH4/DC4 -> 85.627551 | DW4: =DF4/DH4 -> 0.77638086 | DX4: =DH4/DP4 -> 4.152156e-07 | DY4: =DH4/DQ4 -> 2.5840546e-07 | DZ4: =DH4/DR4 -> 6.8422859e-07 | EA4: =DH4/DS4 -> 6.9306281e-07 | EB4: =DO4/DP4 -> 0.020763302 | EC4: =DO4/DQ4 -> 0.012921843 | ED4: =DO4/DR4 -> 0.034215586 | EE4: =DO4/DS4 -> 0.034657351 | EF4: =DO4/DH4 -> 50006.075 | EG4: =DQ4/DH4 -> 3869887.2 | EH4: =DR4/DH4 -> 1461499.9 | EI4: =DS4/DH4 -> 1442870.7 | EJ4: =DP4/DQ4 -> 0.62234045 | EK4: =DR4/DQ4 -> 0.37765955 | EL4: =DS4/DQ4 -> 0.37284566 | EM4: =DK4/DO4 -> 0.7397334 | EN4: =DN4/DO4 -> 0.2602666 | EO4: =DI4/DF4 -> 45019.313 | EP4: =DL4/DG4 -> 53088.307 | EQ4: =DT4/DC4 -> 0.91326531 | ER4: =DU4/DC4 -> 0.086734694 | FD4: 182628.3 | FE4: 182628300 | FF4: 16918566 | FG4: =(FF4/FE4)*100 -> 9.2639346 | FH4: 1.75 | FI4: 51.8 | FJ4: 95.6 | FK4: =FD4/L4 -> 0.067937931 | FL4: 0.22 | FM4: 6.02 | FN4: 5.88 | FO4: 4.55 | FP4: 130.8 | FQ4: 163.1 | FR4: 10 | FS4: 4.2 | FT4: 2868.4 | FU4: 2617.8 | FV4: 710.3 | FW4: =FU4-FV4 -> 1907.5 | FX4: 1147 | FY4: 4 | FZ4: 14875.93 | GA4: 119.9
A5: Riau | B5: 2022 | C5: 916 | D5: 45.98 | E5: 0.29519579 | F5: =D5-E5 -> 45.684804 | G5: 649948 | H5: =D5*L5/100 -> 1457073.6 | I5: 0.50870224 | J5: 0.50865168 | K5: =I5-J5 -> 5.0563141e-05 | L5: 3168929 | M5: 4.37 | N5: 3.72 | O5: 5.68 | P5: 63.86 | Q5: 83.59 | R5: 43.28 | S5: 694008 | T5: 1277659 | U5: 334746 | V5: 235115 | W5: =100-X5-Y5 -> 63.61 | X5: 28.97 | Y5: 7.42 | Z5: 1266219 | AA5: 34966 | AB5: 230084 | AC5: 6679 | AD5: 18642 | AE5: 164959 | AF5: 568587 | AG5: 93309 | AH5: 179718 | AI5: 18560 | AJ5: 30956 | AK5: 9593 | AL5: 58862 | AM5: 130044 | AN5: 191647 | AO5: 54396 | AP5: 111708 | AQ5: =Z5/sum(Z5:AP5) -> 0.39957317 | AR5: =AA5/sum($Z5:$AP5) -> 0.011034012 | AS5: =AB5/sum($Z5:$AP5) -> 0.072606234 | AT5: =AC5/sum($Z5:$AP5) -> 0.0021076521 | AU5: =AD5/sum($Z5:$AP5) -> 0.0058827446 | AV5: =AE5/sum($Z5:$AP5) -> 0.052055127 | AW5: =AF5/sum($Z5:$AP5) -> 0.1794256 | AX5: =AG5/sum($Z5:$AP5) -> 0.029444964 | AY5: =AH5/sum($Z5:$AP5) -> 0.056712536 | ... BG5: =AP5/sum($Z5:$AP5) -> 0.035251026 | BH5: 40 | BI5: 2938.564 | BJ5: 1.7309639 | BK5: 2889691 | BL5: =BI5*1000/BK5 -> 1.0169129 | BM5: 44.3 | BN5: 54.02 | BO5: 16477 | BP5: 555 | BQ5: 420 | BR5: 593002 | BS5: 173909 | BT5: 4751 | BU5: 10388 | DA5: 150 | DB5: 236 | DC5: 386 | DD5: 7827 | DE5: 74441 | DF5: 63748 | DG5: 18520 | DH5: 82268 | DI5: 4266561754 | DJ5: 554351386 | DK5: 4820913140 | DL5: 1557667859 | DM5: 336737446 | DN5: 1894405305 | DO5: 6715318445 | DP5: 413662869319 | DQ5: 591999174685 | DR5: =DQ5-DP5 -> 178336305366 | DS5: 176663812892 | DT5: 344 | DU5: 42 | DV5: =DH5/DC5 -> 213.12953 | DW5: =DF5/DH5 -> 0.77488209 | DX5: =DH5/DP5 -> 1.9887693e-07 | DY5: =DH5/DQ5 -> 1.3896641e-07 | DZ5: =DH5/DR5 -> 4.613082e-07 | EA5: =DH5/DS5 -> 4.6567545e-07 | EB5: =DO5/DP5 -> 0.016233796 | EC5: =DO5/DQ5 -> 0.011343459 | ED5: =DO5/DR5 -> 0.037655364 | EE5: =DO5/DS5 -> 0.03801185 | EF5: =DO5/DH5 -> 81627.345 | EG5: =DQ5/DH5 -> 7195983.5 | EH5: =DR5/DH5 -> 2167748.2 | EI5: =DS5/DH5 -> 2147418.4 | EJ5: =DP5/DQ5 -> 0.69875582 | EK5: =DR5/DQ5 -> 0.30124418 | EL5: =DS5/DQ5 -> 0.29841902 | EM5: =DK5/DO5 -> 0.71789792 | EN5: =DN5/DO5 -> 0.28210208 | EO5: =DI5/DF5 -> 66928.559 | EP5: =DL5/DG5 -> 84107.336 | EQ5: =DT5/DC5 -> 0.89119171 | ER5: =DU5/DC5 -> 0.10880829 | FD5: 529533 | FE5: 529533000 | FF5: 1.701169e+08 | FG5: =(FF5/FE5)*100 -> 32.125836 | FH5: 4.73 | FI5: 51.8 | FJ5: 2748.7 | FK5: =FD5/L5 -> 0.16710157 | FL5: 3.89 | FM5: 6.02 | FN5: 5.67 | FO5: 4.23 | FP5: 130.8 | FQ5: 163.1 | FR5: 10 | FS5: 4.2 | FT5: 22596 | FU5: 20690.9 | FV5: 4899.4 | FW5: =FU5-FV5 -> 15791.5 | FX5: 1795.1 | FY5: 4 | FZ5: 14875.93 | GA5: 119.9
A6: Jambi | B6: 2022 | C6: 92 | D6: 40.02 | E6: 0.27593228 | F6: =D6-E6 -> 39.744068 | G6: 299736 | H6: =D6*L6/100 -> 719487.16 | I6: 0.47659526 | J6: 0.42800893 | K6: =I6-J6 -> 0.048586327 | L6: 1797819 | M6: 4.59 | N6: 4.33 | O6: 5.05 | P6: 67.84 | Q6: 86.17 | R6: 48.97 | S6: 440747 | T6: 628911 | U6: 257486 | V6: 134140 | W6: =100-X6-Y6 -> 61.86 | X6: 30.68 | Y6: 7.46 | Z6: 862275 | AA6: 56641 | AB6: 94420 | AC6: 1520 | AD6: 4093 | AE6: 85331 | AF6: 260547 | AG6: 62670 | AH6: 90857 | AI6: 4866 | AJ6: 16043 | AK6: 2139 | AL6: 19974 | AM6: 74381 | AN6: 91169 | AO6: 26537 | AP6: 44356 | AQ6: =Z6/sum(Z6:AP6) -> 0.47962281 | AR6: =AA6/sum($Z6:$AP6) -> 0.031505396 | AS6: =AB6/sum($Z6:$AP6) -> 0.052519191 | AT6: =AC6/sum($Z6:$AP6) -> 0.00084546887 | AU6: =AD6/sum($Z6:$AP6) -> 0.0022766474 | AV6: =AE6/sum($Z6:$AP6) -> 0.047463621 | AW6: =AF6/sum($Z6:$AP6) -> 0.14492393 | AX6: =AG6/sum($Z6:$AP6) -> 0.034858904 | AY6: =AH6/sum($Z6:$AP6) -> 0.050537346 | ... BG6: =AP6/sum($Z6:$AP6) -> 0.024672117 | BH6: 39 | BI6: 2649.0342 | BJ6: 0.71752649 | BK6: 2520767 | BL6: =BI6*1000/BK6 -> 1.0508842 | BM6: 44.76 | BN6: 59.98 | BO6: 11203 | BP6: 978 | BQ6: 870 | BR6: 268570 | BS6: 112330 | BT6: 1925 | BU6: 3123 | DA6: 103 | DB6: 90 | DC6: 193 | DD6: 4344 | DE6: 23509 | DF6: 22318 | DG6: 5535 | DH6: 27853 | DI6: 1223247536 | DJ6: 81227879 | DK6: 1304475415 | DL6: 448817027 | DM6: 48993694 | DN6: 497810721 | DO6: 1802286136 | DP6: 37826829189 | DQ6: 62457166353 | DR6: =DQ6-DP6 -> 24630337164 | DS6: 24425409709 | DT6: 178 | DU6: 15 | DV6: =DH6/DC6 -> 144.31606 | DW6: =DF6/DH6 -> 0.80127814 | DX6: =DH6/DP6 -> 7.3632923e-07 | DY6: =DH6/DQ6 -> 4.4595363e-07 | DZ6: =DH6/DR6 -> 1.1308412e-06 | EA6: =DH6/DS6 -> 1.1403289e-06 | EB6: =DO6/DP6 -> 0.04764571 | EC6: =DO6/DQ6 -> 0.028856355 | ED6: =DO6/DR6 -> 0.073173425 | EE6: =DO6/DS6 -> 0.073787345 | EF6: =DO6/DH6 -> 64707.074 | EG6: =DQ6/DH6 -> 2242385.6 | EH6: =DR6/DH6 -> 884297.46 | EI6: =DS6/DH6 -> 876940 | EJ6: =DP6/DQ6 -> 0.60564434 | EK6: =DR6/DQ6 -> 0.39435566 | EL6: =DS6/DQ6 -> 0.39107457 | EM6: =DK6/DO6 -> 0.7237893 | EN6: =DN6/DO6 -> 0.2762107 | EO6: =DI6/DF6 -> 54809.908 | EP6: =DL6/DG6 -> 81087.087 | EQ6: =DT6/DC6 -> 0.92227979 | ER6: =DU6/DC6 -> 0.077720207 | FD6: 161731.9 | FE6: 161731900 | FF6: 16213293 | FG6: =(FF6/FE6)*100 -> 10.024796 | FH6: 3.12 | FI6: 51.8 | FJ6: 39.2 | FK6: =FD6/L6 -> 0.089960057 | FL6: 2.15 | FM6: 6.02 | FN6: 5.36 | FO6: 3.97 | FP6: 130.8 | FQ6: 163.1 | FR6: 10 | FS6: 4.2 | FT6: 3001.9 | FU6: 2719.4 | FV6: 310.1 | FW6: =FU6-FV6 -> 2409.3 | FX6: 907.1 | FY6: 4 | FZ6: 14875.93 | GA6: 119.9
A7: Sumatera Selatan | B7: 2022 | C7: 160 | D7: 36.72 | E7: 0.25679714 | F7: =D7-E7 -> 36.463203 | G7: 649448 | H7: =D7*L7/100 -> 1575179.3 | I7: 0.44178784 | J7: 0.40187735 | K7: =I7-J7 -> 0.039910486 | L7: 4289704 | M7: 4.63 | N7: 4.53 | O7: 4.8 | P7: 69.31 | Q7: 84.95 | R7: 53.32 | S7: 1012639 | T7: 1470045 | U7: 785338 | V7: 303829 | W7: =100-X7-Y7 -> 64.54 | X7: 28.38 | Y7: 7.08 | Z7: 1992257 | AA7: 75036 | AB7: 267855 | AC7: 12971 | AD7: 8130 | AE7: 201842 | AF7: 694992 | AG7: 133528 | AH7: 193235 | AI7: 23012 | AJ7: 25256 | AK7: 4843 | AL7: 57558 | AM7: 194644 | AN7: 195620 | AO7: 58745 | AP7: 150180 | AQ7: =Z7/sum(Z7:AP7) -> 0.46442762 | AR7: =AA7/sum($Z7:$AP7) -> 0.017492116 | AS7: =AB7/sum($Z7:$AP7) -> 0.062441371 | AT7: =AC7/sum($Z7:$AP7) -> 0.0030237518 | AU7: =AD7/sum($Z7:$AP7) -> 0.0018952357 | AV7: =AE7/sum($Z7:$AP7) -> 0.047052664 | AW7: =AF7/sum($Z7:$AP7) -> 0.16201398 | AX7: =AG7/sum($Z7:$AP7) -> 0.031127556 | AY7: =AH7/sum($Z7:$AP7) -> 0.045046232 | ... BG7: =AP7/sum($Z7:$AP7) -> 0.035009409 | BH7: 41 | BI7: 3144.446 | BJ7: 3.3299804 | BK7: 2630695 | BL7: =BI7*1000/BK7 -> 1.195291 | BM7: 45.1 | BN7: 63.28 | BO7: 23589 | BP7: 1212 | BQ7: 1119 | BR7: 573899 | BS7: 95170 | BT7: 4681 | BU7: 16715 | DA7: 172 | DB7: 139 | DC7: 311 | DD7: 6958 | DE7: 64350 | DF7: 46106 | DG7: 22690 | DH7: 68796 | DI7: 3059524810 | DJ7: 383126877 | DK7: 3442651687 | DL7: 1372343204 | DM7: 215366011 | DN7: 1587709215 | DO7: 5030360902 | DP7: 89734205396 | DQ7: 183833254610 | DR7: =DQ7-DP7 -> 94099049214 | DS7: 92936472024 | DT7: 284 | DU7: 27 | DV7: =DH7/DC7 -> 221.209 | DW7: =DF7/DH7 -> 0.67018431 | DX7: =DH7/DP7 -> 7.6666417e-07 | DY7: =DH7/DQ7 -> 3.7423044e-07 | DZ7: =DH7/DR7 -> 7.3110197e-07 | EA7: =DH7/DS7 -> 7.402476e-07 | EB7: =DO7/DP7 -> 0.056058455 | EC7: =DO7/DQ7 -> 0.027363716 | ED7: =DO7/DR7 -> 0.053458148 | EE7: =DO7/DS7 -> 0.054126876 | EF7: =DO7/DH7 -> 73119.962 | EG7: =DQ7/DH7 -> 2672150.3 | EH7: =DR7/DH7 -> 1367798.3 | EI7: =DS7/DH7 -> 1350899.4 | EJ7: =DP7/DQ7 -> 0.48812825 | EK7: =DR7/DQ7 -> 0.51187175 | EL7: =DS7/DQ7 -> 0.50554766 | EM7: =DK7/DO7 -> 0.68437469 | EN7: =DN7/DO7 -> 0.31562531 | EO7: =DI7/DF7 -> 66358.496 | EP7: =DL7/DG7 -> 60482.292 | EQ7: =DT7/DC7 -> 0.91318328 | ER7: =DU7/DC7 -> 0.08681672 | FD7: 343503.6 | FE7: 343503600 | FF7: 63307615 | FG7: =(FF7/FE7)*100 -> 18.429971 | FH7: 4.39 | FI7: 51.8 | FJ7: 1226.3 | FK7: =FD7/L7 -> 0.080076294 | FL7: 2.53 | FM7: 6.02 | FN7: 5.34 | FO7: 4.05 | FP7: 130.8 | FQ7: 163.1 | FR7: 10 | FS7: 4.2 | FT7: 7583.3 | FU7: 6789.8 | FV7: 1704.8 | FW7: =FU7-FV7 -> 5085 | FX7: 2902.5 | FY7: 4 | FZ7: 14875.93 | GA7: 119.9
A8: Bengkulu | B8: 2022 | C8: 26 | D8: 32.46 | E8: 0.24193566 | F8: =D8-E8 -> 32.218064 | G8: 172272 | H8: =D8*L8/100 -> 336771.2 | I8: 0.57859683 | J8: 0.49588197 | K8: =I8-J8 -> 0.082714864 | L8: 1037496 | M8: 3.59 | N8: 3.39 | O8: 3.91 | P8: 69.81 | Q8: 84.72 | R8: 54.36 | S8: 225584 | T8: 297741 | U8: 181804 | V8: 83167 | W8: =100-X8-Y8 -> 63.06 | X8: 28.92 | Y8: 8.02 | Z8: 499641 | AA8: 11121 | AB8: 53218 | AC8: 2605 | AD8: 4169 | AE8: 45823 | AF8: 165220 | AG8: 28769 | AH8: 36180 | AI8: 5769 | AJ8: 8766 | AK8: 1705 | AL8: 10074 | AM8: 66540 | AN8: 50633 | AO8: 19352 | AP8: 27911 | AQ8: =Z8/sum(Z8:AP8) -> 0.48158354 | AR8: =AA8/sum($Z8:$AP8) -> 0.010719077 | AS8: =AB8/sum($Z8:$AP8) -> 0.051294656 | AT8: =AC8/sum($Z8:$AP8) -> 0.0025108531 | AU8: =AD8/sum($Z8:$AP8) -> 0.0040183287 | AV8: =AE8/sum($Z8:$AP8) -> 0.044166917 | AW8: =AF8/sum($Z8:$AP8) -> 0.15924881 | AX8: =AG8/sum($Z8:$AP8) -> 0.027729264 | AY8: =AH8/sum($Z8:$AP8) -> 0.034872424 | ... BG8: =AP8/sum($Z8:$AP8) -> 0.026902272 | BH8: 38 | BI8: 2238.0943 | BJ8: 1.0426325 | BK8: 2737834 | BL8: =BI8*1000/BK8 -> 0.81746896 | BM8: 47.72 | BN8: 67.54 | BO8: 4246 | BP8: 664 | BQ8: 662 | BR8: 117043 | BS8: 24826 | BT8: 834 | BU8: 1958 | DA8: 39 | DB8: 35 | DC8: 74 | DD8: 1488 | DE8: 4940 | DF8: 5264 | DG8: 1164 | DH8: 6428 | DI8: 250451827 | DJ8: 7680719 | DK8: 258132546 | DL8: 53961108 | DM8: 780743 | DN8: 54741851 | DO8: 312874397 | DP8: 11430107228 | DQ8: 17116441144 | DR8: =DQ8-DP8 -> 5686333916 | DS8: 5584631012 | DT8: 65 | DU8: 9 | DV8: =DH8/DC8 -> 86.864865 | DW8: =DF8/DH8 -> 0.81891724 | DX8: =DH8/DP8 -> 5.6237443e-07 | DY8: =DH8/DQ8 -> 3.7554536e-07 | DZ8: =DH8/DR8 -> 1.1304296e-06 | EA8: =DH8/DS8 -> 1.1510161e-06 | EB8: =DO8/DP8 -> 0.027372831 | EC8: =DO8/DQ8 -> 0.018279173 | ED8: =DO8/DR8 -> 0.055022164 | EE8: =DO8/DS8 -> 0.056024184 | EF8: =DO8/DH8 -> 48673.677 | EG8: =DQ8/DH8 -> 2662794.2 | EH8: =DR8/DH8 -> 884619.46 | EI8: =DS8/DH8 -> 868797.61 | EJ8: =DP8/DQ8 -> 0.66778527 | EK8: =DR8/DQ8 -> 0.33221473 | EL8: =DS8/DQ8 -> 0.32627291 | EM8: =DK8/DO8 -> 0.8250357 | EN8: =DN8/DO8 -> 0.1749643 | EO8: =DI8/DF8 -> 47578.235 | EP8: =DL8/DG8 -> 46358.34 | EQ8: =DT8/DC8 -> 0.87837838 | ER8: =DU8/DC8 -> 0.12162162 | FD8: 49916.1 | FE8: 49916100 | FF8: 2863150.6 | FG8: =(FF8/FE8)*100 -> 5.7359261 | FH8: 3.08 | FI8: 51.8 | FJ8: 52.2 | FK8: =FD8/L8 -> 0.048112089 | FL8: 2.73 | FM8: 6.02 | FN8: 5.89 | FO8: 4.42 | FP8: 130.8 | FQ8: 163.1 | FR8: 10 | FS8: 4.2 | FT8: 311.2 | FU8: 5418.9 | FV8: 22.4 | FW8: =FU8-FV8 -> 5396.5 | FX8: 391.9 | FY8: 4 | FZ8: 14875.93 | GA8: 119.9
A9: Lampung | B9: 2022 | C9: 30 | D9: 28.49 | E9: 0.20955681 | F9: =D9-E9 -> 28.280443 | G9: 462137 | H9: =D9*L9/100 -> 1250131.5 | I9: 0.40715912 | J9: 0.40821017 | K9: =I9-J9 -> -0.0010510504 | L9: 4387966 | M9: 4.52 | N9: 4.1 | O9: 5.24 | P9: 70.06 | Q9: 85.84 | R9: 53.54 | S9: 878210 | T9: 1135028 | U9: 807884 | V9: 303546 | W9: =100-X9-Y9 -> 63.38 | X9: 29.7 | Y9: 6.92 | Z9: 1914133 | AA9: 17131 | AB9: 409629 | AC9: 4742 | AD9: 20707 | AE9: 216667 | AF9: 865967 | AG9: 147397 | AH9: 183528 | AI9: 18878 | AJ9: 27928 | AK9: 2577 | AL9: 37241 | AM9: 120485 | AN9: 191652 | AO9: 63328 | AP9: 145976 | AQ9: =Z9/sum(Z9:AP9) -> 0.4362233 | AR9: =AA9/sum($Z9:$AP9) -> 0.0039040868 | AS9: =AB9/sum($Z9:$AP9) -> 0.09335282 | AT9: =AC9/sum($Z9:$AP9) -> 0.0010806829 | AU9: =AD9/sum($Z9:$AP9) -> 0.0047190429 | AV9: =AE9/sum($Z9:$AP9) -> 0.049377548 | AW9: =AF9/sum($Z9:$AP9) -> 0.19735044 | AX9: =AG9/sum($Z9:$AP9) -> 0.03359119 | AY9: =AH9/sum($Z9:$AP9) -> 0.041825301 | ... BG9: =AP9/sum($Z9:$AP9) -> 0.03326735 | BH9: 40 | BI9: 2440.4862 | BJ9: 0.34887354 | BK9: 2322728 | BL9: =BI9*1000/BK9 -> 1.0506982 | BM9: 55.67 | BN9: 71.51 | BO9: 15790 | BP9: 928 | BQ9: 866 | BR9: 467278 | BS9: 95808 | BT9: 3193 | BU9: 11782 | DA9: 289 | DB9: 127 | DC9: 416 | DD9: 10608 | DE9: 49857 | DF9: 48628 | DG9: 11837 | DH9: 60465 | DI9: 1900350146 | DJ9: 69056397 | DK9: 1969406543 | DL9: 576905524 | DM9: 32071632 | DN9: 608977156 | DO9: 2578383699 | DP9: 52285233457 | DQ9: 79891922824 | DR9: =DQ9-DP9 -> 27606689367 | DS9: 27070434111 | DT9: 388 | DU9: 28 | DV9: =DH9/DC9 -> 145.34856 | DW9: =DF9/DH9 -> 0.80423385 | DX9: =DH9/DP9 -> 1.1564451e-06 | DY9: =DH9/DQ9 -> 7.5683496e-07 | DZ9: =DH9/DR9 -> 2.19023e-06 | EA9: =DH9/DS9 -> 2.2336177e-06 | EB9: =DO9/DP9 -> 0.049313803 | EC9: =DO9/DQ9 -> 0.032273396 | ED9: =DO9/DR9 -> 0.093397063 | EE9: =DO9/DS9 -> 0.095247224 | EF9: =DO9/DH9 -> 42642.582 | EG9: =DQ9/DH9 -> 1321292 | EH9: =DR9/DH9 -> 456573.05 | EI9: =DS9/DH9 -> 447704.19 | EJ9: =DP9/DQ9 -> 0.65444956 | EK9: =DR9/DQ9 -> 0.34555044 | EL9: =DS9/DQ9 -> 0.33883818 | EM9: =DK9/DO9 -> 0.76381438 | EN9: =DN9/DO9 -> 0.23618562 | EO9: =DI9/DF9 -> 39079.34 | EP9: =DL9/DG9 -> 48737.478 | EQ9: =DT9/DC9 -> 0.93269231 | ER9: =DU9/DC9 -> 0.067307692 | FD9: 257534.2 | FE9: 257534200 | FF9: 46589527 | FG9: =(FF9/FE9)*100 -> 18.090617 | FH9: 0.4 | FI9: 51.8 | FJ9: 247.8 | FK9: =FD9/L9 -> 0.05869102 | FL9: 1.82 | FM9: 6.02 | FN9: 5.12 | FO9: 3.8 | FP9: 130.8 | FQ9: 163.1 | FR9: 10 | FS9: 4.2 | FT9: 5601.1 | FU9: 288.8 | FV9: 2706.4 | FW9: =FU9-FV9 -> -2417.6 | FX9: 2968.5 | FY9: 4 | FZ9: 14875.93 | GA9: 119.9
A10: Bangka Belitung | B10: 2022 | C10: 380 | D10: 50.37 | E10: 0.3520311 | F10: =D10-E10 -> 50.017969 | G10: 144140 | H10: =D10*L10/100 -> 368190.6 | I10: 0.4434422 | J10: 0.36799907 | K10: =I10-J10 -> 0.075443131 | L10: 730972 | M10: 4.77 | N10: 4.33 | O10: 5.62 | P10: 67.38 | Q10: 86.02 | R10: 47.55 | S10: 206869 | T10: 325048 | U10: 59517 | V10: 24598 | W10: =100-X10-Y10 -> 74.93 | X10: 21.7 | Y10: 3.37 | Z10: 183099 | AA10: 138969 | AB10: 50185 | AC10: 2012 | AD10: 254 | AE10: 33381 | AF10: 128709 | AG10: 15143 | AH10: 36734 | AI10: 5849 | AJ10: 6771 | AK10: 551 | AL10: 7933 | AM10: 40359 | AN10: 37193 | AO10: 16265 | AP10: 27565 | AQ10: =Z10/sum(Z10:AP10) -> 0.25048702 | AR10: =AA10/sum($Z10:$AP10) -> 0.19011535 | AS10: =AB10/sum($Z10:$AP10) -> 0.068655161 | AT10: =AC10/sum($Z10:$AP10) -> 0.0027524994 | AU10: =AD10/sum($Z10:$AP10) -> 0.00034748253 | AV10: =AE10/sum($Z10:$AP10) -> 0.045666592 | AW10: =AF10/sum($Z10:$AP10) -> 0.17607925 | AX10: =AG10/sum($Z10:$AP10) -> 0.020716252 | AY10: =AH10/sum($Z10:$AP10) -> 0.050253635 | ... BG10: =AP10/sum($Z10:$AP10) -> 0.037710063 | BH10: 41 | BI10: 3264.884 | BJ10: 1.0792596 | BK10: 2969146 | BL10: =BI10*1000/BK10 -> 1.0996037 | BM10: 43.49 | BN10: 49.63 | BO10: 4483 | BP10: 532 | BQ10: 501 | BR10: 105071 | BS10: 49780 | BT10: 780 | BU10: 1560 | DA10: 67 | DB10: 43 | DC10: 110 | DD10: 2668 | DE10: 11621 | DF10: 12086 | DG10: 2203 | DH10: 14289 | DI10: 600383912 | DJ10: 45933461 | DK10: 646317373 | DL10: 126200136 | DM10: 4380611 | DN10: 130580747 | DO10: 776898120 | DP10: 21574166843 | DQ10: 49270238495 | DR10: =DQ10-DP10 -> 27696071652 | DS10: 27136704101 | DT10: 99 | DU10: 11 | DV10: =DH10/DC10 -> 129.9 | DW10: =DF10/DH10 -> 0.84582546 | DX10: =DH10/DP10 -> 6.623199e-07 | DY10: =DH10/DQ10 -> 2.900128e-07 | DZ10: =DH10/DR10 -> 5.1592154e-07 | EA10: =DH10/DS10 -> 5.2655621e-07 | EB10: =DO10/DP10 -> 0.036010573 | EC10: =DO10/DQ10 -> 0.015768101 | ED10: =DO10/DR10 -> 0.028050842 | EE10: =DO10/DS10 -> 0.028629052 | EF10: =DO10/DH10 -> 54370.363 | EG10: =DQ10/DH10 -> 3448123.6 | EH10: =DR10/DH10 -> 1938279.2 | EI10: =DS10/DH10 -> 1899132.5 | EJ10: =DP10/DQ10 -> 0.43787421 | EK10: =DR10/DQ10 -> 0.56212579 | EL10: =DS10/DQ10 -> 0.55077274 | EM10: =DK10/DO10 -> 0.83192037 | EN10: =DN10/DO10 -> 0.16807963 | EO10: =DI10/DF10 -> 49675.981 | EP10: =DL10/DG10 -> 57285.581 | EQ10: =DT10/DC10 -> 0.9 | ER10: =DU10/DC10 -> 0.1 | FD10: 57804.2 | FE10: 57804200 | FF10: 12484719 | FG10: =(FF10/FE10)*100 -> 21.598291 | FH10: 5.14 | FI10: 51.8 | FJ10: 129.7 | FK10: =FD10/L10 -> 0.079078542 | FL10: 0.18 | FM10: 6.02 | FN10: 4.98 | FO10: 3.68 | FP10: 130.8 | FQ10: 163.1 | FR10: 10 | FS10: 4.2 | FT10: 2634.4 | FU10: 2510.2 | FV10: 206.6 | FW10: =FU10-FV10 -> 2303.6 | FX10: 466.1 | FY10: 4 | FZ10: 14875.93 | GA10: 119.9
A11: Kepulauan Riau | B11: 2022 | C11: 863 | D11: 63.68 | E11: 0.41825896 | F11: =D11-E11 -> 63.261741 | G11: 472030 | H11: =D11*L11/100 -> 736138.89 | I11: 0.67544209 | J11: 0.6034253 | K11: =I11-J11 -> 0.072016782 | L11: 1155997 | N11: 7.78 | O11: 9.03 | P11: 68.94 | Q11: 80.02 | R11: 50.68 | S11: 228843 | T11: 698846 | U11: 76616 | V11: 57246 | W11: =100-X11-Y11 -> 79.32 | X11: 15.73 | Y11: 4.95 | Z11: 90120 | AA11: 9630 | AB11: 297852 | AC11: 3976 | AD11: 1692 | AE11: 82574 | AF11: 201209 | AG11: 73239 | AH11: 117832 | AI11: 10787 | AJ11: 17249 | AK11: 13137 | AL11: 30991 | AM11: 59649 | AN11: 52821 | AO11: 18953 | AP11: 74286 | AQ11: =Z11/sum(Z11:AP11) -> 0.07795868 | AR11: =AA11/sum($Z11:$AP11) -> 0.0083304714 | AS11: =AB11/sum($Z11:$AP11) -> 0.25765811 | AT11: =AC11/sum($Z11:$AP11) -> 0.0034394553 | AU11: =AD11/sum($Z11:$AP11) -> 0.0014636716 | AV11: =AE11/sum($Z11:$AP11) -> 0.071430981 | AW11: =AF11/sum($Z11:$AP11) -> 0.17405668 | AX11: =AG11/sum($Z11:$AP11) -> 0.063355701 | AY11: =AH11/sum($Z11:$AP11) -> 0.10193106 | ... BG11: =AP11/sum($Z11:$AP11) -> 0.064261412 | BH11: 44 | BI11: 3050.172 | BJ11: 1.4876924 | BK11: 4155520 | BL11: =BI11*1000/BK11 -> 0.73400489 | BM11: 32.57 | BN11: 36.32 | BO11: 11382 | BP11: 414 | BQ11: 320 | BR11: 310171 | BS11: 87054 | BT11: 4036 | BU11: 13680 | DA11: 408 | DB11: 249 | DC11: 657 | DD11: 16544 | DE11: 150239 | DF11: 136253 | DG11: 30530 | DH11: 166783 | DI11: 9665342982 | DJ11: 777284513 | DK11: 10442627495 | DL11: 2309612411 | DM11: 340304548 | DN11: 2649916959 | DO11: 13092544454 | DP11: 101760034034 | DQ11: 191481513754 | DR11: =DQ11-DP11 -> 89721479720 | DS11: 88241194262 | DT11: 323 | DU11: 334 | DV11: =DH11/DC11 -> 253.8554 | DW11: =DF11/DH11 -> 0.81694777 | DX11: =DH11/DP11 -> 1.6389833e-06 | DY11: =DH11/DQ11 -> 8.7101359e-07 | DZ11: =DH11/DR11 -> 1.8588971e-06 | EA11: =DH11/DS11 -> 1.8900809e-06 | EB11: =DO11/DP11 -> 0.12866097 | EC11: =DO11/DQ11 -> 0.068374979 | ED11: =DO11/DR11 -> 0.1459243 | EE11: =DO11/DS11 -> 0.14837225 | EF11: =DO11/DH11 -> 78500.473 | EG11: =DQ11/DH11 -> 1148087.7 | EH11: =DR11/DH11 -> 537953.39 | EI11: =DS11/DH11 -> 529077.87 | EJ11: =DP11/DQ11 -> 0.53143529 | EK11: =DR11/DQ11 -> 0.46856471 | EL11: =DS11/DQ11 -> 0.46083401 | EM11: =DK11/DO11 -> 0.79760107 | EN11: =DN11/DO11 -> 0.20239893 | EO11: =DI11/DF11 -> 70936.735 | EP11: =DL11/DG11 -> 75650.587 | EQ11: =DT11/DC11 -> 0.49162861 | ER11: =DU11/DC11 -> 0.50837139 | FD11: 190111.1 | FE11: 190111100 | FF11: 79348156 | FG11: =(FF11/FE11)*100 -> 41.737782 | FH11: 4.55 | FI11: 51.8 | FJ11: 934 | FK11: =FD11/L11 -> 0.1644564 | FL11: -1.14 | FM11: 6.02 | FN11: 5.83 | FO11: 4.29 | FP11: 130.8 | FQ11: 163.1 | FR11: 10 | FS11: 4.2 | FT11: 18217 | FU11: 18260.6 | FV11: 16715.5 | FW11: =FU11-FV11 -> 1545.1 | FX11: 1234.1 | FY11: 4 | FZ11: 14875.93 | GA11: 119.9
A12: DKI Jakarta | B12: 2022 | C12: 1655 | D12: 63.12 | E12: 0.416744 | F12: =D12-E12 -> 62.703256 | G12: 1858151 | H12: =D12*L12/100 -> 3077164.4 | I12: 0.63566561 | J12: 0.56201476 | K12: =I12-J12 -> 0.07365085 | L12: 4875102 | M12: 7.18 | N12: 7.5 | O12: 6.65 | P12: 63.08 | Q12: 80.02 | R12: 46.62 | S12: 1183102 | T12: 2923158 | U12: 242452 | V12: 131936 | W12: =100-X12-Y12 -> 81.81 | X12: 15.48 | Y12: 2.71 | Z12: 25474 | AA12: 17005 | AB12: 500278 | AC12: 14533 | AD12: 18719 | AE12: 218962 | AF12: 1177618 | AG12: 598473 | AH12: 603860 | AI12: 125605 | AJ12: 209146 | AK12: 94734 | AL12: 278664 | AM12: 202342 | AN12: 207039 | AO12: 120537 | AP12: 462113 | AQ12: =Z12/sum(Z12:AP12) -> 0.0052253266 | AR12: =AA12/sum($Z12:$AP12) -> 0.0034881321 | AS12: =AB12/sum($Z12:$AP12) -> 0.10261898 | AT12: =AC12/sum($Z12:$AP12) -> 0.0029810658 | AU12: =AD12/sum($Z12:$AP12) -> 0.0038397145 | AV12: =AE12/sum($Z12:$AP12) -> 0.044914342 | AW12: =AF12/sum($Z12:$AP12) -> 0.24155761 | AX12: =AG12/sum($Z12:$AP12) -> 0.12276112 | AY12: =AH12/sum($Z12:$AP12) -> 0.12386613 | ... BG12: =AP12/sum($Z12:$AP12) -> 0.094790427 | BH12: 44 | BI12: 4641.854 | BJ12: 5.1100072 | BK12: 5255824 | BL12: =BI12*1000/BK12 -> 0.88318292 | BM12: 36.82 | BN12: 36.88 | BO12: 36647 | BP12: 919 | BQ12: 499 | BR12: 1735860 | BS12: 362562 | BT12: 18116 | BU12: 49475 | DA12: 1134 | DB12: 475 | DC12: 1609 | DD12: 45692 | DE12: 204332 | DF12: 199411 | DG12: 50613 | DH12: 250024 | DI12: 11123576269 | DJ12: 523340072 | DK12: 11646916341 | DL12: 4314758321 | DM12: 251690746 | DN12: 4566449067 | DO12: 16213365408 | DP12: 281738511256 | DQ12: 491567212461 | DR12: =DQ12-DP12 -> 209828701205 | DS12: 208718425904 | DT12: 1487 | DU12: 122 | DV12: =DH12/DC12 -> 155.39093 | DW12: =DF12/DH12 -> 0.79756743 | DX12: =DH12/DP12 -> 8.8743281e-07 | DY12: =DH12/DQ12 -> 5.0862627e-07 | DZ12: =DH12/DR12 -> 1.1915624e-06 | EA12: =DH12/DS12 -> 1.1979009e-06 | EB12: =DO12/DP12 -> 0.057547565 | EC12: =DO12/DQ12 -> 0.032983008 | ED12: =DO12/DR12 -> 0.077269531 | EE12: =DO12/DS12 -> 0.077680566 | EF12: =DO12/DH12 -> 64847.236 | EG12: =DQ12/DH12 -> 1966080.1 | EH12: =DR12/DH12 -> 839234.24 | EI12: =DS12/DH12 -> 834793.56 | EJ12: =DP12/DQ12 -> 0.57314342 | EK12: =DR12/DQ12 -> 0.42685658 | EL12: =DS12/DQ12 -> 0.42459794 | EM12: =DK12/DO12 -> 0.71835279 | EN12: =DN12/DO12 -> 0.28164721 | EO12: =DI12/DF12 -> 55782.16 | EP12: =DL12/DG12 -> 85250.001 | EQ12: =DT12/DC12 -> 0.92417651 | ER12: =DU12/DC12 -> 0.075823493 | FD12: 1953489 | FE12: 1953489000 | FF12: 2.2874159e+08 | FG12: =(FF12/FE12)*100 -> 11.709387 | FH12: 5.88 | FI12: 51.8 | FJ12: 3744.1 | FK12: =FD12/L12 -> 0.40070731 | FL12: 2.27 | FM12: 6.02 | FN12: 5.89 | FO12: 4.31 | FP12: 130.8 | FQ12: 163.1 | FR12: 10 | FS12: 4.2 | FT12: 11502.7 | FU12: 19962.9 | FV12: 100108.1 | FW12: =FU12-FV12 -> -80145.2 | FX12: 77566 | FY12: 4 | FZ12: 14875.93 | GA12: 119.9
A13: Jawa Barat | B13: 2022 | C13: 4629 | D13: 45.39 | E13: 0.29916394 | F13: =D13-E13 -> 45.090836 | G13: 5740015 | H13: =D13*L13/100 -> 10645121 | I13: 0.58296511 | J13: 0.61476186 | K13: =I13-J13 -> -0.031796746 | L13: 23452568 | M13: 8.31 | N13: 8.55 | O13: 7.89 | P13: 66.15 | Q13: 83.93 | R13: 48.01 | S13: 5139406 | T13: 9846241 | U13: 2077898 | V13: 1318780 | W13: =100-X13-Y13 -> 73.88 | X13: 20.5 | Y13: 5.62 | Z13: 3585851 | AA13: 147242 | AB13: 4522840 | AC13: 58362 | AD13: 149206 | AE13: 1710514 | AF13: 5439021 | AG13: 1218505 | AH13: 2148541 | AI13: 260602 | AJ13: 352782 | AK13: 136561 | AL13: 503286 | AM13: 566135 | AN13: 1024834 | AO13: 333273 | AP13: 1295013 | AQ13: =Z13/sum(Z13:AP13) -> 0.15289801 | AR13: =AA13/sum($Z13:$AP13) -> 0.006278289 | AS13: =AB13/sum($Z13:$AP13) -> 0.19285052 | AT13: =AC13/sum($Z13:$AP13) -> 0.0024885121 | AU13: =AD13/sum($Z13:$AP13) -> 0.0063620325 | AV13: =AE13/sum($Z13:$AP13) -> 0.072935041 | AW13: =AF13/sum($Z13:$AP13) -> 0.2319158 | AX13: =AG13/sum($Z13:$AP13) -> 0.051956144 | AY13: =AH13/sum($Z13:$AP13) -> 0.091612185 | ... BG13: =AP13/sum($Z13:$AP13) -> 0.055218388 | BH13: 42 | BI13: 1841.4873 | BJ13: 1.7198844 | BK13: 3533613 | BL13: =BI13*1000/BK13 -> 0.52113441 | BM13: 48.57 | BN13: 54.61 | BO13: 292753 | BP13: 7624 | BQ13: 6979 | BR13: 4203172 | BS13: 988063 | BT13: 46782 | BU13: 159117 | DA13: 5422 | DB13: 3292 | DC13: 8714 | DD13: 218730 | DE13: 1675154 | DF13: 1621420 | DG13: 272463 | DH13: 1893883 | DI13: 84854901379 | DJ13: 4609404736 | DK13: 89464306115 | DL13: 22038333959 | DM13: 1820909372 | DN13: 23859243331 | DO13: 113323549446 | DP13: 1048762806704 | DQ13: 2010401338411 | DR13: =DQ13-DP13 -> 961638531707 | DS13: 954400094642 | DT13: 7489 | DU13: 1225 | DV13: =DH13/DC13 -> 217.33796 | DW13: =DF13/DH13 -> 0.85613525 | DX13: =DH13/DP13 -> 1.8058259e-06 | DY13: =DH13/DQ13 -> 9.4204225e-07 | DZ13: =DH13/DR13 -> 1.9694334e-06 | EA13: =DH13/DS13 -> 1.9843701e-06 | EB13: =DO13/DP13 -> 0.10805451 | EC13: =DO13/DQ13 -> 0.05636862 | ED13: =DO13/DR13 -> 0.11784423 | EE13: =DO13/DS13 -> 0.11873799 | EF13: =DO13/DH13 -> 59836.616 | EG13: =DQ13/DH13 -> 1061523.5 | EH13: =DR13/DH13 -> 507760.26 | EI13: =DS13/DH13 -> 503938.26 | EJ13: =DP13/DQ13 -> 0.52166838 | EK13: =DR13/DQ13 -> 0.47833162 | EL13: =DS13/DQ13 -> 0.47473113 | EM13: =DK13/DO13 -> 0.78945909 | EN13: =DN13/DO13 -> 0.21054091 | EO13: =DI13/DF13 -> 52333.696 | EP13: =DL13/DG13 -> 80885.603 | EQ13: =DT13/DC13 -> 0.85942162 | ER13: =DU13/DC13 -> 0.14057838 | FD13: 1589984.9 | FE13: 1589984900 | FF13: 6.8342025e+08 | FG13: =(FF13/FE13)*100 -> 42.982814 | FH13: 7 | FI13: 51.8 | FJ13: 6534.5 | FK13: =FD13/L13 -> 0.06779577 | FL13: 0.33 | FM13: 6.02 | FN13: 5.87 | FO13: 4.27 | FP13: 130.8 | FQ13: 163.1 | FR13: 10 | FS13: 4.2 | FT13: 38546.6 | FU13: 35808.3 | FV13: 8661.1 | FW13: =FU13-FV13 -> 27147.2 | FX13: 17681.7 | FY13: 4 | FZ13: 14875.93 | GA13: 119.9
A14: Jawa Tengah | B14: 2022 | C14: 467 | D14: 39.84 | E14: 0.27466822 | F14: =D14-E14 -> 39.565332 | G14: 3097275 | H14: =D14*L14/100 -> 7326758.9 | I14: 0.45749959 | J14: 0.43353259 | K14: =I14-J14 -> 0.023967001 | L14: 18390459 | M14: 5.57 | N14: 5.75 | O14: 5.31 | P14: 70.84 | Q14: 83.74 | R14: 58.31 | S14: 3922691 | T14: 6770006 | U14: 2261830 | V14: 991581 | W14: =100-X14-Y14 -> 71.41 | X14: 23.2 | Y14: 5.39 | Z14: 4557468 | AA14: 84993 | AB14: 4025810 | AC14: 27545 | AD14: 57093 | AE14: 1482142 | AF14: 3565465 | AG14: 512175 | AH14: 1405347 | AI14: 103731 | AJ14: 201499 | AK14: 17209 | AL14: 177173 | AM14: 357097 | AN14: 749980 | AO14: 249877 | AP14: 815855 | AQ14: =Z14/sum(Z14:AP14) -> 0.24781698 | AR14: =AA14/sum($Z14:$AP14) -> 0.0046215812 | AS14: =AB14/sum($Z14:$AP14) -> 0.21890753 | AT14: =AC14/sum($Z14:$AP14) -> 0.0014977875 | AU14: =AD14/sum($Z14:$AP14) -> 0.0031044902 | AV14: =AE14/sum($Z14:$AP14) -> 0.080592986 | AW14: =AF14/sum($Z14:$AP14) -> 0.1938758 | AX14: =AG14/sum($Z14:$AP14) -> 0.027850039 | AY14: =AH14/sum($Z14:$AP14) -> 0.076417179 | ... BG14: =AP14/sum($Z14:$AP14) -> 0.044362949 | BH14: 42 | BI14: 1812.9354 | BJ14: 0.77579055 | BK14: 2200716 | BL14: =BI14*1000/BK14 -> 0.82379345 | BM14: 49.99 | BN14: 60.16 | BO14: 111970 | BP14: 12269 | BQ14: 11639 | BR14: 3128875 | BS14: 544331 | BT14: 19204 | BU14: 77386 | DA14: 2936 | DB14: 1483 | DC14: 4419 | DD14: 101848 | DE14: 1070684 | DF14: 1047281 | DG14: 125251 | DH14: 1172532 | DI14: 37852635657 | DJ14: 2029117558 | DK14: 39881753215 | DL14: 7086941006 | DM14: 764390117 | DN14: 7851331123 | DO14: 47733084338 | DP14: 313227608019 | DQ14: 634748049891 | DR14: =DQ14-DP14 -> 321520441872 | DS14: 313952880091 | DT14: 3973 | DU14: 446 | DV14: =DH14/DC14 -> 265.33876 | DW14: =DF14/DH14 -> 0.89317903 | DX14: =DH14/DP14 -> 3.7433865e-06 | DY14: =DH14/DQ14 -> 1.84724e-06 | DZ14: =DH14/DR14 -> 3.646835e-06 | EA14: =DH14/DS14 -> 3.7347388e-06 | EB14: =DO14/DP14 -> 0.15239105 | EC14: =DO14/DQ14 -> 0.075200049 | ED14: =DO14/DR14 -> 0.1484605 | EE14: =DO14/DS14 -> 0.15203901 | EF14: =DO14/DH14 -> 40709.409 | EG14: =DQ14/DH14 -> 541348.17 | EH14: =DR14/DH14 -> 274210.38 | EI14: =DS14/DH14 -> 267756.34 | EJ14: =DP14/DQ14 -> 0.49346762 | EK14: =DR14/DQ14 -> 0.50653238 | EL14: =DS14/DQ14 -> 0.49461023 | EM14: =DK14/DO14 -> 0.83551595 | EN14: =DN14/DO14 -> 0.16448405 | EO14: =DI14/DF14 -> 36143.724 | EP14: =DL14/DG14 -> 56581.912 | EQ14: =DT14/DC14 -> 0.89907219 | ER14: =DU14/DC14 -> 0.10092781 | FD14: 1050278.1 | FE14: 1.0502781e+09 | FF14: 3.4616965e+08 | FG14: =(FF14/FE14)*100 -> 32.959809 | FH14: 3.88 | FI14: 51.8 | FJ14: 2362 | FK14: =FD14/L14 -> 0.057109945 | FL14: 2.14 | FM14: 6.02 | FN14: 5.63 | FO14: 4.09 | FP14: 130.8 | FQ14: 163.1 | FR14: 10 | FS14: 4.2 | FT14: 11740.2 | FU14: 12362.9 | FV14: 14428.6 | FW14: =FU14-FV14 -> -2065.7 | FX14: 16130.5 | FY14: 4 | FZ14: 14875.93 | GA14: 119.9
A15: DI Yogyakarta | B15: 2022 | C15: 113 | D15: 46.62 | E15: 0.34176924 | F15: =D15-E15 -> 46.278231 | G15: 466370 | H15: =D15*L15/100 -> 1044815.3 | I15: 0.4847009 | J15: 0.46780594 | K15: =I15-J15 -> 0.016894965 | L15: 2241131 | M15: 4.06 | N15: 3.9 | O15: 4.27 | P15: 72.6 | Q15: 82.22 | R15: 63.38 | S15: 468305 | T15: 962181 | U15: 269489 | V15: 106775 | W15: =100-X15-Y15 -> 67.06 | X15: 28.18 | Y15: 4.76 | Z15: 402044 | AA15: 6939 | AB15: 387207 | AC15: 1568 | AD15: 7272 | AE15: 159070 | AF15: 444742 | AG15: 100671 | AH15: 225614 | AI15: 22693 | AJ15: 24400 | AK15: 4693 | AL15: 52282 | AM15: 67735 | AN15: 141321 | AO15: 53210 | AP15: 139670 | AQ15: =Z15/sum(Z15:AP15) -> 0.17939335 | AR15: =AA15/sum($Z15:$AP15) -> 0.0030962045 | AS15: =AB15/sum($Z15:$AP15) -> 0.17277303 | AT15: =AC15/sum($Z15:$AP15) -> 0.00069964674 | AU15: =AD15/sum($Z15:$AP15) -> 0.0032447902 | AV15: =AE15/sum($Z15:$AP15) -> 0.070977556 | AW15: =AF15/sum($Z15:$AP15) -> 0.19844534 | AX15: =AG15/sum($Z15:$AP15) -> 0.04491973 | AY15: =AH15/sum($Z15:$AP15) -> 0.10066971 | ... BG15: =AP15/sum($Z15:$AP15) -> 0.062321212 | BH15: 40 | BI15: 1840.9155 | BJ15: 4.3011632 | BK15: 2462583 | BL15: =BI15*1000/BK15 -> 0.74755471 | BM15: 44.19 | BN15: 53.38 | BO15: 13310 | BP15: 1825 | BQ15: 1704 | BR15: 364326 | BS15: 63441 | BT15: 2086 | BU15: 8253 | DA15: 425 | DB15: 132 | DC15: 557 | DD15: 14437 | DE15: 65329 | DF15: 68730 | DG15: 11036 | DH15: 79766 | DI15: 2282222594 | DJ15: 158259089 | DK15: 2440481683 | DL15: 568953912 | DM15: 56467038 | DN15: 625420950 | DO15: 3065902633 | DP15: 9267062908 | DQ15: 22600612278 | DR15: =DQ15-DP15 -> 13333549370 | DS15: 13168113764 | DT15: 503 | DU15: 54 | DV15: =DH15/DC15 -> 143.20646 | DW15: =DF15/DH15 -> 0.86164531 | DX15: =DH15/DP15 -> 8.6074737e-06 | DY15: =DH15/DQ15 -> 3.5293734e-06 | DZ15: =DH15/DR15 -> 5.9823531e-06 | EA15: =DH15/DS15 -> 6.0575115e-06 | EB15: =DO15/DP15 -> 0.33083866 | EC15: =DO15/DQ15 -> 0.13565573 | ED15: =DO15/DR15 -> 0.22993897 | EE15: =DO15/DS15 -> 0.23282778 | EF15: =DO15/DH15 -> 38436.209 | EG15: =DQ15/DH15 -> 283336.41 | EH15: =DR15/DH15 -> 167158.31 | EI15: =DS15/DH15 -> 165084.29 | EJ15: =DP15/DQ15 -> 0.41003592 | EK15: =DR15/DQ15 -> 0.58996408 | EL15: =DS15/DQ15 -> 0.58264412 | EM15: =DK15/DO15 -> 0.79600756 | EN15: =DN15/DO15 -> 0.20399244 | EO15: =DI15/DF15 -> 33205.625 | EP15: =DL15/DG15 -> 51554.36 | EQ15: =DT15/DC15 -> 0.90305206 | ER15: =DU15/DC15 -> 0.096947935 | FD15: 112901.3 | FE15: 112901300 | FF15: 12890390 | FG15: =(FF15/FE15)*100 -> 11.417397 | FH15: 1.76 | FI15: 51.8 | FJ15: 113.9 | FK15: =FD15/L15 -> 0.05037693 | FL15: 4.55 | FM15: 6.02 | FN15: 6.29 | FO15: 4.59 | FP15: 130.8 | FQ15: 163.1 | FR15: 10 | FS15: 4.2 | FT15: 581.6 | FU15: 536 | FV15: 63 | FW15: =FU15-FV15 -> 473 | FX15: 1320.4 | FY15: 4 | FZ15: 14875.93 | GA15: 119.9
A16: Jawa Timur | B16: 2022 | C16: 3574 | D16: 36.14 | E16: 0.26344642 | F16: =D16-E16 -> 35.876554 | G16: 3713936 | H16: =D16*L16/100 -> 7811044.1 | I16: 0.51467058 | J16: 0.45991361 | K16: =I16-J16 -> 0.054756974 | L16: 21613293 | M16: 5.49 | N16: 5.74 | O16: 5.13 | P16: 71.23 | Q16: 85.76 | R16: 57.28 | S16: 4436795 | T16: 7216142 | U16: 3108951 | V16: 1246057 | W16: =100-X16-Y16 -> 66.2 | X16: 28.03 | Y16: 5.77 | Z16: 6766440 | AA16: 108273 | AB16: 3221241 | AC16: 43101 | AD16: 69351 | AE16: 1396816 | AF16: 4340444 | AG16: 705855 | AH16: 1556876 | AI16: 126854 | AJ16: 204139 | AK16: 37368 | AL16: 285802 | AM16: 462128 | AN16: 998127 | AO16: 313930 | AP16: 976548 | AQ16: =Z16/sum(Z16:AP16) -> 0.31306844 | AR16: =AA16/sum($Z16:$AP16) -> 0.0050095559 | AS16: =AB16/sum($Z16:$AP16) -> 0.14903981 | AT16: =AC16/sum($Z16:$AP16) -> 0.0019941894 | AU16: =AD16/sum($Z16:$AP16) -> 0.0032087197 | AV16: =AE16/sum($Z16:$AP16) -> 0.064627634 | AW16: =AF16/sum($Z16:$AP16) -> 0.20082289 | AX16: =AG16/sum($Z16:$AP16) -> 0.032658374 | AY16: =AH16/sum($Z16:$AP16) -> 0.072033262 | ... BG16: =AP16/sum($Z16:$AP16) -> 0.045182749 | BH16: 41 | BI16: 1891.5671 | BJ16: 1.2195162 | BK16: 2638752 | BL16: =BI16*1000/BK16 -> 0.71684157 | BM16: 50.73 | BN16: 63.86 | BO16: 95978 | BP16: 8497 | BQ16: 8073 | BR16: 2919531 | BS16: 633773 | BT16: 26691 | BU16: 58254 | DA16: 4535 | DB16: 1763 | DC16: 6298 | DD16: 159337 | DE16: 814816 | DF16: 803823 | DG16: 170320 | DH16: 974143 | DI16: 36540371120 | DJ16: 1649052621 | DK16: 38189423741 | DL16: 11201234381 | DM16: 731213480 | DN16: 11932447861 | DO16: 50121871602 | DP16: 584879871386 | DQ16: 1041827274222 | DR16: =DQ16-DP16 -> 456947402836 | DS16: 447184958620 | DT16: 5914 | DU16: 384 | DV16: =DH16/DC16 -> 154.67498 | DW16: =DF16/DH16 -> 0.82515914 | DX16: =DH16/DP16 -> 1.6655437e-06 | DY16: =DH16/DQ16 -> 9.3503311e-07 | DZ16: =DH16/DR16 -> 2.1318493e-06 | EA16: =DH16/DS16 -> 2.1783895e-06 | EB16: =DO16/DP16 -> 0.085696011 | EC16: =DO16/DQ16 -> 0.048109579 | ED16: =DO16/DR16 -> 0.10968849 | EE16: =DO16/DS16 -> 0.11208309 | EF16: =DO16/DH16 -> 51452.273 | EG16: =DQ16/DH16 -> 1069480.8 | EH16: =DR16/DH16 -> 469076.31 | EI16: =DS16/DH16 -> 459054.74 | EJ16: =DP16/DQ16 -> 0.56139812 | EK16: =DR16/DQ16 -> 0.43860188 | EL16: =DS16/DQ16 -> 0.42923138 | EM16: =DK16/DO16 -> 0.76193132 | EN16: =DN16/DO16 -> 0.23806868 | EO16: =DI16/DF16 -> 45458.23 | EP16: =DL16/DG16 -> 65765.82 | EQ16: =DT16/DC16 -> 0.93902826 | ER16: =DU16/DC16 -> 0.060971737 | FD16: 1757874.9 | FE16: 1757874900 | FF16: 5.3639403e+08 | FG16: =(FF16/FE16)*100 -> 30.513777 | FH16: 6.27 | FI16: 51.8 | FJ16: 3134 | FK16: =FD16/L16 -> 0.081333044 | FL16: 2.53 | FM16: 6.02 | FN16: 6.13 | FO16: 4.5 | FP16: 130.8 | FQ16: 163.1 | FR16: 10 | FS16: 4.2 | FT16: 24963.2 | FU16: 25898.6 | FV16: 31946.5 | FW16: =FU16-FV16 -> -6047.9 | FX16: 19233.8 | FY16: 4 | FZ16: 14875.93 | GA16: 119.9
A17: Banten | B17: 2022 | C17: 3703 | D17: 52.04 | E17: 0.34930725 | F17: =D17-E17 -> 51.690693 | G17: 2002153 | H17: =D17*L17/100 -> 3091497.6 | I17: 0.67605884 | J17: 0.71547278 | K17: =I17-J17 -> -0.039413935 | L17: 5940618 | M17: 8.09 | N17: 7.39 | O17: 9.35 | P17: 64.72 | Q17: 81.69 | R17: 47.17 | S17: 1302970 | T17: 2961507 | U17: 473435 | V17: 271703 | W17: =100-X17-Y17 -> 76.98 | X17: 18.45 | Y17: 4.57 | Z17: 670880 | AA17: 38623 | AB17: 1368588 | AC17: 22227 | AD17: 56523 | AE17: 353551 | AF17: 1240325 | AG17: 410961 | AH17: 461408 | AI17: 71074 | AJ17: 116204 | AK17: 70604 | AL17: 211101 | AM17: 141346 | AN17: 283139 | AO17: 93029 | AP17: 331035 | AQ17: =Z17/sum(Z17:AP17) -> 0.11293101 | AR17: =AA17/sum($Z17:$AP17) -> 0.0065015121 | AS17: =AB17/sum($Z17:$AP17) -> 0.23037805 | AT17: =AC17/sum($Z17:$AP17) -> 0.0037415299 | AU17: =AD17/sum($Z17:$AP17) -> 0.0095146667 | AV17: =AE17/sum($Z17:$AP17) -> 0.059514178 | AW17: =AF17/sum($Z17:$AP17) -> 0.2087872 | AX17: =AG17/sum($Z17:$AP17) -> 0.069178156 | AY17: =AH17/sum($Z17:$AP17) -> 0.077670034 | ... BG17: =AP17/sum($Z17:$AP17) -> 0.055724 | BH17: 42 | BI17: 2501.2031 | BJ17: 1.6337516 | BK17: 4370278 | BL17: =BI17*1000/BK17 -> 0.57232128 | BM17: 42.5 | BN17: 47.96 | BO17: 58778 | BP17: 1473 | BQ17: 1265 | BR17: 1412620 | BS17: 354431 | BT17: 20709 | BU17: 50271 | DA17: 2269 | DB17: 1557 | DC17: 3826 | DD17: 108033 | DE17: 708364 | DF17: 687697 | DG17: 128700 | DH17: 816397 | DI17: 37163271204 | DJ17: 1894329577 | DK17: 39057600781 | DL17: 10173136678 | DM17: 983149570 | DN17: 11156286248 | DO17: 50213887029 | DP17: 625806114712 | DQ17: 1087303142410 | DR17: =DQ17-DP17 -> 461497027698 | DS17: 458588270958 | DT17: 3384 | DU17: 442 | DV17: =DH17/DC17 -> 213.38134 | DW17: =DF17/DH17 -> 0.84235611 | DX17: =DH17/DP17 -> 1.3045526e-06 | DY17: =DH17/DQ17 -> 7.508458e-07 | DZ17: =DH17/DR17 -> 1.769019e-06 | EA17: =DH17/DS17 -> 1.7802396e-06 | EB17: =DO17/DP17 -> 0.080238729 | EC17: =DO17/DQ17 -> 0.046182049 | ED17: =DO17/DR17 -> 0.10880652 | EE17: =DO17/DS17 -> 0.10949667 | EF17: =DO17/DH17 -> 61506.702 | EG17: =DQ17/DH17 -> 1331831.4 | EH17: =DR17/DH17 -> 565285.06 | EI17: =DS17/DH17 -> 561722.14 | EJ17: =DP17/DQ17 -> 0.57555809 | EK17: =DR17/DQ17 -> 0.42444191 | EL17: =DS17/DQ17 -> 0.42176671 | EM17: =DK17/DO17 -> 0.77782468 | EN17: =DN17/DO17 -> 0.22217532 | EO17: =DI17/DF17 -> 54040.182 | EP17: =DL17/DG17 -> 79045.351 | EQ17: =DT17/DC17 -> 0.88447465 | ER17: =DU17/DC17 -> 0.11552535 | FD17: 484129.4 | FE17: 484129400 | FF17: 1.6063946e+08 | FG17: =(FF17/FE17)*100 -> 33.1811 | FH17: 3.6 | FI17: 51.8 | FJ17: 3410.7 | FK17: =FD17/L17 -> 0.081494787 | FL17: 0.75 | FM17: 6.02 | FN17: 5.08 | FO17: 3.75 | FP17: 130.8 | FQ17: 163.1 | FR17: 10 | FS17: 4.2 | FT17: 14084.2 | FU17: 14565.5 | FV17: 17688.7 | FW17: =FU17-FV17 -> -3123.2 | FX17: 3754.2 | FY17: 4 | FZ17: 14875.93 | GA17: 119.9
